NAMESPACE                  LAST SEEN   TYPE      REASON                           OBJECT                                                                SUBOBJECT                                         SOURCE                                                                 MESSAGE                                                                                                                                                                                                                                                                                                                                                                              FIRST SEEN   COUNT   NAME
calico-system              30m         Warning   FailedScheduling                 pod/calico-kube-controllers-dd594dfc9-k8l2q                                                                             default-scheduler, default-scheduler-r8s-cp-wlp7h-lhvgq                0/1 nodes are available: 1 node(s) had untolerated taint {node.kubernetes.io/not-ready: }. preemption: 0/1 nodes are available: 1 Preemption is not helpful for scheduling.                                                                                                                                                                                                          30m          1       calico-kube-controllers-dd594dfc9-k8l2q.1890a467a42e4dfe
calico-system              29m         Normal    Scheduled                        pod/calico-kube-controllers-dd594dfc9-k8l2q                                                                             default-scheduler, default-scheduler-r8s-cp-wlp7h-lhvgq                Successfully assigned calico-system/calico-kube-controllers-dd594dfc9-k8l2q to r8s-cp-wlp7h-lhvgq                                                                                                                                                                                                                                                                                    29m          1       calico-kube-controllers-dd594dfc9-k8l2q.1890a46ea68ee0aa
calico-system              29m         Warning   FailedCreatePodSandBox           pod/calico-kube-controllers-dd594dfc9-k8l2q                                                                             kubelet, r8s-cp-wlp7h-lhvgq                                            Failed to create pod sandbox: rpc error: code = Unknown desc = failed to setup network for sandbox "525deaccb60b96c85af668de76c588503ebccbd1c359ba93ab5384411e3b1497": plugin type="calico" failed (add): stat /var/lib/calico/nodename: no such file or directory: check that the calico/node container is running and has mounted /var/lib/calico/                                 29m          1       calico-kube-controllers-dd594dfc9-k8l2q.1890a46ed0b386e3
calico-system              29m         Normal    Pulling                          pod/calico-kube-controllers-dd594dfc9-k8l2q                           spec.containers{calico-kube-controllers}          kubelet, r8s-cp-wlp7h-lhvgq                                            Pulling image "docker.io/rancher/mirrored-calico-kube-controllers:v3.31.2"                                                                                                                                                                                                                                                                                                           29m          1       calico-kube-controllers-dd594dfc9-k8l2q.1890a471789514ea
calico-system              29m         Normal    Pulled                           pod/calico-kube-controllers-dd594dfc9-k8l2q                           spec.containers{calico-kube-controllers}          kubelet, r8s-cp-wlp7h-lhvgq                                            Successfully pulled image "docker.io/rancher/mirrored-calico-kube-controllers:v3.31.2" in 10.454s (10.454s including waiting). Image size: 53900585 bytes.                                                                                                                                                                                                                           29m          1       calico-kube-controllers-dd594dfc9-k8l2q.1890a473e7bb64c9
calico-system              29m         Normal    Created                          pod/calico-kube-controllers-dd594dfc9-k8l2q                           spec.containers{calico-kube-controllers}          kubelet, r8s-cp-wlp7h-lhvgq                                            Created container: calico-kube-controllers                                                                                                                                                                                                                                                                                                                                           29m          1       calico-kube-controllers-dd594dfc9-k8l2q.1890a473ec2d4e46
calico-system              29m         Normal    Started                          pod/calico-kube-controllers-dd594dfc9-k8l2q                           spec.containers{calico-kube-controllers}          kubelet, r8s-cp-wlp7h-lhvgq                                            Started container calico-kube-controllers                                                                                                                                                                                                                                                                                                                                            29m          1       calico-kube-controllers-dd594dfc9-k8l2q.1890a473f8f599f5
calico-system              30m         Normal    SuccessfulCreate                 replicaset/calico-kube-controllers-dd594dfc9                                                                            replicaset-controller                                                  Created pod: calico-kube-controllers-dd594dfc9-k8l2q                                                                                                                                                                                                                                                                                                                                 30m          1       calico-kube-controllers-dd594dfc9.1890a467a43b947c
calico-system              30m         Normal    ScalingReplicaSet                deployment/calico-kube-controllers                                                                                      deployment-controller                                                  Scaled up replica set calico-kube-controllers-dd594dfc9 from 0 to 1                                                                                                                                                                                                                                                                                                                  30m          1       calico-kube-controllers.1890a467a3cb587b
calico-system              26m         Normal    Scheduled                        pod/calico-node-88rjf                                                                                                   default-scheduler, default-scheduler-r8s-cp-wlp7h-lhvgq                Successfully assigned calico-system/calico-node-88rjf to r8s-wk-jnhwv-j5k8h                                                                                                                                                                                                                                                                                                          26m          1       calico-node-88rjf.1890a494578522b6
calico-system              26m         Normal    Pulling                          pod/calico-node-88rjf                                                 spec.initContainers{flexvol-driver}               kubelet, r8s-wk-jnhwv-j5k8h                                            Pulling image "docker.io/rancher/mirrored-calico-pod2daemon-flexvol:v3.31.2"                                                                                                                                                                                                                                                                                                         26m          1       calico-node-88rjf.1890a4956b3121bb
calico-system              26m         Normal    Pulled                           pod/calico-node-88rjf                                                 spec.initContainers{flexvol-driver}               kubelet, r8s-wk-jnhwv-j5k8h                                            Successfully pulled image "docker.io/rancher/mirrored-calico-pod2daemon-flexvol:v3.31.2" in 5.404s (5.404s including waiting). Image size: 6168017 bytes.                                                                                                                                                                                                                            26m          1       calico-node-88rjf.1890a496ad5ef7c1
calico-system              26m         Normal    Created                          pod/calico-node-88rjf                                                 spec.initContainers{flexvol-driver}               kubelet, r8s-wk-jnhwv-j5k8h                                            Created container: flexvol-driver                                                                                                                                                                                                                                                                                                                                                    26m          1       calico-node-88rjf.1890a496aee3b9e9
calico-system              26m         Normal    Started                          pod/calico-node-88rjf                                                 spec.initContainers{flexvol-driver}               kubelet, r8s-wk-jnhwv-j5k8h                                            Started container flexvol-driver                                                                                                                                                                                                                                                                                                                                                     26m          1       calico-node-88rjf.1890a496b5ef7233
calico-system              26m         Normal    Pulling                          pod/calico-node-88rjf                                                 spec.initContainers{ebpf-bootstrap}               kubelet, r8s-wk-jnhwv-j5k8h                                            Pulling image "docker.io/rancher/mirrored-calico-node:v3.31.2"                                                                                                                                                                                                                                                                                                                       26m          1       calico-node-88rjf.1890a496d41dc6c3
calico-system              26m         Normal    Pulled                           pod/calico-node-88rjf                                                 spec.initContainers{ebpf-bootstrap}               kubelet, r8s-wk-jnhwv-j5k8h                                            Successfully pulled image "docker.io/rancher/mirrored-calico-node:v3.31.2" in 12.523s (12.523s including waiting). Image size: 159690977 bytes.                                                                                                                                                                                                                                      26m          1       calico-node-88rjf.1890a499be8dc4b8
calico-system              26m         Normal    Created                          pod/calico-node-88rjf                                                 spec.initContainers{ebpf-bootstrap}               kubelet, r8s-wk-jnhwv-j5k8h                                            Created container: ebpf-bootstrap                                                                                                                                                                                                                                                                                                                                                    26m          1       calico-node-88rjf.1890a499c0749dca
calico-system              26m         Normal    Started                          pod/calico-node-88rjf                                                 spec.initContainers{ebpf-bootstrap}               kubelet, r8s-wk-jnhwv-j5k8h                                            Started container ebpf-bootstrap                                                                                                                                                                                                                                                                                                                                                     26m          1       calico-node-88rjf.1890a499c7a05cb8
calico-system              26m         Normal    Pulling                          pod/calico-node-88rjf                                                 spec.initContainers{install-cni}                  kubelet, r8s-wk-jnhwv-j5k8h                                            Pulling image "docker.io/rancher/mirrored-calico-cni:v3.31.2"                                                                                                                                                                                                                                                                                                                        26m          1       calico-node-88rjf.1890a49a18ca069c
calico-system              26m         Normal    Pulled                           pod/calico-node-88rjf                                                 spec.initContainers{install-cni}                  kubelet, r8s-wk-jnhwv-j5k8h                                            Successfully pulled image "docker.io/rancher/mirrored-calico-cni:v3.31.2" in 7.882s (7.882s including waiting). Image size: 72114070 bytes.                                                                                                                                                                                                                                          26m          1       calico-node-88rjf.1890a49beea18ca4
calico-system              26m         Normal    Created                          pod/calico-node-88rjf                                                 spec.initContainers{install-cni}                  kubelet, r8s-wk-jnhwv-j5k8h                                            Created container: install-cni                                                                                                                                                                                                                                                                                                                                                       26m          1       calico-node-88rjf.1890a49bf0abf9b9
calico-system              26m         Normal    Started                          pod/calico-node-88rjf                                                 spec.initContainers{install-cni}                  kubelet, r8s-wk-jnhwv-j5k8h                                            Started container install-cni                                                                                                                                                                                                                                                                                                                                                        26m          1       calico-node-88rjf.1890a49bf8a01fe6
calico-system              26m         Normal    Pulled                           pod/calico-node-88rjf                                                 spec.containers{calico-node}                      kubelet, r8s-wk-jnhwv-j5k8h                                            Container image "docker.io/rancher/mirrored-calico-node:v3.31.2" already present on machine                                                                                                                                                                                                                                                                                          26m          1       calico-node-88rjf.1890a49c6f54740f
calico-system              26m         Normal    Created                          pod/calico-node-88rjf                                                 spec.containers{calico-node}                      kubelet, r8s-wk-jnhwv-j5k8h                                            Created container: calico-node                                                                                                                                                                                                                                                                                                                                                       26m          1       calico-node-88rjf.1890a49c7156b7a1
calico-system              26m         Normal    Started                          pod/calico-node-88rjf                                                 spec.containers{calico-node}                      kubelet, r8s-wk-jnhwv-j5k8h                                            Started container calico-node                                                                                                                                                                                                                                                                                                                                                        26m          1       calico-node-88rjf.1890a49c7811e059
calico-system              26m         Warning   Unhealthy                        pod/calico-node-88rjf                                                 spec.containers{calico-node}                      kubelet, r8s-wk-jnhwv-j5k8h                                            Readiness probe failed: calico/node is not ready: felix is not ready: readiness probe reporting 503                                                                                                                                                                                                                                                                                  26m          2       calico-node-88rjf.1890a49cb277bce7
calico-system              26m         Normal    Scheduled                        pod/calico-node-f86rc                                                                                                   default-scheduler, default-scheduler-r8s-cp-wlp7h-lhvgq                Successfully assigned calico-system/calico-node-f86rc to r8s-wk-jnhwv-vpdq4                                                                                                                                                                                                                                                                                                          26m          1       calico-node-f86rc.1890a494fb0f67fa
calico-system              26m         Normal    Pulling                          pod/calico-node-f86rc                                                 spec.initContainers{flexvol-driver}               kubelet, r8s-wk-jnhwv-vpdq4                                            Pulling image "docker.io/rancher/mirrored-calico-pod2daemon-flexvol:v3.31.2"                                                                                                                                                                                                                                                                                                         26m          1       calico-node-f86rc.1890a49616b92d57
calico-system              26m         Normal    Pulled                           pod/calico-node-f86rc                                                 spec.initContainers{flexvol-driver}               kubelet, r8s-wk-jnhwv-vpdq4                                            Successfully pulled image "docker.io/rancher/mirrored-calico-pod2daemon-flexvol:v3.31.2" in 5.017s (5.017s including waiting). Image size: 6168017 bytes.                                                                                                                                                                                                                            26m          1       calico-node-f86rc.1890a49741c39732
calico-system              26m         Normal    Created                          pod/calico-node-f86rc                                                 spec.initContainers{flexvol-driver}               kubelet, r8s-wk-jnhwv-vpdq4                                            Created container: flexvol-driver                                                                                                                                                                                                                                                                                                                                                    26m          1       calico-node-f86rc.1890a49743983206
calico-system              26m         Normal    Started                          pod/calico-node-f86rc                                                 spec.initContainers{flexvol-driver}               kubelet, r8s-wk-jnhwv-vpdq4                                            Started container flexvol-driver                                                                                                                                                                                                                                                                                                                                                     26m          1       calico-node-f86rc.1890a4974e3895b4
calico-system              26m         Normal    Pulling                          pod/calico-node-f86rc                                                 spec.initContainers{ebpf-bootstrap}               kubelet, r8s-wk-jnhwv-vpdq4                                            Pulling image "docker.io/rancher/mirrored-calico-node:v3.31.2"                                                                                                                                                                                                                                                                                                                       26m          1       calico-node-f86rc.1890a4977cdaba71
calico-system              26m         Normal    Pulled                           pod/calico-node-f86rc                                                 spec.initContainers{ebpf-bootstrap}               kubelet, r8s-wk-jnhwv-vpdq4                                            Successfully pulled image "docker.io/rancher/mirrored-calico-node:v3.31.2" in 12.122s (12.122s including waiting). Image size: 159690977 bytes.                                                                                                                                                                                                                                      26m          1       calico-node-f86rc.1890a49a4f63f996
calico-system              26m         Normal    Created                          pod/calico-node-f86rc                                                 spec.initContainers{ebpf-bootstrap}               kubelet, r8s-wk-jnhwv-vpdq4                                            Created container: ebpf-bootstrap                                                                                                                                                                                                                                                                                                                                                    26m          1       calico-node-f86rc.1890a49a5108120c
calico-system              26m         Normal    Started                          pod/calico-node-f86rc                                                 spec.initContainers{ebpf-bootstrap}               kubelet, r8s-wk-jnhwv-vpdq4                                            Started container ebpf-bootstrap                                                                                                                                                                                                                                                                                                                                                     26m          1       calico-node-f86rc.1890a49a586ac73c
calico-system              26m         Normal    Pulling                          pod/calico-node-f86rc                                                 spec.initContainers{install-cni}                  kubelet, r8s-wk-jnhwv-vpdq4                                            Pulling image "docker.io/rancher/mirrored-calico-cni:v3.31.2"                                                                                                                                                                                                                                                                                                                        26m          1       calico-node-f86rc.1890a49a858b3209
calico-system              26m         Normal    Pulled                           pod/calico-node-f86rc                                                 spec.initContainers{install-cni}                  kubelet, r8s-wk-jnhwv-vpdq4                                            Successfully pulled image "docker.io/rancher/mirrored-calico-cni:v3.31.2" in 8.124s (8.124s including waiting). Image size: 72114070 bytes.                                                                                                                                                                                                                                          26m          1       calico-node-f86rc.1890a49c69d44612
calico-system              26m         Normal    Created                          pod/calico-node-f86rc                                                 spec.initContainers{install-cni}                  kubelet, r8s-wk-jnhwv-vpdq4                                            Created container: install-cni                                                                                                                                                                                                                                                                                                                                                       26m          1       calico-node-f86rc.1890a49c6be64d45
calico-system              26m         Normal    Started                          pod/calico-node-f86rc                                                 spec.initContainers{install-cni}                  kubelet, r8s-wk-jnhwv-vpdq4                                            Started container install-cni                                                                                                                                                                                                                                                                                                                                                        26m          1       calico-node-f86rc.1890a49c73a94fa8
calico-system              26m         Normal    Pulled                           pod/calico-node-f86rc                                                 spec.containers{calico-node}                      kubelet, r8s-wk-jnhwv-vpdq4                                            Container image "docker.io/rancher/mirrored-calico-node:v3.31.2" already present on machine                                                                                                                                                                                                                                                                                          26m          1       calico-node-f86rc.1890a49cdbc001a2
calico-system              26m         Normal    Created                          pod/calico-node-f86rc                                                 spec.containers{calico-node}                      kubelet, r8s-wk-jnhwv-vpdq4                                            Created container: calico-node                                                                                                                                                                                                                                                                                                                                                       26m          1       calico-node-f86rc.1890a49cde3be9f1
calico-system              26m         Normal    Started                          pod/calico-node-f86rc                                                 spec.containers{calico-node}                      kubelet, r8s-wk-jnhwv-vpdq4                                            Started container calico-node                                                                                                                                                                                                                                                                                                                                                        26m          1       calico-node-f86rc.1890a49ce6566232
calico-system              26m         Warning   Unhealthy                        pod/calico-node-f86rc                                                 spec.containers{calico-node}                      kubelet, r8s-wk-jnhwv-vpdq4                                            Readiness probe failed: calico/node is not ready: felix is not ready: Get "http://localhost:9099/readiness": dial tcp [::1]:9099: connect: connection refused                                                                                                                                                                                                                        26m          1       calico-node-f86rc.1890a49d1ed619ca
calico-system              26m         Warning   Unhealthy                        pod/calico-node-f86rc                                                 spec.containers{calico-node}                      kubelet, r8s-wk-jnhwv-vpdq4                                            Readiness probe failed: calico/node is not ready: felix is not ready: readiness probe reporting 503                                                                                                                                                                                                                                                                                  26m          1       calico-node-f86rc.1890a49d5c076666
calico-system              30m         Normal    Scheduled                        pod/calico-node-hmc5p                                                                                                   default-scheduler, default-scheduler-r8s-cp-wlp7h-lhvgq                Successfully assigned calico-system/calico-node-hmc5p to r8s-cp-wlp7h-lhvgq                                                                                                                                                                                                                                                                                                          30m          1       calico-node-hmc5p.1890a4679d896391
calico-system              30m         Normal    Pulling                          pod/calico-node-hmc5p                                                 spec.initContainers{flexvol-driver}               kubelet, r8s-cp-wlp7h-lhvgq                                            Pulling image "docker.io/rancher/mirrored-calico-pod2daemon-flexvol:v3.31.2"                                                                                                                                                                                                                                                                                                         30m          1       calico-node-hmc5p.1890a467b71c16c1
calico-system              30m         Normal    Pulled                           pod/calico-node-hmc5p                                                 spec.initContainers{flexvol-driver}               kubelet, r8s-cp-wlp7h-lhvgq                                            Successfully pulled image "docker.io/rancher/mirrored-calico-pod2daemon-flexvol:v3.31.2" in 5.042s (5.042s including waiting). Image size: 6168017 bytes.                                                                                                                                                                                                                            30m          1       calico-node-hmc5p.1890a468e3b03380
calico-system              30m         Normal    Created                          pod/calico-node-hmc5p                                                 spec.initContainers{flexvol-driver}               kubelet, r8s-cp-wlp7h-lhvgq                                            Created container: flexvol-driver                                                                                                                                                                                                                                                                                                                                                    30m          1       calico-node-hmc5p.1890a468e609ccb2
calico-system              30m         Normal    Started                          pod/calico-node-hmc5p                                                 spec.initContainers{flexvol-driver}               kubelet, r8s-cp-wlp7h-lhvgq                                            Started container flexvol-driver                                                                                                                                                                                                                                                                                                                                                     30m          1       calico-node-hmc5p.1890a468edaf2d70
calico-system              30m         Normal    Pulling                          pod/calico-node-hmc5p                                                 spec.initContainers{ebpf-bootstrap}               kubelet, r8s-cp-wlp7h-lhvgq                                            Pulling image "docker.io/rancher/mirrored-calico-node:v3.31.2"                                                                                                                                                                                                                                                                                                                       30m          1       calico-node-hmc5p.1890a4690c936d4f
calico-system              29m         Normal    Pulled                           pod/calico-node-hmc5p                                                 spec.initContainers{ebpf-bootstrap}               kubelet, r8s-cp-wlp7h-lhvgq                                            Successfully pulled image "docker.io/rancher/mirrored-calico-node:v3.31.2" in 13.564s (13.564s including waiting). Image size: 159690977 bytes.                                                                                                                                                                                                                                      29m          1       calico-node-hmc5p.1890a46c35119e26
calico-system              29m         Normal    Created                          pod/calico-node-hmc5p                                                 spec.initContainers{ebpf-bootstrap}               kubelet, r8s-cp-wlp7h-lhvgq                                            Created container: ebpf-bootstrap                                                                                                                                                                                                                                                                                                                                                    29m          1       calico-node-hmc5p.1890a46c378cd82d
calico-system              29m         Normal    Started                          pod/calico-node-hmc5p                                                 spec.initContainers{ebpf-bootstrap}               kubelet, r8s-cp-wlp7h-lhvgq                                            Started container ebpf-bootstrap                                                                                                                                                                                                                                                                                                                                                     29m          1       calico-node-hmc5p.1890a46c3f9c6ba7
calico-system              29m         Normal    Pulling                          pod/calico-node-hmc5p                                                 spec.initContainers{install-cni}                  kubelet, r8s-cp-wlp7h-lhvgq                                            Pulling image "docker.io/rancher/mirrored-calico-cni:v3.31.2"                                                                                                                                                                                                                                                                                                                        29m          1       calico-node-hmc5p.1890a46c8f9ea411
calico-system              29m         Normal    Pulled                           pod/calico-node-hmc5p                                                 spec.initContainers{install-cni}                  kubelet, r8s-cp-wlp7h-lhvgq                                            Successfully pulled image "docker.io/rancher/mirrored-calico-cni:v3.31.2" in 7.851s (7.851s including waiting). Image size: 72114070 bytes.                                                                                                                                                                                                                                          29m          1       calico-node-hmc5p.1890a46e63a0ce49
calico-system              29m         Normal    Created                          pod/calico-node-hmc5p                                                 spec.initContainers{install-cni}                  kubelet, r8s-cp-wlp7h-lhvgq                                            Created container: install-cni                                                                                                                                                                                                                                                                                                                                                       29m          1       calico-node-hmc5p.1890a46e659dd0b3
calico-system              29m         Normal    Started                          pod/calico-node-hmc5p                                                 spec.initContainers{install-cni}                  kubelet, r8s-cp-wlp7h-lhvgq                                            Started container install-cni                                                                                                                                                                                                                                                                                                                                                        29m          1       calico-node-hmc5p.1890a46e6c936704
calico-system              29m         Normal    Pulled                           pod/calico-node-hmc5p                                                 spec.containers{calico-node}                      kubelet, r8s-cp-wlp7h-lhvgq                                            Container image "docker.io/rancher/mirrored-calico-node:v3.31.2" already present on machine                                                                                                                                                                                                                                                                                          29m          1       calico-node-hmc5p.1890a46eabe87707
calico-system              29m         Normal    Created                          pod/calico-node-hmc5p                                                 spec.containers{calico-node}                      kubelet, r8s-cp-wlp7h-lhvgq                                            Created container: calico-node                                                                                                                                                                                                                                                                                                                                                       29m          1       calico-node-hmc5p.1890a46eb13ebd1d
calico-system              29m         Normal    Started                          pod/calico-node-hmc5p                                                 spec.containers{calico-node}                      kubelet, r8s-cp-wlp7h-lhvgq                                            Started container calico-node                                                                                                                                                                                                                                                                                                                                                        29m          1       calico-node-hmc5p.1890a46ebed79b40
calico-system              29m         Warning   Unhealthy                        pod/calico-node-hmc5p                                                 spec.containers{calico-node}                      kubelet, r8s-cp-wlp7h-lhvgq                                            Readiness probe failed: calico/node is not ready: felix is not ready: Get "http://localhost:9099/readiness": dial tcp [::1]:9099: connect: connection refused                                                                                                                                                                                                                        29m          2       calico-node-hmc5p.1890a46ef155c1ae
calico-system              29m         Warning   Unhealthy                        pod/calico-node-hmc5p                                                 spec.containers{calico-node}                      kubelet, r8s-cp-wlp7h-lhvgq                                            Readiness probe failed: calico/node is not ready: felix is not ready: readiness probe reporting 503                                                                                                                                                                                                                                                                                  29m          1       calico-node-hmc5p.1890a46f66d8d775
calico-system              26m         Normal    Scheduled                        pod/calico-node-lfwtj                                                                                                   default-scheduler, default-scheduler-r8s-cp-wlp7h-lhvgq                Successfully assigned calico-system/calico-node-lfwtj to r8s-wk-jnhwv-4xqzn                                                                                                                                                                                                                                                                                                          26m          1       calico-node-lfwtj.1890a494928cfe8f
calico-system              26m         Normal    Pulling                          pod/calico-node-lfwtj                                                 spec.initContainers{flexvol-driver}               kubelet, r8s-wk-jnhwv-4xqzn                                            Pulling image "docker.io/rancher/mirrored-calico-pod2daemon-flexvol:v3.31.2"                                                                                                                                                                                                                                                                                                         26m          1       calico-node-lfwtj.1890a495a9fbe13d
calico-system              26m         Normal    Pulled                           pod/calico-node-lfwtj                                                 spec.initContainers{flexvol-driver}               kubelet, r8s-wk-jnhwv-4xqzn                                            Successfully pulled image "docker.io/rancher/mirrored-calico-pod2daemon-flexvol:v3.31.2" in 5.027s (5.027s including waiting). Image size: 6168017 bytes.                                                                                                                                                                                                                            26m          1       calico-node-lfwtj.1890a496d5a0d575
calico-system              26m         Normal    Created                          pod/calico-node-lfwtj                                                 spec.initContainers{flexvol-driver}               kubelet, r8s-wk-jnhwv-4xqzn                                            Created container: flexvol-driver                                                                                                                                                                                                                                                                                                                                                    26m          1       calico-node-lfwtj.1890a496d7e693ab
calico-system              26m         Normal    Started                          pod/calico-node-lfwtj                                                 spec.initContainers{flexvol-driver}               kubelet, r8s-wk-jnhwv-4xqzn                                            Started container flexvol-driver                                                                                                                                                                                                                                                                                                                                                     26m          1       calico-node-lfwtj.1890a496e0fb647d
calico-system              26m         Normal    Pulling                          pod/calico-node-lfwtj                                                 spec.initContainers{ebpf-bootstrap}               kubelet, r8s-wk-jnhwv-4xqzn                                            Pulling image "docker.io/rancher/mirrored-calico-node:v3.31.2"                                                                                                                                                                                                                                                                                                                       26m          1       calico-node-lfwtj.1890a49712d22d2d
calico-system              26m         Normal    Pulled                           pod/calico-node-lfwtj                                                 spec.initContainers{ebpf-bootstrap}               kubelet, r8s-wk-jnhwv-4xqzn                                            Successfully pulled image "docker.io/rancher/mirrored-calico-node:v3.31.2" in 13.201s (13.201s including waiting). Image size: 159690977 bytes.                                                                                                                                                                                                                                      26m          1       calico-node-lfwtj.1890a49a25b0b849
calico-system              26m         Normal    Created                          pod/calico-node-lfwtj                                                 spec.initContainers{ebpf-bootstrap}               kubelet, r8s-wk-jnhwv-4xqzn                                            Created container: ebpf-bootstrap                                                                                                                                                                                                                                                                                                                                                    26m          1       calico-node-lfwtj.1890a49a2893a298
calico-system              26m         Normal    Started                          pod/calico-node-lfwtj                                                 spec.initContainers{ebpf-bootstrap}               kubelet, r8s-wk-jnhwv-4xqzn                                            Started container ebpf-bootstrap                                                                                                                                                                                                                                                                                                                                                     26m          1       calico-node-lfwtj.1890a49a30a40c19
calico-system              26m         Normal    Pulling                          pod/calico-node-lfwtj                                                 spec.initContainers{install-cni}                  kubelet, r8s-wk-jnhwv-4xqzn                                            Pulling image "docker.io/rancher/mirrored-calico-cni:v3.31.2"                                                                                                                                                                                                                                                                                                                        26m          1       calico-node-lfwtj.1890a49a574700dd
calico-system              26m         Normal    Pulled                           pod/calico-node-lfwtj                                                 spec.initContainers{install-cni}                  kubelet, r8s-wk-jnhwv-4xqzn                                            Successfully pulled image "docker.io/rancher/mirrored-calico-cni:v3.31.2" in 8.093s (8.093s including waiting). Image size: 72114070 bytes.                                                                                                                                                                                                                                          26m          1       calico-node-lfwtj.1890a49c39b059bb
calico-system              26m         Normal    Created                          pod/calico-node-lfwtj                                                 spec.initContainers{install-cni}                  kubelet, r8s-wk-jnhwv-4xqzn                                            Created container: install-cni                                                                                                                                                                                                                                                                                                                                                       26m          1       calico-node-lfwtj.1890a49c3b840819
calico-system              26m         Normal    Started                          pod/calico-node-lfwtj                                                 spec.initContainers{install-cni}                  kubelet, r8s-wk-jnhwv-4xqzn                                            Started container install-cni                                                                                                                                                                                                                                                                                                                                                        26m          1       calico-node-lfwtj.1890a49c42dcfcc7
calico-system              26m         Normal    Pulled                           pod/calico-node-lfwtj                                                 spec.containers{calico-node}                      kubelet, r8s-wk-jnhwv-4xqzn                                            Container image "docker.io/rancher/mirrored-calico-node:v3.31.2" already present on machine                                                                                                                                                                                                                                                                                          26m          1       calico-node-lfwtj.1890a49cad27bb99
calico-system              26m         Normal    Created                          pod/calico-node-lfwtj                                                 spec.containers{calico-node}                      kubelet, r8s-wk-jnhwv-4xqzn                                            Created container: calico-node                                                                                                                                                                                                                                                                                                                                                       26m          1       calico-node-lfwtj.1890a49cafc059f5
calico-system              26m         Normal    Started                          pod/calico-node-lfwtj                                                 spec.containers{calico-node}                      kubelet, r8s-wk-jnhwv-4xqzn                                            Started container calico-node                                                                                                                                                                                                                                                                                                                                                        26m          1       calico-node-lfwtj.1890a49cb7ed14b6
calico-system              26m         Warning   Unhealthy                        pod/calico-node-lfwtj                                                 spec.containers{calico-node}                      kubelet, r8s-wk-jnhwv-4xqzn                                            Readiness probe failed: calico/node is not ready: felix is not ready: Get "http://localhost:9099/readiness": dial tcp [::1]:9099: connect: connection refused                                                                                                                                                                                                                        26m          1       calico-node-lfwtj.1890a49cf0357dfa
calico-system              26m         Warning   Unhealthy                        pod/calico-node-lfwtj                                                 spec.containers{calico-node}                      kubelet, r8s-wk-jnhwv-4xqzn                                            Readiness probe failed: calico/node is not ready: felix is not ready: readiness probe reporting 503                                                                                                                                                                                                                                                                                  26m          1       calico-node-lfwtj.1890a49d2d34a551
calico-system              30m         Normal    SuccessfulCreate                 daemonset/calico-node                                                                                                   daemonset-controller                                                   Created pod: calico-node-hmc5p                                                                                                                                                                                                                                                                                                                                                       30m          1       calico-node.1890a4679c9594e1
calico-system              26m         Normal    SuccessfulCreate                 daemonset/calico-node                                                                                                   daemonset-controller                                                   Created pod: calico-node-88rjf                                                                                                                                                                                                                                                                                                                                                       26m          1       calico-node.1890a49454c01f3c
calico-system              26m         Normal    SuccessfulCreate                 daemonset/calico-node                                                                                                   daemonset-controller                                                   Created pod: calico-node-lfwtj                                                                                                                                                                                                                                                                                                                                                       26m          1       calico-node.1890a4948f267409
calico-system              26m         Normal    SuccessfulCreate                 daemonset/calico-node                                                                                                   daemonset-controller                                                   Created pod: calico-node-f86rc                                                                                                                                                                                                                                                                                                                                                       26m          1       calico-node.1890a494f9682e77
calico-system              26m         Warning   FailedScheduling                 pod/calico-typha-7d8cc95cfb-cfp6q                                                                                       default-scheduler, default-scheduler-r8s-cp-wlp7h-lhvgq                0/4 nodes are available: 1 node(s) didn't have free ports for the requested pod ports, 3 node(s) had untolerated taint {node.kubernetes.io/not-ready: }. preemption: 0/4 nodes are available: 1 node(s) didn't have free ports for the requested pod ports, 3 Preemption is not helpful for scheduling.                                                                              26m          1       calico-typha-7d8cc95cfb-cfp6q.1890a495e4bd6b60
calico-system              26m         Normal    Scheduled                        pod/calico-typha-7d8cc95cfb-cfp6q                                                                                       default-scheduler, default-scheduler-r8s-cp-wlp7h-lhvgq                Successfully assigned calico-system/calico-typha-7d8cc95cfb-cfp6q to r8s-wk-jnhwv-j5k8h                                                                                                                                                                                                                                                                                              26m          1       calico-typha-7d8cc95cfb-cfp6q.1890a49c2ec53da6
calico-system              59s         Warning   DNSConfigForming                 pod/calico-typha-7d8cc95cfb-cfp6q                                                                                       kubelet, r8s-wk-jnhwv-j5k8h                                            Nameserver limits were exceeded, some nameservers have been omitted, the applied nameserver line is: 67.207.67.2 67.207.67.3 67.207.67.2                                                                                                                                                                                                                                             26m          45      calico-typha-7d8cc95cfb-cfp6q.1890a49c4961a6dc
calico-system              26m         Normal    Pulling                          pod/calico-typha-7d8cc95cfb-cfp6q                                     spec.containers{calico-typha}                     kubelet, r8s-wk-jnhwv-j5k8h                                            Pulling image "docker.io/rancher/mirrored-calico-typha:v3.31.2"                                                                                                                                                                                                                                                                                                                      26m          1       calico-typha-7d8cc95cfb-cfp6q.1890a49c55ce3c84
calico-system              26m         Normal    TaintManagerEviction             pod/calico-typha-7d8cc95cfb-cfp6q                                                                                       taint-eviction-controller                                              Cancelling deletion of Pod calico-system/calico-typha-7d8cc95cfb-cfp6q                                                                                                                                                                                                                                                                                                               26m          1       calico-typha-7d8cc95cfb-cfp6q.1890a49c7b4194aa
calico-system              26m         Normal    Pulled                           pod/calico-typha-7d8cc95cfb-cfp6q                                     spec.containers{calico-typha}                     kubelet, r8s-wk-jnhwv-j5k8h                                            Successfully pulled image "docker.io/rancher/mirrored-calico-typha:v3.31.2" in 6.082s (6.083s including waiting). Image size: 36066535 bytes.                                                                                                                                                                                                                                        26m          1       calico-typha-7d8cc95cfb-cfp6q.1890a49dc06c32cb
calico-system              26m         Normal    Created                          pod/calico-typha-7d8cc95cfb-cfp6q                                     spec.containers{calico-typha}                     kubelet, r8s-wk-jnhwv-j5k8h                                            Created container: calico-typha                                                                                                                                                                                                                                                                                                                                                      26m          1       calico-typha-7d8cc95cfb-cfp6q.1890a49dc3c44bc6
calico-system              26m         Normal    Started                          pod/calico-typha-7d8cc95cfb-cfp6q                                     spec.containers{calico-typha}                     kubelet, r8s-wk-jnhwv-j5k8h                                            Started container calico-typha                                                                                                                                                                                                                                                                                                                                                       26m          1       calico-typha-7d8cc95cfb-cfp6q.1890a49dcaf5ffaf
calico-system              30m         Warning   FailedScheduling                 pod/calico-typha-7d8cc95cfb-k8tbj                                                                                       default-scheduler, default-scheduler-r8s-cp-wlp7h-lhvgq                0/1 nodes are available: 1 node(s) had untolerated taint {node.kubernetes.io/not-ready: }. preemption: 0/1 nodes are available: 1 Preemption is not helpful for scheduling.                                                                                                                                                                                                          30m          1       calico-typha-7d8cc95cfb-k8tbj.1890a46795ff9fc4
calico-system              29m         Normal    Scheduled                        pod/calico-typha-7d8cc95cfb-k8tbj                                                                                       default-scheduler, default-scheduler-r8s-cp-wlp7h-lhvgq                Successfully assigned calico-system/calico-typha-7d8cc95cfb-k8tbj to r8s-cp-wlp7h-lhvgq                                                                                                                                                                                                                                                                                              29m          1       calico-typha-7d8cc95cfb-k8tbj.1890a46ea797769f
calico-system              4m20s       Warning   DNSConfigForming                 pod/calico-typha-7d8cc95cfb-k8tbj                                                                                       kubelet, r8s-cp-wlp7h-lhvgq                                            Nameserver limits were exceeded, some nameservers have been omitted, the applied nameserver line is: 67.207.67.3 67.207.67.2 67.207.67.3                                                                                                                                                                                                                                             29m          45      calico-typha-7d8cc95cfb-k8tbj.1890a46ebbd9489a
calico-system              29m         Normal    Pulling                          pod/calico-typha-7d8cc95cfb-k8tbj                                     spec.containers{calico-typha}                     kubelet, r8s-cp-wlp7h-lhvgq                                            Pulling image "docker.io/rancher/mirrored-calico-typha:v3.31.2"                                                                                                                                                                                                                                                                                                                      29m          1       calico-typha-7d8cc95cfb-k8tbj.1890a46ed96a9bb0
calico-system              29m         Normal    Pulled                           pod/calico-typha-7d8cc95cfb-k8tbj                                     spec.containers{calico-typha}                     kubelet, r8s-cp-wlp7h-lhvgq                                            Successfully pulled image "docker.io/rancher/mirrored-calico-typha:v3.31.2" in 5.592s (5.592s including waiting). Image size: 36066535 bytes.                                                                                                                                                                                                                                        29m          1       calico-typha-7d8cc95cfb-k8tbj.1890a47026c2be4c
calico-system              29m         Normal    Created                          pod/calico-typha-7d8cc95cfb-k8tbj                                     spec.containers{calico-typha}                     kubelet, r8s-cp-wlp7h-lhvgq                                            Created container: calico-typha                                                                                                                                                                                                                                                                                                                                                      29m          1       calico-typha-7d8cc95cfb-k8tbj.1890a470294f26e1
calico-system              29m         Normal    Started                          pod/calico-typha-7d8cc95cfb-k8tbj                                     spec.containers{calico-typha}                     kubelet, r8s-cp-wlp7h-lhvgq                                            Started container calico-typha                                                                                                                                                                                                                                                                                                                                                       29m          1       calico-typha-7d8cc95cfb-k8tbj.1890a47031345502
calico-system              30m         Normal    SuccessfulCreate                 replicaset/calico-typha-7d8cc95cfb                                                                                      replicaset-controller                                                  Created pod: calico-typha-7d8cc95cfb-k8tbj                                                                                                                                                                                                                                                                                                                                           30m          1       calico-typha-7d8cc95cfb.1890a46795f65512
calico-system              26m         Normal    SuccessfulCreate                 replicaset/calico-typha-7d8cc95cfb                                                                                      replicaset-controller                                                  Created pod: calico-typha-7d8cc95cfb-cfp6q                                                                                                                                                                                                                                                                                                                                           26m          1       calico-typha-7d8cc95cfb.1890a495e4aebbd9
calico-system              30m         Normal    NoPods                           poddisruptionbudget/calico-typha                                                                                        controllermanager                                                      No matching pods found                                                                                                                                                                                                                                                                                                                                                               30m          2       calico-typha.1890a46792311205
calico-system              30m         Normal    ScalingReplicaSet                deployment/calico-typha                                                                                                 deployment-controller                                                  Scaled up replica set calico-typha-7d8cc95cfb from 0 to 1                                                                                                                                                                                                                                                                                                                            30m          1       calico-typha.1890a467954a6a63
calico-system              26m         Normal    ScalingReplicaSet                deployment/calico-typha                                                                                                 deployment-controller                                                  Scaled up replica set calico-typha-7d8cc95cfb from 1 to 2                                                                                                                                                                                                                                                                                                                            26m          1       calico-typha.1890a495e372935f
cattle-fleet-system        27m         Warning   FailedScheduling                 pod/fleet-agent-66b6b7fd98-6tmk2                                                                                        default-scheduler, default-scheduler-r8s-cp-wlp7h-lhvgq                0/1 nodes are available: 1 node(s) had untolerated taint {node-role.kubernetes.io/control-plane: }. preemption: 0/1 nodes are available: 1 Preemption is not helpful for scheduling.                                                                                                                                                                                                 27m          1       fleet-agent-66b6b7fd98-6tmk2.1890a489c1db83b6
cattle-fleet-system        27m         Warning   FailedScheduling                 pod/fleet-agent-66b6b7fd98-g42m8                                                                                        default-scheduler, default-scheduler-r8s-cp-wlp7h-lhvgq                0/1 nodes are available: 1 node(s) had untolerated taint {node-role.kubernetes.io/control-plane: }. preemption: 0/1 nodes are available: 1 Preemption is not helpful for scheduling.                                                                                                                                                                                                 27m          1       fleet-agent-66b6b7fd98-g42m8.1890a48a601c6723
cattle-fleet-system        26m         Normal    Scheduled                        pod/fleet-agent-66b6b7fd98-g42m8                                                                                        default-scheduler, default-scheduler-r8s-cp-wlp7h-lhvgq                Successfully assigned cattle-fleet-system/fleet-agent-66b6b7fd98-g42m8 to r8s-wk-jnhwv-j5k8h                                                                                                                                                                                                                                                                                         26m          1       fleet-agent-66b6b7fd98-g42m8.1890a49c2f61b30a
cattle-fleet-system        26m         Warning   FailedCreatePodSandBox           pod/fleet-agent-66b6b7fd98-g42m8                                                                                        kubelet, r8s-wk-jnhwv-j5k8h                                            Failed to create pod sandbox: rpc error: code = Unknown desc = failed to setup network for sandbox "828eaace2beb48a356950513d088189200154818d74e21013013b9c29dc3f70c": plugin type="calico" failed (add): stat /var/lib/calico/nodename: no such file or directory: check that the calico/node container is running and has mounted /var/lib/calico/                                 26m          1       fleet-agent-66b6b7fd98-g42m8.1890a49c55fdb941
cattle-fleet-system        26m         Normal    TaintManagerEviction             pod/fleet-agent-66b6b7fd98-g42m8                                                                                        taint-eviction-controller                                              Cancelling deletion of Pod cattle-fleet-system/fleet-agent-66b6b7fd98-g42m8                                                                                                                                                                                                                                                                                                          26m          1       fleet-agent-66b6b7fd98-g42m8.1890a49c7b415c75
cattle-fleet-system        26m         Normal    Pulling                          pod/fleet-agent-66b6b7fd98-g42m8                                      spec.containers{fleet-agent}                      kubelet, r8s-wk-jnhwv-j5k8h                                            Pulling image "rancher/fleet-agent:v0.13.4"                                                                                                                                                                                                                                                                                                                                          26m          1       fleet-agent-66b6b7fd98-g42m8.1890a49f1956963a
cattle-fleet-system        26m         Normal    Pulled                           pod/fleet-agent-66b6b7fd98-g42m8                                      spec.containers{fleet-agent}                      kubelet, r8s-wk-jnhwv-j5k8h                                            Successfully pulled image "rancher/fleet-agent:v0.13.4" in 6.579s (6.58s including waiting). Image size: 29240851 bytes.                                                                                                                                                                                                                                                             26m          1       fleet-agent-66b6b7fd98-g42m8.1890a4a0a189f6a1
cattle-fleet-system        26m         Normal    Created                          pod/fleet-agent-66b6b7fd98-g42m8                                      spec.containers{fleet-agent}                      kubelet, r8s-wk-jnhwv-j5k8h                                            Created container: fleet-agent                                                                                                                                                                                                                                                                                                                                                       26m          1       fleet-agent-66b6b7fd98-g42m8.1890a4a0a28e83ae
cattle-fleet-system        26m         Normal    Started                          pod/fleet-agent-66b6b7fd98-g42m8                                      spec.containers{fleet-agent}                      kubelet, r8s-wk-jnhwv-j5k8h                                            Started container fleet-agent                                                                                                                                                                                                                                                                                                                                                        26m          1       fleet-agent-66b6b7fd98-g42m8.1890a4a0a7b58b33
cattle-fleet-system        27m         Warning   FailedScheduling                 pod/fleet-agent-66b6b7fd98-pldz6                                                                                        default-scheduler, default-scheduler-r8s-cp-wlp7h-lhvgq                0/1 nodes are available: 1 node(s) had untolerated taint {node-role.kubernetes.io/control-plane: }. preemption: 0/1 nodes are available: 1 Preemption is not helpful for scheduling.                                                                                                                                                                                                 27m          1       fleet-agent-66b6b7fd98-pldz6.1890a489fba3139a
cattle-fleet-system        27m         Warning   FailedScheduling                 pod/fleet-agent-66b6b7fd98-rmx6x                                                                                        default-scheduler, default-scheduler-r8s-cp-wlp7h-lhvgq                0/1 nodes are available: 1 node(s) had untolerated taint {node-role.kubernetes.io/control-plane: }. preemption: 0/1 nodes are available: 1 Preemption is not helpful for scheduling.                                                                                                                                                                                                 27m          1       fleet-agent-66b6b7fd98-rmx6x.1890a48849820e9c
cattle-fleet-system        27m         Normal    SuccessfulCreate                 replicaset/fleet-agent-66b6b7fd98                                                                                       replicaset-controller                                                  Created pod: fleet-agent-66b6b7fd98-rmx6x                                                                                                                                                                                                                                                                                                                                            27m          1       fleet-agent-66b6b7fd98.1890a4884952ee84
cattle-fleet-system        27m         Normal    SuccessfulCreate                 replicaset/fleet-agent-66b6b7fd98                                                                                       replicaset-controller                                                  Created pod: fleet-agent-66b6b7fd98-6tmk2                                                                                                                                                                                                                                                                                                                                            27m          1       fleet-agent-66b6b7fd98.1890a489c22e8317
cattle-fleet-system        27m         Normal    SuccessfulCreate                 replicaset/fleet-agent-66b6b7fd98                                                                                       replicaset-controller                                                  Created pod: fleet-agent-66b6b7fd98-pldz6                                                                                                                                                                                                                                                                                                                                            27m          1       fleet-agent-66b6b7fd98.1890a489fbb0c2d2
cattle-fleet-system        27m         Normal    SuccessfulCreate                 replicaset/fleet-agent-66b6b7fd98                                                                                       replicaset-controller                                                  Created pod: fleet-agent-66b6b7fd98-g42m8                                                                                                                                                                                                                                                                                                                                            27m          1       fleet-agent-66b6b7fd98.1890a48a60c57465
cattle-fleet-system        27m         Normal    ScalingReplicaSet                deployment/fleet-agent                                                                                                  deployment-controller                                                  Scaled up replica set fleet-agent-66b6b7fd98 from 0 to 1                                                                                                                                                                                                                                                                                                                             27m          1       fleet-agent.1890a488470df8ae
cattle-fleet-system        27m         Normal    ScalingReplicaSet                deployment/fleet-agent                                                                                                  deployment-controller                                                  Scaled up replica set fleet-agent-66b6b7fd98 from 0 to 1                                                                                                                                                                                                                                                                                                                             27m          1       fleet-agent.1890a489c0e14b55
cattle-fleet-system        27m         Normal    ScalingReplicaSet                deployment/fleet-agent                                                                                                  deployment-controller                                                  Scaled up replica set fleet-agent-66b6b7fd98 from 0 to 1                                                                                                                                                                                                                                                                                                                             27m          1       fleet-agent.1890a489fb1e8be8
cattle-fleet-system        27m         Normal    ScalingReplicaSet                deployment/fleet-agent                                                                                                  deployment-controller                                                  Scaled up replica set fleet-agent-66b6b7fd98 from 0 to 1                                                                                                                                                                                                                                                                                                                             27m          1       fleet-agent.1890a48a5f1d3d03
cattle-system              25m         Normal    SuccessfulCreate                 job/apply-system-agent-upgrader-on-r8s-cp-wlp7h-lhvgq-with-35-a3c65                                                     job-controller                                                         Created pod: apply-system-agent-upgrader-on-r8s-cp-wlp7h-lhvgq-with-35-jbh6t                                                                                                                                                                                                                                                                                                         25m          1       apply-system-agent-upgrader-on-r8s-cp-wlp7h-lhvgq-with-35-a3c65.1890a4a30f7b30dc
cattle-system              25m         Normal    Completed                        job/apply-system-agent-upgrader-on-r8s-cp-wlp7h-lhvgq-with-35-a3c65                                                     job-controller                                                         Job completed                                                                                                                                                                                                                                                                                                                                                                        25m          1       apply-system-agent-upgrader-on-r8s-cp-wlp7h-lhvgq-with-35-a3c65.1890a4a6ab360e4a
cattle-system              25m         Normal    Scheduled                        pod/apply-system-agent-upgrader-on-r8s-cp-wlp7h-lhvgq-with-35-jbh6t                                                     default-scheduler, default-scheduler-r8s-cp-wlp7h-lhvgq                Successfully assigned cattle-system/apply-system-agent-upgrader-on-r8s-cp-wlp7h-lhvgq-with-35-jbh6t to r8s-cp-wlp7h-lhvgq                                                                                                                                                                                                                                                            25m          1       apply-system-agent-upgrader-on-r8s-cp-wlp7h-lhvgq-with-35-jbh6t.1890a4a311f21791
cattle-system              25m         Normal    Pulling                          pod/apply-system-agent-upgrader-on-r8s-cp-wlp7h-lhvgq-with-35-jbh6t   spec.containers{upgrade}                          kubelet, r8s-cp-wlp7h-lhvgq                                            Pulling image "rancher/system-agent:v0.3.13-suc"                                                                                                                                                                                                                                                                                                                                     25m          1       apply-system-agent-upgrader-on-r8s-cp-wlp7h-lhvgq-with-35-jbh6t.1890a4a344a46f47
cattle-system              25m         Normal    Pulled                           pod/apply-system-agent-upgrader-on-r8s-cp-wlp7h-lhvgq-with-35-jbh6t   spec.containers{upgrade}                          kubelet, r8s-cp-wlp7h-lhvgq                                            Successfully pulled image "rancher/system-agent:v0.3.13-suc" in 9.671s (9.671s including waiting). Image size: 69982919 bytes.                                                                                                                                                                                                                                                       25m          1       apply-system-agent-upgrader-on-r8s-cp-wlp7h-lhvgq-with-35-jbh6t.1890a4a5851afd59
cattle-system              25m         Normal    Created                          pod/apply-system-agent-upgrader-on-r8s-cp-wlp7h-lhvgq-with-35-jbh6t   spec.containers{upgrade}                          kubelet, r8s-cp-wlp7h-lhvgq                                            Created container: upgrade                                                                                                                                                                                                                                                                                                                                                           25m          1       apply-system-agent-upgrader-on-r8s-cp-wlp7h-lhvgq-with-35-jbh6t.1890a4a587510b78
cattle-system              25m         Normal    Started                          pod/apply-system-agent-upgrader-on-r8s-cp-wlp7h-lhvgq-with-35-jbh6t   spec.containers{upgrade}                          kubelet, r8s-cp-wlp7h-lhvgq                                            Started container upgrade                                                                                                                                                                                                                                                                                                                                                            25m          1       apply-system-agent-upgrader-on-r8s-cp-wlp7h-lhvgq-with-35-jbh6t.1890a4a58ff774e1
cattle-system              25m         Normal    Scheduled                        pod/apply-system-agent-upgrader-on-r8s-wk-jnhwv-4xqzn-with-35-72mxx                                                     default-scheduler, default-scheduler-r8s-cp-wlp7h-lhvgq                Successfully assigned cattle-system/apply-system-agent-upgrader-on-r8s-wk-jnhwv-4xqzn-with-35-72mxx to r8s-wk-jnhwv-4xqzn                                                                                                                                                                                                                                                            25m          1       apply-system-agent-upgrader-on-r8s-wk-jnhwv-4xqzn-with-35-72mxx.1890a4a3155285db
cattle-system              25m         Normal    Pulling                          pod/apply-system-agent-upgrader-on-r8s-wk-jnhwv-4xqzn-with-35-72mxx   spec.containers{upgrade}                          kubelet, r8s-wk-jnhwv-4xqzn                                            Pulling image "rancher/system-agent:v0.3.13-suc"                                                                                                                                                                                                                                                                                                                                     25m          1       apply-system-agent-upgrader-on-r8s-wk-jnhwv-4xqzn-with-35-72mxx.1890a4a34165d0e9
cattle-system              25m         Normal    Pulled                           pod/apply-system-agent-upgrader-on-r8s-wk-jnhwv-4xqzn-with-35-72mxx   spec.containers{upgrade}                          kubelet, r8s-wk-jnhwv-4xqzn                                            Successfully pulled image "rancher/system-agent:v0.3.13-suc" in 8.801s (8.801s including waiting). Image size: 69982919 bytes.                                                                                                                                                                                                                                                       25m          1       apply-system-agent-upgrader-on-r8s-wk-jnhwv-4xqzn-with-35-72mxx.1890a4a54dfd4ee4
cattle-system              25m         Normal    Created                          pod/apply-system-agent-upgrader-on-r8s-wk-jnhwv-4xqzn-with-35-72mxx   spec.containers{upgrade}                          kubelet, r8s-wk-jnhwv-4xqzn                                            Created container: upgrade                                                                                                                                                                                                                                                                                                                                                           25m          1       apply-system-agent-upgrader-on-r8s-wk-jnhwv-4xqzn-with-35-72mxx.1890a4a5500d9b6b
cattle-system              25m         Normal    Started                          pod/apply-system-agent-upgrader-on-r8s-wk-jnhwv-4xqzn-with-35-72mxx   spec.containers{upgrade}                          kubelet, r8s-wk-jnhwv-4xqzn                                            Started container upgrade                                                                                                                                                                                                                                                                                                                                                            25m          1       apply-system-agent-upgrader-on-r8s-wk-jnhwv-4xqzn-with-35-72mxx.1890a4a55857def1
cattle-system              25m         Normal    SuccessfulCreate                 job/apply-system-agent-upgrader-on-r8s-wk-jnhwv-4xqzn-with-35-f3743                                                     job-controller                                                         Created pod: apply-system-agent-upgrader-on-r8s-wk-jnhwv-4xqzn-with-35-72mxx                                                                                                                                                                                                                                                                                                         25m          1       apply-system-agent-upgrader-on-r8s-wk-jnhwv-4xqzn-with-35-f3743.1890a4a314b9911c
cattle-system              25m         Normal    Completed                        job/apply-system-agent-upgrader-on-r8s-wk-jnhwv-4xqzn-with-35-f3743                                                     job-controller                                                         Job completed                                                                                                                                                                                                                                                                                                                                                                        25m          1       apply-system-agent-upgrader-on-r8s-wk-jnhwv-4xqzn-with-35-f3743.1890a4a69476a7f9
cattle-system              25m         Normal    SuccessfulCreate                 job/apply-system-agent-upgrader-on-r8s-wk-jnhwv-j5k8h-with-35-52ab6                                                     job-controller                                                         Created pod: apply-system-agent-upgrader-on-r8s-wk-jnhwv-j5k8h-with-35-frpl7                                                                                                                                                                                                                                                                                                         25m          1       apply-system-agent-upgrader-on-r8s-wk-jnhwv-j5k8h-with-35-52ab6.1890a4a3197dde65
cattle-system              25m         Normal    Completed                        job/apply-system-agent-upgrader-on-r8s-wk-jnhwv-j5k8h-with-35-52ab6                                                     job-controller                                                         Job completed                                                                                                                                                                                                                                                                                                                                                                        25m          1       apply-system-agent-upgrader-on-r8s-wk-jnhwv-j5k8h-with-35-52ab6.1890a4a650113c3f
cattle-system              25m         Normal    Scheduled                        pod/apply-system-agent-upgrader-on-r8s-wk-jnhwv-j5k8h-with-35-frpl7                                                     default-scheduler, default-scheduler-r8s-cp-wlp7h-lhvgq                Successfully assigned cattle-system/apply-system-agent-upgrader-on-r8s-wk-jnhwv-j5k8h-with-35-frpl7 to r8s-wk-jnhwv-j5k8h                                                                                                                                                                                                                                                            25m          1       apply-system-agent-upgrader-on-r8s-wk-jnhwv-j5k8h-with-35-frpl7.1890a4a31b156bc3
cattle-system              25m         Normal    Pulling                          pod/apply-system-agent-upgrader-on-r8s-wk-jnhwv-j5k8h-with-35-frpl7   spec.containers{upgrade}                          kubelet, r8s-wk-jnhwv-j5k8h                                            Pulling image "rancher/system-agent:v0.3.13-suc"                                                                                                                                                                                                                                                                                                                                     25m          1       apply-system-agent-upgrader-on-r8s-wk-jnhwv-j5k8h-with-35-frpl7.1890a4a347b0481b
cattle-system              25m         Normal    Pulled                           pod/apply-system-agent-upgrader-on-r8s-wk-jnhwv-j5k8h-with-35-frpl7   spec.containers{upgrade}                          kubelet, r8s-wk-jnhwv-j5k8h                                            Successfully pulled image "rancher/system-agent:v0.3.13-suc" in 8.691s (8.691s including waiting). Image size: 69982919 bytes.                                                                                                                                                                                                                                                       25m          1       apply-system-agent-upgrader-on-r8s-wk-jnhwv-j5k8h-with-35-frpl7.1890a4a54dc600a9
cattle-system              25m         Normal    Created                          pod/apply-system-agent-upgrader-on-r8s-wk-jnhwv-j5k8h-with-35-frpl7   spec.containers{upgrade}                          kubelet, r8s-wk-jnhwv-j5k8h                                            Created container: upgrade                                                                                                                                                                                                                                                                                                                                                           25m          1       apply-system-agent-upgrader-on-r8s-wk-jnhwv-j5k8h-with-35-frpl7.1890a4a54f669dc4
cattle-system              25m         Normal    Started                          pod/apply-system-agent-upgrader-on-r8s-wk-jnhwv-j5k8h-with-35-frpl7   spec.containers{upgrade}                          kubelet, r8s-wk-jnhwv-j5k8h                                            Started container upgrade                                                                                                                                                                                                                                                                                                                                                            25m          1       apply-system-agent-upgrader-on-r8s-wk-jnhwv-j5k8h-with-35-frpl7.1890a4a55565a2ad
cattle-system              25m         Normal    Scheduled                        pod/apply-system-agent-upgrader-on-r8s-wk-jnhwv-vpdq4-with-35-7rdfj                                                     default-scheduler, default-scheduler-r8s-cp-wlp7h-lhvgq                Successfully assigned cattle-system/apply-system-agent-upgrader-on-r8s-wk-jnhwv-vpdq4-with-35-7rdfj to r8s-wk-jnhwv-vpdq4                                                                                                                                                                                                                                                            25m          1       apply-system-agent-upgrader-on-r8s-wk-jnhwv-vpdq4-with-35-7rdfj.1890a4a333b1ba64
cattle-system              25m         Normal    Pulling                          pod/apply-system-agent-upgrader-on-r8s-wk-jnhwv-vpdq4-with-35-7rdfj   spec.containers{upgrade}                          kubelet, r8s-wk-jnhwv-vpdq4                                            Pulling image "rancher/system-agent:v0.3.13-suc"                                                                                                                                                                                                                                                                                                                                     25m          1       apply-system-agent-upgrader-on-r8s-wk-jnhwv-vpdq4-with-35-7rdfj.1890a4a351a6bf79
cattle-system              25m         Normal    Pulled                           pod/apply-system-agent-upgrader-on-r8s-wk-jnhwv-vpdq4-with-35-7rdfj   spec.containers{upgrade}                          kubelet, r8s-wk-jnhwv-vpdq4                                            Successfully pulled image "rancher/system-agent:v0.3.13-suc" in 9.227s (9.227s including waiting). Image size: 69982919 bytes.                                                                                                                                                                                                                                                       25m          1       apply-system-agent-upgrader-on-r8s-wk-jnhwv-vpdq4-with-35-7rdfj.1890a4a577ad51c9
cattle-system              25m         Normal    Created                          pod/apply-system-agent-upgrader-on-r8s-wk-jnhwv-vpdq4-with-35-7rdfj   spec.containers{upgrade}                          kubelet, r8s-wk-jnhwv-vpdq4                                            Created container: upgrade                                                                                                                                                                                                                                                                                                                                                           25m          1       apply-system-agent-upgrader-on-r8s-wk-jnhwv-vpdq4-with-35-7rdfj.1890a4a57b72d8d1
cattle-system              25m         Normal    Started                          pod/apply-system-agent-upgrader-on-r8s-wk-jnhwv-vpdq4-with-35-7rdfj   spec.containers{upgrade}                          kubelet, r8s-wk-jnhwv-vpdq4                                            Started container upgrade                                                                                                                                                                                                                                                                                                                                                            25m          1       apply-system-agent-upgrader-on-r8s-wk-jnhwv-vpdq4-with-35-7rdfj.1890a4a58647b8c5
cattle-system              25m         Normal    SuccessfulCreate                 job/apply-system-agent-upgrader-on-r8s-wk-jnhwv-vpdq4-with-35-99476                                                     job-controller                                                         Created pod: apply-system-agent-upgrader-on-r8s-wk-jnhwv-vpdq4-with-35-7rdfj                                                                                                                                                                                                                                                                                                         25m          1       apply-system-agent-upgrader-on-r8s-wk-jnhwv-vpdq4-with-35-99476.1890a4a3308a2d4e
cattle-system              25m         Normal    Completed                        job/apply-system-agent-upgrader-on-r8s-wk-jnhwv-vpdq4-with-35-99476                                                     job-controller                                                         Job completed                                                                                                                                                                                                                                                                                                                                                                        25m          1       apply-system-agent-upgrader-on-r8s-wk-jnhwv-vpdq4-with-35-99476.1890a4a6c6663e66
cattle-system              28m         Normal    Scheduled                        pod/cattle-cluster-agent-59f8f4f496-88mv7                                                                               default-scheduler, default-scheduler-r8s-cp-wlp7h-lhvgq                Successfully assigned cattle-system/cattle-cluster-agent-59f8f4f496-88mv7 to r8s-cp-wlp7h-lhvgq                                                                                                                                                                                                                                                                                      28m          1       cattle-cluster-agent-59f8f4f496-88mv7.1890a4853e5680b9
cattle-system              28m         Normal    Pulled                           pod/cattle-cluster-agent-59f8f4f496-88mv7                             spec.containers{cluster-register}                 kubelet, r8s-cp-wlp7h-lhvgq                                            Container image "rancher/rancher-agent:v2.12.3" already present on machine                                                                                                                                                                                                                                                                                                           28m          1       cattle-cluster-agent-59f8f4f496-88mv7.1890a4857fcae7e2
cattle-system              28m         Normal    Created                          pod/cattle-cluster-agent-59f8f4f496-88mv7                             spec.containers{cluster-register}                 kubelet, r8s-cp-wlp7h-lhvgq                                            Created container: cluster-register                                                                                                                                                                                                                                                                                                                                                  28m          1       cattle-cluster-agent-59f8f4f496-88mv7.1890a485820bff19
cattle-system              28m         Normal    Started                          pod/cattle-cluster-agent-59f8f4f496-88mv7                             spec.containers{cluster-register}                 kubelet, r8s-cp-wlp7h-lhvgq                                            Started container cluster-register                                                                                                                                                                                                                                                                                                                                                   28m          1       cattle-cluster-agent-59f8f4f496-88mv7.1890a48589d1c589
cattle-system              27m         Normal    Killing                          pod/cattle-cluster-agent-59f8f4f496-88mv7                             spec.containers{cluster-register}                 kubelet, r8s-cp-wlp7h-lhvgq                                            Stopping container cluster-register                                                                                                                                                                                                                                                                                                                                                  27m          1       cattle-cluster-agent-59f8f4f496-88mv7.1890a48873f5538e
cattle-system              28m         Normal    SuccessfulCreate                 replicaset/cattle-cluster-agent-59f8f4f496                                                                              replicaset-controller                                                  Created pod: cattle-cluster-agent-59f8f4f496-88mv7                                                                                                                                                                                                                                                                                                                                   28m          1       cattle-cluster-agent-59f8f4f496.1890a4853dbe6f98
cattle-system              27m         Normal    SuccessfulDelete                 replicaset/cattle-cluster-agent-59f8f4f496                                                                              replicaset-controller                                                  Deleted pod: cattle-cluster-agent-59f8f4f496-88mv7                                                                                                                                                                                                                                                                                                                                   27m          1       cattle-cluster-agent-59f8f4f496.1890a48873a3694f
cattle-system              28m         Normal    Scheduled                        pod/cattle-cluster-agent-75665b77db-pfxh9                                                                               default-scheduler, default-scheduler-r8s-cp-wlp7h-lhvgq                Successfully assigned cattle-system/cattle-cluster-agent-75665b77db-pfxh9 to r8s-cp-wlp7h-lhvgq                                                                                                                                                                                                                                                                                      28m          1       cattle-cluster-agent-75665b77db-pfxh9.1890a4827c1dcbec
cattle-system              28m         Normal    Pulled                           pod/cattle-cluster-agent-75665b77db-pfxh9                             spec.containers{cluster-register}                 kubelet, r8s-cp-wlp7h-lhvgq                                            Container image "rancher/rancher-agent:v2.12.3" already present on machine                                                                                                                                                                                                                                                                                                           28m          1       cattle-cluster-agent-75665b77db-pfxh9.1890a482af95c6af
cattle-system              28m         Normal    Created                          pod/cattle-cluster-agent-75665b77db-pfxh9                             spec.containers{cluster-register}                 kubelet, r8s-cp-wlp7h-lhvgq                                            Created container: cluster-register                                                                                                                                                                                                                                                                                                                                                  28m          1       cattle-cluster-agent-75665b77db-pfxh9.1890a482b21624e6
cattle-system              28m         Normal    Started                          pod/cattle-cluster-agent-75665b77db-pfxh9                             spec.containers{cluster-register}                 kubelet, r8s-cp-wlp7h-lhvgq                                            Started container cluster-register                                                                                                                                                                                                                                                                                                                                                   28m          1       cattle-cluster-agent-75665b77db-pfxh9.1890a482bc61661d
cattle-system              28m         Normal    Killing                          pod/cattle-cluster-agent-75665b77db-pfxh9                             spec.containers{cluster-register}                 kubelet, r8s-cp-wlp7h-lhvgq                                            Stopping container cluster-register                                                                                                                                                                                                                                                                                                                                                  28m          1       cattle-cluster-agent-75665b77db-pfxh9.1890a4859d360fcd
cattle-system              28m         Normal    SuccessfulCreate                 replicaset/cattle-cluster-agent-75665b77db                                                                              replicaset-controller                                                  Created pod: cattle-cluster-agent-75665b77db-pfxh9                                                                                                                                                                                                                                                                                                                                   28m          1       cattle-cluster-agent-75665b77db.1890a48279f43097
cattle-system              28m         Normal    SuccessfulDelete                 replicaset/cattle-cluster-agent-75665b77db                                                                              replicaset-controller                                                  Deleted pod: cattle-cluster-agent-75665b77db-pfxh9                                                                                                                                                                                                                                                                                                                                   28m          1       cattle-cluster-agent-75665b77db.1890a4859d98b7f0
cattle-system              27m         Normal    Scheduled                        pod/cattle-cluster-agent-78b58bc994-m6nps                                                                               default-scheduler, default-scheduler-r8s-cp-wlp7h-lhvgq                Successfully assigned cattle-system/cattle-cluster-agent-78b58bc994-m6nps to r8s-cp-wlp7h-lhvgq                                                                                                                                                                                                                                                                                      27m          1       cattle-cluster-agent-78b58bc994-m6nps.1890a488ac4521ba
cattle-system              27m         Normal    Pulled                           pod/cattle-cluster-agent-78b58bc994-m6nps                             spec.containers{cluster-register}                 kubelet, r8s-cp-wlp7h-lhvgq                                            Container image "rancher/rancher-agent:v2.12.3" already present on machine                                                                                                                                                                                                                                                                                                           27m          1       cattle-cluster-agent-78b58bc994-m6nps.1890a489104d867d
cattle-system              27m         Normal    Created                          pod/cattle-cluster-agent-78b58bc994-m6nps                             spec.containers{cluster-register}                 kubelet, r8s-cp-wlp7h-lhvgq                                            Created container: cluster-register                                                                                                                                                                                                                                                                                                                                                  27m          1       cattle-cluster-agent-78b58bc994-m6nps.1890a489129ac81f
cattle-system              27m         Normal    Started                          pod/cattle-cluster-agent-78b58bc994-m6nps                             spec.containers{cluster-register}                 kubelet, r8s-cp-wlp7h-lhvgq                                            Started container cluster-register                                                                                                                                                                                                                                                                                                                                                   27m          1       cattle-cluster-agent-78b58bc994-m6nps.1890a489195e4dd9
cattle-system              27m         Normal    Killing                          pod/cattle-cluster-agent-78b58bc994-m6nps                             spec.containers{cluster-register}                 kubelet, r8s-cp-wlp7h-lhvgq                                            Stopping container cluster-register                                                                                                                                                                                                                                                                                                                                                  27m          1       cattle-cluster-agent-78b58bc994-m6nps.1890a48a8af941e9
cattle-system              27m         Normal    SuccessfulCreate                 replicaset/cattle-cluster-agent-78b58bc994                                                                              replicaset-controller                                                  Created pod: cattle-cluster-agent-78b58bc994-m6nps                                                                                                                                                                                                                                                                                                                                   27m          1       cattle-cluster-agent-78b58bc994.1890a488a9e22cf7
cattle-system              27m         Normal    SuccessfulDelete                 replicaset/cattle-cluster-agent-78b58bc994                                                                              replicaset-controller                                                  Deleted pod: cattle-cluster-agent-78b58bc994-m6nps                                                                                                                                                                                                                                                                                                                                   27m          1       cattle-cluster-agent-78b58bc994.1890a48a8b14e3c8
cattle-system              30m         Warning   FailedScheduling                 pod/cattle-cluster-agent-7fc7966ccd-5c24d                                                                               default-scheduler, default-scheduler-r8s-cp-wlp7h-lhvgq                0/1 nodes are available: 1 node(s) had untolerated taint {node.kubernetes.io/not-ready: }. preemption: 0/1 nodes are available: 1 Preemption is not helpful for scheduling.                                                                                                                                                                                                          30m          1       cattle-cluster-agent-7fc7966ccd-5c24d.1890a45f0df23084
cattle-system              29m         Normal    Scheduled                        pod/cattle-cluster-agent-7fc7966ccd-5c24d                                                                               default-scheduler, default-scheduler-r8s-cp-wlp7h-lhvgq                Successfully assigned cattle-system/cattle-cluster-agent-7fc7966ccd-5c24d to r8s-cp-wlp7h-lhvgq                                                                                                                                                                                                                                                                                      29m          1       cattle-cluster-agent-7fc7966ccd-5c24d.1890a46ea68f00e4
cattle-system              29m         Warning   FailedCreatePodSandBox           pod/cattle-cluster-agent-7fc7966ccd-5c24d                                                                               kubelet, r8s-cp-wlp7h-lhvgq                                            Failed to create pod sandbox: rpc error: code = Unknown desc = failed to setup network for sandbox "5de7edf1fecc21e57aa4978d9affd71475b0904a3c6b6fa46106e5b616ac5c87": plugin type="calico" failed (add): stat /var/lib/calico/nodename: no such file or directory: check that the calico/node container is running and has mounted /var/lib/calico/                                 29m          1       cattle-cluster-agent-7fc7966ccd-5c24d.1890a46ed21eefc0
cattle-system              29m         Normal    Pulling                          pod/cattle-cluster-agent-7fc7966ccd-5c24d                             spec.containers{cluster-register}                 kubelet, r8s-cp-wlp7h-lhvgq                                            Pulling image "rancher/rancher-agent:v2.12.3"                                                                                                                                                                                                                                                                                                                                        29m          1       cattle-cluster-agent-7fc7966ccd-5c24d.1890a471a9904b78
cattle-system              29m         Normal    Pulled                           pod/cattle-cluster-agent-7fc7966ccd-5c24d                             spec.containers{cluster-register}                 kubelet, r8s-cp-wlp7h-lhvgq                                            Successfully pulled image "rancher/rancher-agent:v2.12.3" in 20.642s (20.642s including waiting). Image size: 458621917 bytes.                                                                                                                                                                                                                                                       29m          1       cattle-cluster-agent-7fc7966ccd-5c24d.1890a47677f4445e
cattle-system              28m         Normal    Created                          pod/cattle-cluster-agent-7fc7966ccd-5c24d                             spec.containers{cluster-register}                 kubelet, r8s-cp-wlp7h-lhvgq                                            Created container: cluster-register                                                                                                                                                                                                                                                                                                                                                  29m          4       cattle-cluster-agent-7fc7966ccd-5c24d.1890a47679feda4c
cattle-system              28m         Normal    Started                          pod/cattle-cluster-agent-7fc7966ccd-5c24d                             spec.containers{cluster-register}                 kubelet, r8s-cp-wlp7h-lhvgq                                            Started container cluster-register                                                                                                                                                                                                                                                                                                                                                   29m          4       cattle-cluster-agent-7fc7966ccd-5c24d.1890a4767fc66aaa
cattle-system              28m         Normal    Pulled                           pod/cattle-cluster-agent-7fc7966ccd-5c24d                             spec.containers{cluster-register}                 kubelet, r8s-cp-wlp7h-lhvgq                                            Container image "rancher/rancher-agent:v2.12.3" already present on machine                                                                                                                                                                                                                                                                                                           29m          3       cattle-cluster-agent-7fc7966ccd-5c24d.1890a476a24bec9e
cattle-system              28m         Warning   BackOff                          pod/cattle-cluster-agent-7fc7966ccd-5c24d                             spec.containers{cluster-register}                 kubelet, r8s-cp-wlp7h-lhvgq                                            Back-off restarting failed container cluster-register in pod cattle-cluster-agent-7fc7966ccd-5c24d_cattle-system(4caeff50-4ba7-4cef-9947-4ab2889aab2e)                                                                                                                                                                                                                               28m          3       cattle-cluster-agent-7fc7966ccd-5c24d.1890a478096d53d2
cattle-system              28m         Normal    Killing                          pod/cattle-cluster-agent-7fc7966ccd-5c24d                             spec.containers{cluster-register}                 kubelet, r8s-cp-wlp7h-lhvgq                                            Stopping container cluster-register                                                                                                                                                                                                                                                                                                                                                  28m          1       cattle-cluster-agent-7fc7966ccd-5c24d.1890a482cd451cd6
cattle-system              30m         Normal    SuccessfulCreate                 replicaset/cattle-cluster-agent-7fc7966ccd                                                                              replicaset-controller                                                  Created pod: cattle-cluster-agent-7fc7966ccd-5c24d                                                                                                                                                                                                                                                                                                                                   30m          1       cattle-cluster-agent-7fc7966ccd.1890a45f0c3bd6c6
cattle-system              28m         Normal    SuccessfulDelete                 replicaset/cattle-cluster-agent-7fc7966ccd                                                                              replicaset-controller                                                  Deleted pod: cattle-cluster-agent-7fc7966ccd-5c24d                                                                                                                                                                                                                                                                                                                                   28m          1       cattle-cluster-agent-7fc7966ccd.1890a482ce0d902a
cattle-system              27m         Normal    Scheduled                        pod/cattle-cluster-agent-dbb4889db-4qhf5                                                                                default-scheduler, default-scheduler-r8s-cp-wlp7h-lhvgq                Successfully assigned cattle-system/cattle-cluster-agent-dbb4889db-4qhf5 to r8s-cp-wlp7h-lhvgq                                                                                                                                                                                                                                                                                       27m          1       cattle-cluster-agent-dbb4889db-4qhf5.1890a48a36bec4b4
cattle-system              27m         Normal    Pulled                           pod/cattle-cluster-agent-dbb4889db-4qhf5                              spec.containers{cluster-register}                 kubelet, r8s-cp-wlp7h-lhvgq                                            Container image "rancher/rancher-agent:v2.12.3" already present on machine                                                                                                                                                                                                                                                                                                           27m          1       cattle-cluster-agent-dbb4889db-4qhf5.1890a48a6bf713b1
cattle-system              27m         Normal    Created                          pod/cattle-cluster-agent-dbb4889db-4qhf5                              spec.containers{cluster-register}                 kubelet, r8s-cp-wlp7h-lhvgq                                            Created container: cluster-register                                                                                                                                                                                                                                                                                                                                                  27m          1       cattle-cluster-agent-dbb4889db-4qhf5.1890a48a6dff2501
cattle-system              27m         Normal    Started                          pod/cattle-cluster-agent-dbb4889db-4qhf5                              spec.containers{cluster-register}                 kubelet, r8s-cp-wlp7h-lhvgq                                            Started container cluster-register                                                                                                                                                                                                                                                                                                                                                   27m          1       cattle-cluster-agent-dbb4889db-4qhf5.1890a48a7670ad5a
cattle-system              26m         Normal    Scheduled                        pod/cattle-cluster-agent-dbb4889db-7lb5n                                                                                default-scheduler, default-scheduler-r8s-cp-wlp7h-lhvgq                Successfully assigned cattle-system/cattle-cluster-agent-dbb4889db-7lb5n to r8s-cp-wlp7h-lhvgq                                                                                                                                                                                                                                                                                       26m          1       cattle-cluster-agent-dbb4889db-7lb5n.1890a4945718692d
cattle-system              26m         Normal    Pulled                           pod/cattle-cluster-agent-dbb4889db-7lb5n                              spec.containers{cluster-register}                 kubelet, r8s-cp-wlp7h-lhvgq                                            Container image "rancher/rancher-agent:v2.12.3" already present on machine                                                                                                                                                                                                                                                                                                           26m          1       cattle-cluster-agent-dbb4889db-7lb5n.1890a494b83b881d
cattle-system              26m         Normal    Created                          pod/cattle-cluster-agent-dbb4889db-7lb5n                              spec.containers{cluster-register}                 kubelet, r8s-cp-wlp7h-lhvgq                                            Created container: cluster-register                                                                                                                                                                                                                                                                                                                                                  26m          1       cattle-cluster-agent-dbb4889db-7lb5n.1890a494baf0f047
cattle-system              26m         Normal    Started                          pod/cattle-cluster-agent-dbb4889db-7lb5n                              spec.containers{cluster-register}                 kubelet, r8s-cp-wlp7h-lhvgq                                            Started container cluster-register                                                                                                                                                                                                                                                                                                                                                   26m          1       cattle-cluster-agent-dbb4889db-7lb5n.1890a494cb2ad6e8
cattle-system              27m         Normal    Scheduled                        pod/cattle-cluster-agent-dbb4889db-j2292                                                                                default-scheduler, default-scheduler-r8s-cp-wlp7h-lhvgq                Successfully assigned cattle-system/cattle-cluster-agent-dbb4889db-j2292 to r8s-cp-wlp7h-lhvgq                                                                                                                                                                                                                                                                                       27m          1       cattle-cluster-agent-dbb4889db-j2292.1890a487f5518268
cattle-system              27m         Normal    Pulled                           pod/cattle-cluster-agent-dbb4889db-j2292                              spec.containers{cluster-register}                 kubelet, r8s-cp-wlp7h-lhvgq                                            Container image "rancher/rancher-agent:v2.12.3" already present on machine                                                                                                                                                                                                                                                                                                           27m          1       cattle-cluster-agent-dbb4889db-j2292.1890a48847a298dd
cattle-system              27m         Normal    Created                          pod/cattle-cluster-agent-dbb4889db-j2292                              spec.containers{cluster-register}                 kubelet, r8s-cp-wlp7h-lhvgq                                            Created container: cluster-register                                                                                                                                                                                                                                                                                                                                                  27m          1       cattle-cluster-agent-dbb4889db-j2292.1890a4884c45e3da
cattle-system              27m         Normal    Started                          pod/cattle-cluster-agent-dbb4889db-j2292                              spec.containers{cluster-register}                 kubelet, r8s-cp-wlp7h-lhvgq                                            Started container cluster-register                                                                                                                                                                                                                                                                                                                                                   27m          1       cattle-cluster-agent-dbb4889db-j2292.1890a4885a10d1c6
cattle-system              27m         Normal    Killing                          pod/cattle-cluster-agent-dbb4889db-j2292                              spec.containers{cluster-register}                 kubelet, r8s-cp-wlp7h-lhvgq                                            Stopping container cluster-register                                                                                                                                                                                                                                                                                                                                                  27m          1       cattle-cluster-agent-dbb4889db-j2292.1890a48927cb3f6f
cattle-system              27m         Normal    SuccessfulCreate                 replicaset/cattle-cluster-agent-dbb4889db                                                                               replicaset-controller                                                  Created pod: cattle-cluster-agent-dbb4889db-j2292                                                                                                                                                                                                                                                                                                                                    27m          1       cattle-cluster-agent-dbb4889db.1890a487f406d92e
cattle-system              27m         Normal    SuccessfulDelete                 replicaset/cattle-cluster-agent-dbb4889db                                                                               replicaset-controller                                                  Deleted pod: cattle-cluster-agent-dbb4889db-j2292                                                                                                                                                                                                                                                                                                                                    27m          1       cattle-cluster-agent-dbb4889db.1890a4892621398f
cattle-system              27m         Normal    SuccessfulCreate                 replicaset/cattle-cluster-agent-dbb4889db                                                                               replicaset-controller                                                  Created pod: cattle-cluster-agent-dbb4889db-4qhf5                                                                                                                                                                                                                                                                                                                                    27m          1       cattle-cluster-agent-dbb4889db.1890a48a360c9b93
cattle-system              26m         Normal    SuccessfulCreate                 replicaset/cattle-cluster-agent-dbb4889db                                                                               replicaset-controller                                                  Created pod: cattle-cluster-agent-dbb4889db-7lb5n                                                                                                                                                                                                                                                                                                                                    26m          1       cattle-cluster-agent-dbb4889db.1890a49455726d83
cattle-system              30m         Normal    ScalingReplicaSet                deployment/cattle-cluster-agent                                                                                         deployment-controller                                                  Scaled up replica set cattle-cluster-agent-7fc7966ccd from 0 to 1                                                                                                                                                                                                                                                                                                                    30m          1       cattle-cluster-agent.1890a45ef0b3dc62
cattle-system              28m         Normal    ScalingReplicaSet                deployment/cattle-cluster-agent                                                                                         deployment-controller                                                  Scaled up replica set cattle-cluster-agent-75665b77db from 0 to 1                                                                                                                                                                                                                                                                                                                    28m          1       cattle-cluster-agent.1890a482776b7453
cattle-system              28m         Normal    ScalingReplicaSet                deployment/cattle-cluster-agent                                                                                         deployment-controller                                                  Scaled down replica set cattle-cluster-agent-7fc7966ccd from 1 to 0                                                                                                                                                                                                                                                                                                                  28m          1       cattle-cluster-agent.1890a482cbe76e18
cattle-system              28m         Normal    ScalingReplicaSet                deployment/cattle-cluster-agent                                                                                         deployment-controller                                                  Scaled up replica set cattle-cluster-agent-59f8f4f496 from 0 to 1                                                                                                                                                                                                                                                                                                                    28m          1       cattle-cluster-agent.1890a4853d1a5700
cattle-system              28m         Normal    ScalingReplicaSet                deployment/cattle-cluster-agent                                                                                         deployment-controller                                                  Scaled down replica set cattle-cluster-agent-75665b77db from 1 to 0                                                                                                                                                                                                                                                                                                                  28m          1       cattle-cluster-agent.1890a4859afe4f78
cattle-system              27m         Normal    ScalingReplicaSet                deployment/cattle-cluster-agent                                                                                         deployment-controller                                                  Scaled up replica set cattle-cluster-agent-dbb4889db from 0 to 1                                                                                                                                                                                                                                                                                                                     27m          2       cattle-cluster-agent.1890a487f25f1c70
cattle-system              27m         Normal    ScalingReplicaSet                deployment/cattle-cluster-agent                                                                                         deployment-controller                                                  Scaled down replica set cattle-cluster-agent-59f8f4f496 from 1 to 0                                                                                                                                                                                                                                                                                                                  27m          1       cattle-cluster-agent.1890a48871a809b5
cattle-system              27m         Normal    ScalingReplicaSet                deployment/cattle-cluster-agent                                                                                         deployment-controller                                                  Scaled up replica set cattle-cluster-agent-78b58bc994 from 0 to 1                                                                                                                                                                                                                                                                                                                    27m          1       cattle-cluster-agent.1890a488a89598b9
cattle-system              27m         Normal    ScalingReplicaSet                deployment/cattle-cluster-agent                                                                                         deployment-controller                                                  Scaled down replica set cattle-cluster-agent-dbb4889db from 1 to 0                                                                                                                                                                                                                                                                                                                   27m          1       cattle-cluster-agent.1890a48923b6be30
cattle-system              26m         Normal    ScalingReplicaSet                deployment/cattle-cluster-agent                                                                                         deployment-controller                                                  (combined from similar events): Scaled up replica set cattle-cluster-agent-dbb4889db from 1 to 2                                                                                                                                                                                                                                                                                     27m          2       cattle-cluster-agent.1890a48a8a42cb92
cattle-system              26m         Normal    Scheduled                        pod/helm-operation-4l78f                                                                                                default-scheduler, default-scheduler-r8s-cp-wlp7h-lhvgq                Successfully assigned cattle-system/helm-operation-4l78f to r8s-wk-jnhwv-vpdq4                                                                                                                                                                                                                                                                                                       26m          1       helm-operation-4l78f.1890a49d5d678c87
cattle-system              26m         Normal    Pulling                          pod/helm-operation-4l78f                                              spec.initContainers{init-kubeconfig-volume}       kubelet, r8s-wk-jnhwv-vpdq4                                            Pulling image "rancher/shell:v0.5.0"                                                                                                                                                                                                                                                                                                                                                 26m          1       helm-operation-4l78f.1890a49d86e81d2f
cattle-system              26m         Normal    Pulled                           pod/helm-operation-4l78f                                              spec.initContainers{init-kubeconfig-volume}       kubelet, r8s-wk-jnhwv-vpdq4                                            Successfully pulled image "rancher/shell:v0.5.0" in 11.354s (11.354s including waiting). Image size: 109610501 bytes.                                                                                                                                                                                                                                                                26m          1       helm-operation-4l78f.1890a4a02baef606
cattle-system              26m         Normal    Created                          pod/helm-operation-4l78f                                              spec.initContainers{init-kubeconfig-volume}       kubelet, r8s-wk-jnhwv-vpdq4                                            Created container: init-kubeconfig-volume                                                                                                                                                                                                                                                                                                                                            26m          1       helm-operation-4l78f.1890a4a02f56d614
cattle-system              26m         Normal    Started                          pod/helm-operation-4l78f                                              spec.initContainers{init-kubeconfig-volume}       kubelet, r8s-wk-jnhwv-vpdq4                                            Started container init-kubeconfig-volume                                                                                                                                                                                                                                                                                                                                             26m          1       helm-operation-4l78f.1890a4a035d81898
cattle-system              26m         Normal    Pulled                           pod/helm-operation-4l78f                                              spec.containers{helm}                             kubelet, r8s-wk-jnhwv-vpdq4                                            Container image "rancher/shell:v0.5.0" already present on machine                                                                                                                                                                                                                                                                                                                    26m          1       helm-operation-4l78f.1890a4a05c982220
cattle-system              26m         Normal    Created                          pod/helm-operation-4l78f                                              spec.containers{helm}                             kubelet, r8s-wk-jnhwv-vpdq4                                            Created container: helm                                                                                                                                                                                                                                                                                                                                                              26m          1       helm-operation-4l78f.1890a4a05e7ea02c
cattle-system              26m         Normal    Started                          pod/helm-operation-4l78f                                              spec.containers{helm}                             kubelet, r8s-wk-jnhwv-vpdq4                                            Started container helm                                                                                                                                                                                                                                                                                                                                                               26m          1       helm-operation-4l78f.1890a4a06493dd58
cattle-system              26m         Normal    Pulled                           pod/helm-operation-4l78f                                              spec.containers{proxy}                            kubelet, r8s-wk-jnhwv-vpdq4                                            Container image "rancher/shell:v0.5.0" already present on machine                                                                                                                                                                                                                                                                                                                    26m          1       helm-operation-4l78f.1890a4a064a1927a
cattle-system              26m         Normal    Created                          pod/helm-operation-4l78f                                              spec.containers{proxy}                            kubelet, r8s-wk-jnhwv-vpdq4                                            Created container: proxy                                                                                                                                                                                                                                                                                                                                                             26m          1       helm-operation-4l78f.1890a4a0668a53de
cattle-system              26m         Normal    Started                          pod/helm-operation-4l78f                                              spec.containers{proxy}                            kubelet, r8s-wk-jnhwv-vpdq4                                            Started container proxy                                                                                                                                                                                                                                                                                                                                                              26m          1       helm-operation-4l78f.1890a4a06d2b1e42
cattle-system              25m         Normal    Scheduled                        pod/helm-operation-7dwbk                                                                                                default-scheduler, default-scheduler-r8s-cp-wlp7h-lhvgq                Successfully assigned cattle-system/helm-operation-7dwbk to r8s-wk-jnhwv-vpdq4                                                                                                                                                                                                                                                                                                       25m          1       helm-operation-7dwbk.1890a4a3d897d963
cattle-system              25m         Normal    Pulled                           pod/helm-operation-7dwbk                                              spec.initContainers{init-kubeconfig-volume}       kubelet, r8s-wk-jnhwv-vpdq4                                            Container image "rancher/shell:v0.5.0" already present on machine                                                                                                                                                                                                                                                                                                                    25m          1       helm-operation-7dwbk.1890a4a4005c0858
cattle-system              25m         Normal    Created                          pod/helm-operation-7dwbk                                              spec.initContainers{init-kubeconfig-volume}       kubelet, r8s-wk-jnhwv-vpdq4                                            Created container: init-kubeconfig-volume                                                                                                                                                                                                                                                                                                                                            25m          1       helm-operation-7dwbk.1890a4a402d75572
cattle-system              25m         Normal    Started                          pod/helm-operation-7dwbk                                              spec.initContainers{init-kubeconfig-volume}       kubelet, r8s-wk-jnhwv-vpdq4                                            Started container init-kubeconfig-volume                                                                                                                                                                                                                                                                                                                                             25m          1       helm-operation-7dwbk.1890a4a409cff227
cattle-system              25m         Normal    Pulled                           pod/helm-operation-7dwbk                                              spec.containers{helm}                             kubelet, r8s-wk-jnhwv-vpdq4                                            Container image "rancher/shell:v0.5.0" already present on machine                                                                                                                                                                                                                                                                                                                    25m          1       helm-operation-7dwbk.1890a4a41b3aa9c2
cattle-system              25m         Normal    Created                          pod/helm-operation-7dwbk                                              spec.containers{helm}                             kubelet, r8s-wk-jnhwv-vpdq4                                            Created container: helm                                                                                                                                                                                                                                                                                                                                                              25m          1       helm-operation-7dwbk.1890a4a41d5e01df
cattle-system              25m         Normal    Started                          pod/helm-operation-7dwbk                                              spec.containers{helm}                             kubelet, r8s-wk-jnhwv-vpdq4                                            Started container helm                                                                                                                                                                                                                                                                                                                                                               25m          1       helm-operation-7dwbk.1890a4a424fac412
cattle-system              25m         Normal    Pulled                           pod/helm-operation-7dwbk                                              spec.containers{proxy}                            kubelet, r8s-wk-jnhwv-vpdq4                                            Container image "rancher/shell:v0.5.0" already present on machine                                                                                                                                                                                                                                                                                                                    25m          1       helm-operation-7dwbk.1890a4a4250a48ba
cattle-system              25m         Normal    Created                          pod/helm-operation-7dwbk                                              spec.containers{proxy}                            kubelet, r8s-wk-jnhwv-vpdq4                                            Created container: proxy                                                                                                                                                                                                                                                                                                                                                             25m          1       helm-operation-7dwbk.1890a4a4273e1c28
cattle-system              25m         Normal    Started                          pod/helm-operation-7dwbk                                              spec.containers{proxy}                            kubelet, r8s-wk-jnhwv-vpdq4                                            Started container proxy                                                                                                                                                                                                                                                                                                                                                              25m          1       helm-operation-7dwbk.1890a4a42dfad321
cattle-system              27m         Normal    Scheduled                        pod/helm-operation-lcgjt                                                                                                default-scheduler, default-scheduler-r8s-cp-wlp7h-lhvgq                Successfully assigned cattle-system/helm-operation-lcgjt to r8s-cp-wlp7h-lhvgq                                                                                                                                                                                                                                                                                                       27m          1       helm-operation-lcgjt.1890a4928166f6eb
cattle-system              27m         Normal    Pulling                          pod/helm-operation-lcgjt                                              spec.initContainers{init-kubeconfig-volume}       kubelet, r8s-cp-wlp7h-lhvgq                                            Pulling image "rancher/shell:v0.5.0"                                                                                                                                                                                                                                                                                                                                                 27m          1       helm-operation-lcgjt.1890a492aad29b72
cattle-system              26m         Normal    Pulled                           pod/helm-operation-lcgjt                                              spec.initContainers{init-kubeconfig-volume}       kubelet, r8s-cp-wlp7h-lhvgq                                            Successfully pulled image "rancher/shell:v0.5.0" in 12.844s (12.844s including waiting). Image size: 109610501 bytes.                                                                                                                                                                                                                                                                26m          1       helm-operation-lcgjt.1890a495a86bc374
cattle-system              26m         Normal    Created                          pod/helm-operation-lcgjt                                              spec.initContainers{init-kubeconfig-volume}       kubelet, r8s-cp-wlp7h-lhvgq                                            Created container: init-kubeconfig-volume                                                                                                                                                                                                                                                                                                                                            26m          1       helm-operation-lcgjt.1890a495ab1806a0
cattle-system              26m         Normal    Started                          pod/helm-operation-lcgjt                                              spec.initContainers{init-kubeconfig-volume}       kubelet, r8s-cp-wlp7h-lhvgq                                            Started container init-kubeconfig-volume                                                                                                                                                                                                                                                                                                                                             26m          1       helm-operation-lcgjt.1890a495b29376bd
cattle-system              26m         Normal    Pulled                           pod/helm-operation-lcgjt                                              spec.containers{helm}                             kubelet, r8s-cp-wlp7h-lhvgq                                            Container image "rancher/shell:v0.5.0" already present on machine                                                                                                                                                                                                                                                                                                                    26m          1       helm-operation-lcgjt.1890a495c301434f
cattle-system              26m         Normal    Created                          pod/helm-operation-lcgjt                                              spec.containers{helm}                             kubelet, r8s-cp-wlp7h-lhvgq                                            Created container: helm                                                                                                                                                                                                                                                                                                                                                              26m          1       helm-operation-lcgjt.1890a495c5cd660e
cattle-system              26m         Normal    Started                          pod/helm-operation-lcgjt                                              spec.containers{helm}                             kubelet, r8s-cp-wlp7h-lhvgq                                            Started container helm                                                                                                                                                                                                                                                                                                                                                               26m          1       helm-operation-lcgjt.1890a495cc7cf238
cattle-system              26m         Normal    Pulled                           pod/helm-operation-lcgjt                                              spec.containers{proxy}                            kubelet, r8s-cp-wlp7h-lhvgq                                            Container image "rancher/shell:v0.5.0" already present on machine                                                                                                                                                                                                                                                                                                                    26m          1       helm-operation-lcgjt.1890a495cc927662
cattle-system              26m         Normal    Created                          pod/helm-operation-lcgjt                                              spec.containers{proxy}                            kubelet, r8s-cp-wlp7h-lhvgq                                            Created container: proxy                                                                                                                                                                                                                                                                                                                                                             26m          1       helm-operation-lcgjt.1890a495ceb9dbfb
cattle-system              26m         Normal    Started                          pod/helm-operation-lcgjt                                              spec.containers{proxy}                            kubelet, r8s-cp-wlp7h-lhvgq                                            Started container proxy                                                                                                                                                                                                                                                                                                                                                              26m          1       helm-operation-lcgjt.1890a495d7efcbaa
cattle-system              26m         Normal    Scheduled                        pod/rancher-webhook-65bdfb464d-b562n                                                                                    default-scheduler, default-scheduler-r8s-cp-wlp7h-lhvgq                Successfully assigned cattle-system/rancher-webhook-65bdfb464d-b562n to r8s-cp-wlp7h-lhvgq                                                                                                                                                                                                                                                                                           26m          1       rancher-webhook-65bdfb464d-b562n.1890a49672418d18
cattle-system              26m         Normal    Pulling                          pod/rancher-webhook-65bdfb464d-b562n                                  spec.containers{rancher-webhook}                  kubelet, r8s-cp-wlp7h-lhvgq                                            Pulling image "rancher/rancher-webhook:v0.8.3"                                                                                                                                                                                                                                                                                                                                       26m          1       rancher-webhook-65bdfb464d-b562n.1890a496b643198f
cattle-system              26m         Normal    Pulled                           pod/rancher-webhook-65bdfb464d-b562n                                  spec.containers{rancher-webhook}                  kubelet, r8s-cp-wlp7h-lhvgq                                            Successfully pulled image "rancher/rancher-webhook:v0.8.3" in 6.599s (6.599s including waiting). Image size: 27164439 bytes.                                                                                                                                                                                                                                                         26m          1       rancher-webhook-65bdfb464d-b562n.1890a4983fa4360f
cattle-system              26m         Normal    Created                          pod/rancher-webhook-65bdfb464d-b562n                                  spec.containers{rancher-webhook}                  kubelet, r8s-cp-wlp7h-lhvgq                                            Created container: rancher-webhook                                                                                                                                                                                                                                                                                                                                                   26m          1       rancher-webhook-65bdfb464d-b562n.1890a49841ac76fb
cattle-system              26m         Normal    Started                          pod/rancher-webhook-65bdfb464d-b562n                                  spec.containers{rancher-webhook}                  kubelet, r8s-cp-wlp7h-lhvgq                                            Started container rancher-webhook                                                                                                                                                                                                                                                                                                                                                    26m          1       rancher-webhook-65bdfb464d-b562n.1890a4984aa85f7c
cattle-system              26m         Warning   Unhealthy                        pod/rancher-webhook-65bdfb464d-b562n                                  spec.containers{rancher-webhook}                  kubelet, r8s-cp-wlp7h-lhvgq                                            Startup probe failed: HTTP probe failed with statuscode: 500                                                                                                                                                                                                                                                                                                                         26m          3       rancher-webhook-65bdfb464d-b562n.1890a498d90c5940
cattle-system              26m         Normal    SuccessfulCreate                 replicaset/rancher-webhook-65bdfb464d                                                                                   replicaset-controller                                                  Created pod: rancher-webhook-65bdfb464d-b562n                                                                                                                                                                                                                                                                                                                                        26m          1       rancher-webhook-65bdfb464d.1890a4966fe6f8bd
cattle-system              26m         Normal    ScalingReplicaSet                deployment/rancher-webhook                                                                                              deployment-controller                                                  Scaled up replica set rancher-webhook-65bdfb464d from 0 to 1                                                                                                                                                                                                                                                                                                                         26m          1       rancher-webhook.1890a4966f4883cd
cattle-system              25m         Normal    Validated                        plan/system-agent-upgrader-windows                                                                                      system-upgrade-controller, r8s-cp-wlp7h-lhvgq                          Plan is valid                                                                                                                                                                                                                                                                                                                                                                        25m          1       system-agent-upgrader-windows.1890a4a2d1721e86
cattle-system              25m         Normal    Resolved                         plan/system-agent-upgrader-windows                                                                                      system-upgrade-controller, r8s-cp-wlp7h-lhvgq                          Resolved latest version from Spec.Version: v0.5.2                                                                                                                                                                                                                                                                                                                                    25m          1       system-agent-upgrader-windows.1890a4a2d1729c60
cattle-system              25m         Normal    Complete                         plan/system-agent-upgrader-windows                                                                                      system-upgrade-controller, r8s-cp-wlp7h-lhvgq                          Jobs complete for version v0.5.2. Hash: d3daa58007f2177e17a5501450f16ac77f8cd5a32431ca69f441c613                                                                                                                                                                                                                                                                                     25m          1       system-agent-upgrader-windows.1890a4a2d30967ab
cattle-system              25m         Normal    Validated                        plan/system-agent-upgrader                                                                                              system-upgrade-controller, r8s-cp-wlp7h-lhvgq                          Plan is valid                                                                                                                                                                                                                                                                                                                                                                        25m          1       system-agent-upgrader.1890a4a2ce1338ab
cattle-system              25m         Normal    Resolved                         plan/system-agent-upgrader                                                                                              system-upgrade-controller, r8s-cp-wlp7h-lhvgq                          Resolved latest version from Spec.Version: v0.3.13-suc                                                                                                                                                                                                                                                                                                                               25m          1       system-agent-upgrader.1890a4a2ce139412
cattle-system              25m         Normal    SyncJob                          plan/system-agent-upgrader                                                                                              system-upgrade-controller, r8s-cp-wlp7h-lhvgq                          Jobs synced for version v0.3.13-suc on Nodes r8s-cp-wlp7h-lhvgq,r8s-wk-jnhwv-4xqzn,r8s-wk-jnhwv-j5k8h,r8s-wk-jnhwv-vpdq4. Hash: 35e4ef60455ea256999b11198ce94d970705e7c2df7e106aaa25a149                                                                                                                                                                                             25m          2       system-agent-upgrader.1890a4a2d2a01a7d
cattle-system              10m         Normal    JobComplete                      plan/system-agent-upgrader                                                                                              system-upgrade-controller, r8s-cp-wlp7h-lhvgq                          Job completed on Node r8s-wk-jnhwv-j5k8h                                                                                                                                                                                                                                                                                                                                             25m          3       system-agent-upgrader.1890a4a650a15578
cattle-system              25m         Normal    SyncJob                          plan/system-agent-upgrader                                                                                              system-upgrade-controller, r8s-cp-wlp7h-lhvgq                          Jobs synced for version v0.3.13-suc on Nodes r8s-cp-wlp7h-lhvgq,r8s-wk-jnhwv-4xqzn,r8s-wk-jnhwv-vpdq4. Hash: 35e4ef60455ea256999b11198ce94d970705e7c2df7e106aaa25a149                                                                                                                                                                                                                25m          1       system-agent-upgrader.1890a4a651aeda72
cattle-system              10m         Normal    JobComplete                      plan/system-agent-upgrader                                                                                              system-upgrade-controller, r8s-cp-wlp7h-lhvgq                          Job completed on Node r8s-wk-jnhwv-4xqzn                                                                                                                                                                                                                                                                                                                                             25m          3       system-agent-upgrader.1890a4a6959f16bb
cattle-system              25m         Normal    SyncJob                          plan/system-agent-upgrader                                                                                              system-upgrade-controller, r8s-cp-wlp7h-lhvgq                          Jobs synced for version v0.3.13-suc on Nodes r8s-cp-wlp7h-lhvgq,r8s-wk-jnhwv-vpdq4. Hash: 35e4ef60455ea256999b11198ce94d970705e7c2df7e106aaa25a149                                                                                                                                                                                                                                   25m          2       system-agent-upgrader.1890a4a699d3eac0
cattle-system              10m         Normal    JobComplete                      plan/system-agent-upgrader                                                                                              system-upgrade-controller, r8s-cp-wlp7h-lhvgq                          Job completed on Node r8s-cp-wlp7h-lhvgq                                                                                                                                                                                                                                                                                                                                             25m          2       system-agent-upgrader.1890a4a6ac44dabb
cattle-system              25m         Normal    SyncJob                          plan/system-agent-upgrader                                                                                              system-upgrade-controller, r8s-cp-wlp7h-lhvgq                          Jobs synced for version v0.3.13-suc on Nodes r8s-wk-jnhwv-vpdq4. Hash: 35e4ef60455ea256999b11198ce94d970705e7c2df7e106aaa25a149                                                                                                                                                                                                                                                      25m          1       system-agent-upgrader.1890a4a6bb347656
cattle-system              10m         Normal    JobComplete                      plan/system-agent-upgrader                                                                                              system-upgrade-controller, r8s-cp-wlp7h-lhvgq                          Job completed on Node r8s-wk-jnhwv-vpdq4                                                                                                                                                                                                                                                                                                                                             25m          3       system-agent-upgrader.1890a4a6c8b60a93
cattle-system              25m         Normal    Complete                         plan/system-agent-upgrader                                                                                              system-upgrade-controller, r8s-cp-wlp7h-lhvgq                          Jobs complete for version v0.3.13-suc. Hash: 35e4ef60455ea256999b11198ce94d970705e7c2df7e106aaa25a149                                                                                                                                                                                                                                                                                25m          1       system-agent-upgrader.1890a4a6ca6d2344
cattle-system              26m         Normal    Scheduled                        pod/system-upgrade-controller-c84595cc6-hzbwt                                                                           default-scheduler, default-scheduler-r8s-cp-wlp7h-lhvgq                Successfully assigned cattle-system/system-upgrade-controller-c84595cc6-hzbwt to r8s-cp-wlp7h-lhvgq                                                                                                                                                                                                                                                                                  26m          1       system-upgrade-controller-c84595cc6-hzbwt.1890a4a0c93cd5f3
cattle-system              26m         Normal    Pulling                          pod/system-upgrade-controller-c84595cc6-hzbwt                         spec.containers{system-upgrade-controller}        kubelet, r8s-cp-wlp7h-lhvgq                                            Pulling image "rancher/system-upgrade-controller:v0.16.3"                                                                                                                                                                                                                                                                                                                            26m          1       system-upgrade-controller-c84595cc6-hzbwt.1890a4a0fa30d031
cattle-system              25m         Normal    Pulled                           pod/system-upgrade-controller-c84595cc6-hzbwt                         spec.containers{system-upgrade-controller}        kubelet, r8s-cp-wlp7h-lhvgq                                            Successfully pulled image "rancher/system-upgrade-controller:v0.16.3" in 5.918s (5.918s including waiting). Image size: 14782583 bytes.                                                                                                                                                                                                                                              25m          1       system-upgrade-controller-c84595cc6-hzbwt.1890a4a25af148c1
cattle-system              25m         Normal    Created                          pod/system-upgrade-controller-c84595cc6-hzbwt                         spec.containers{system-upgrade-controller}        kubelet, r8s-cp-wlp7h-lhvgq                                            Created container: system-upgrade-controller                                                                                                                                                                                                                                                                                                                                         25m          1       system-upgrade-controller-c84595cc6-hzbwt.1890a4a25d3cac15
cattle-system              25m         Normal    Started                          pod/system-upgrade-controller-c84595cc6-hzbwt                         spec.containers{system-upgrade-controller}        kubelet, r8s-cp-wlp7h-lhvgq                                            Started container system-upgrade-controller                                                                                                                                                                                                                                                                                                                                          25m          1       system-upgrade-controller-c84595cc6-hzbwt.1890a4a27492d282
cattle-system              26m         Normal    SuccessfulCreate                 replicaset/system-upgrade-controller-c84595cc6                                                                          replicaset-controller                                                  Created pod: system-upgrade-controller-c84595cc6-hzbwt                                                                                                                                                                                                                                                                                                                               26m          1       system-upgrade-controller-c84595cc6.1890a4a0c82b2e76
cattle-system              26m         Normal    ScalingReplicaSet                deployment/system-upgrade-controller                                                                                    deployment-controller                                                  Scaled up replica set system-upgrade-controller-c84595cc6 from 0 to 1                                                                                                                                                                                                                                                                                                                26m          1       system-upgrade-controller.1890a4a0c7426dbd
default                    31m         Warning   InvalidDiskCapacity              node/r8s-cp-wlp7h-lhvgq                                                                                                 kubelet, r8s-cp-wlp7h-lhvgq                                            invalid capacity 0 on image filesystem                                                                                                                                                                                                                                                                                                                                               31m          1       r8s-cp-wlp7h-lhvgq.1890a45529fd4bd5
default                    31m         Normal    NodeHasSufficientMemory          node/r8s-cp-wlp7h-lhvgq                                                                                                 kubelet, r8s-cp-wlp7h-lhvgq                                            Node r8s-cp-wlp7h-lhvgq status is now: NodeHasSufficientMemory                                                                                                                                                                                                                                                                                                                       31m          8       r8s-cp-wlp7h-lhvgq.1890a4552bf15878
default                    31m         Normal    NodeHasNoDiskPressure            node/r8s-cp-wlp7h-lhvgq                                                                                                 kubelet, r8s-cp-wlp7h-lhvgq                                            Node r8s-cp-wlp7h-lhvgq status is now: NodeHasNoDiskPressure                                                                                                                                                                                                                                                                                                                         31m          8       r8s-cp-wlp7h-lhvgq.1890a4552bf18e95
default                    31m         Normal    NodeHasSufficientPID             node/r8s-cp-wlp7h-lhvgq                                                                                                 kubelet, r8s-cp-wlp7h-lhvgq                                            Node r8s-cp-wlp7h-lhvgq status is now: NodeHasSufficientPID                                                                                                                                                                                                                                                                                                                          31m          7       r8s-cp-wlp7h-lhvgq.1890a4552bf1aa69
default                    31m         Normal    NodeAllocatableEnforced          node/r8s-cp-wlp7h-lhvgq                                                                                                 kubelet, r8s-cp-wlp7h-lhvgq                                            Updated Node Allocatable limit across pods                                                                                                                                                                                                                                                                                                                                           31m          1       r8s-cp-wlp7h-lhvgq.1890a4552f75f3ea
default                    30m         Normal    CertificateExpirationOK          node/r8s-cp-wlp7h-lhvgq                                                                                                 rke2-cert-monitor, r8s-cp-wlp7h-lhvgq                                  Node and Certificate Authority certificates managed by rke2 are OK                                                                                                                                                                                                                                                                                                                   30m          1       r8s-cp-wlp7h-lhvgq.1890a45d41adb8d2
default                    30m         Normal    NodePasswordValidationComplete   node/r8s-cp-wlp7h-lhvgq                                                                                                 rke2-supervisor, r8s-cp-wlp7h-lhvgq                                    Deferred node password secret validation complete                                                                                                                                                                                                                                                                                                                                    30m          1       r8s-cp-wlp7h-lhvgq.1890a45e0d5864c1
default                    30m         Normal    Starting                         node/r8s-cp-wlp7h-lhvgq                                                                                                 kube-proxy, kube-proxy-r8s-cp-wlp7h-lhvgq                                                                                                                                                                                                                                                                                                                                                                                                                   30m          1       r8s-cp-wlp7h-lhvgq.1890a45e23110e15
default                    30m         Normal    Synced                           node/r8s-cp-wlp7h-lhvgq                                                                                                 cloud-node-controller                                                  Node synced successfully                                                                                                                                                                                                                                                                                                                                                             30m          1       r8s-cp-wlp7h-lhvgq.1890a45e2cf09f78
default                    30m         Normal    RegisteredNode                   node/r8s-cp-wlp7h-lhvgq                                                                                                 node-controller                                                        Node r8s-cp-wlp7h-lhvgq event: Registered Node r8s-cp-wlp7h-lhvgq in Controller                                                                                                                                                                                                                                                                                                      30m          1       r8s-cp-wlp7h-lhvgq.1890a45ec3e3281b
default                    25m         Normal    Starting                         node/r8s-cp-wlp7h-lhvgq                                                                                                 system-upgrade-controller, r8s-cp-wlp7h-lhvgq                          system-upgrade-controller v0.16.3 (a8d5a37) starting leader election for cattle-system/system-upgrade-controller                                                                                                                                                                                                                                                                     25m          1       r8s-cp-wlp7h-lhvgq.1890a4a2adae1a55
default                    25m         Normal    Started                          node/r8s-cp-wlp7h-lhvgq                                                                                                 system-upgrade-controller, r8s-cp-wlp7h-lhvgq                          system-upgrade-controller v0.16.3 (a8d5a37) running as cattle-system/system-upgrade-controller                                                                                                                                                                                                                                                                                       25m          1       r8s-cp-wlp7h-lhvgq.1890a4a2ca6e2bae
default                    27m         Normal    CertificateExpirationOK          node/r8s-wk-jnhwv-4xqzn                                                                                                 rke2-cert-monitor, r8s-wk-jnhwv-4xqzn                                  Node and Certificate Authority certificates managed by rke2 are OK                                                                                                                                                                                                                                                                                                                   27m          1       r8s-wk-jnhwv-4xqzn.1890a493bb4520ae
default                    26m         Normal    Starting                         node/r8s-wk-jnhwv-4xqzn                                                                                                 kubelet, r8s-wk-jnhwv-4xqzn                                            Starting kubelet.                                                                                                                                                                                                                                                                                                                                                                    26m          1       r8s-wk-jnhwv-4xqzn.1890a4947e1a64ca
default                    26m         Warning   InvalidDiskCapacity              node/r8s-wk-jnhwv-4xqzn                                                                                                 kubelet, r8s-wk-jnhwv-4xqzn                                            invalid capacity 0 on image filesystem                                                                                                                                                                                                                                                                                                                                               26m          1       r8s-wk-jnhwv-4xqzn.1890a4947e8dafd0
default                    26m         Normal    NodeHasSufficientMemory          node/r8s-wk-jnhwv-4xqzn                                                                                                 kubelet, r8s-wk-jnhwv-4xqzn                                            Node r8s-wk-jnhwv-4xqzn status is now: NodeHasSufficientMemory                                                                                                                                                                                                                                                                                                                       26m          4       r8s-wk-jnhwv-4xqzn.1890a4947fa0024d
default                    26m         Normal    NodeHasNoDiskPressure            node/r8s-wk-jnhwv-4xqzn                                                                                                 kubelet, r8s-wk-jnhwv-4xqzn                                            Node r8s-wk-jnhwv-4xqzn status is now: NodeHasNoDiskPressure                                                                                                                                                                                                                                                                                                                         26m          4       r8s-wk-jnhwv-4xqzn.1890a4947fa02e19
default                    26m         Normal    NodeHasSufficientPID             node/r8s-wk-jnhwv-4xqzn                                                                                                 kubelet, r8s-wk-jnhwv-4xqzn                                            Node r8s-wk-jnhwv-4xqzn status is now: NodeHasSufficientPID                                                                                                                                                                                                                                                                                                                          26m          4       r8s-wk-jnhwv-4xqzn.1890a4947fa046ef
default                    26m         Normal    NodeAllocatableEnforced          node/r8s-wk-jnhwv-4xqzn                                                                                                 kubelet, r8s-wk-jnhwv-4xqzn                                            Updated Node Allocatable limit across pods                                                                                                                                                                                                                                                                                                                                           26m          1       r8s-wk-jnhwv-4xqzn.1890a494820996d2
default                    26m         Normal    Synced                           node/r8s-wk-jnhwv-4xqzn                                                                                                 cloud-node-controller                                                  Node synced successfully                                                                                                                                                                                                                                                                                                                                                             26m          1       r8s-wk-jnhwv-4xqzn.1890a4949817acb6
default                    26m         Normal    CIDRAssignmentFailed             node/r8s-wk-jnhwv-4xqzn                                                                                                 cidrAllocator                                                          Node r8s-wk-jnhwv-4xqzn status is now: CIDRAssignmentFailed                                                                                                                                                                                                                                                                                                                          26m          1       r8s-wk-jnhwv-4xqzn.1890a494989d479d
default                    26m         Normal    RegisteredNode                   node/r8s-wk-jnhwv-4xqzn                                                                                                 node-controller                                                        Node r8s-wk-jnhwv-4xqzn event: Registered Node r8s-wk-jnhwv-4xqzn in Controller                                                                                                                                                                                                                                                                                                      26m          1       r8s-wk-jnhwv-4xqzn.1890a4957d5fda70
default                    26m         Normal    Starting                         node/r8s-wk-jnhwv-4xqzn                                                                                                 kube-proxy, kube-proxy-r8s-wk-jnhwv-4xqzn                                                                                                                                                                                                                                                                                                                                                                                                                   26m          1       r8s-wk-jnhwv-4xqzn.1890a495bfc2543c
default                    26m         Normal    NodeReady                        node/r8s-wk-jnhwv-4xqzn                                                                                                 kubelet, r8s-wk-jnhwv-4xqzn                                            Node r8s-wk-jnhwv-4xqzn status is now: NodeReady                                                                                                                                                                                                                                                                                                                                     26m          1       r8s-wk-jnhwv-4xqzn.1890a49c7c87a784
default                    27m         Normal    CertificateExpirationOK          node/r8s-wk-jnhwv-j5k8h                                                                                                 rke2-cert-monitor, r8s-wk-jnhwv-j5k8h                                  Node and Certificate Authority certificates managed by rke2 are OK                                                                                                                                                                                                                                                                                                                   27m          1       r8s-wk-jnhwv-j5k8h.1890a493985c43f1
default                    26m         Normal    Starting                         node/r8s-wk-jnhwv-j5k8h                                                                                                 kubelet, r8s-wk-jnhwv-j5k8h                                            Starting kubelet.                                                                                                                                                                                                                                                                                                                                                                    26m          1       r8s-wk-jnhwv-j5k8h.1890a4943ed6f0c8
default                    26m         Warning   InvalidDiskCapacity              node/r8s-wk-jnhwv-j5k8h                                                                                                 kubelet, r8s-wk-jnhwv-j5k8h                                            invalid capacity 0 on image filesystem                                                                                                                                                                                                                                                                                                                                               26m          1       r8s-wk-jnhwv-j5k8h.1890a4943f3a170d
default                    26m         Normal    NodeHasSufficientMemory          node/r8s-wk-jnhwv-j5k8h                                                                                                 kubelet, r8s-wk-jnhwv-j5k8h                                            Node r8s-wk-jnhwv-j5k8h status is now: NodeHasSufficientMemory                                                                                                                                                                                                                                                                                                                       26m          4       r8s-wk-jnhwv-j5k8h.1890a4944065a7eb
default                    26m         Normal    NodeHasNoDiskPressure            node/r8s-wk-jnhwv-j5k8h                                                                                                 kubelet, r8s-wk-jnhwv-j5k8h                                            Node r8s-wk-jnhwv-j5k8h status is now: NodeHasNoDiskPressure                                                                                                                                                                                                                                                                                                                         26m          4       r8s-wk-jnhwv-j5k8h.1890a4944065fccd
default                    26m         Normal    NodeHasSufficientPID             node/r8s-wk-jnhwv-j5k8h                                                                                                 kubelet, r8s-wk-jnhwv-j5k8h                                            Node r8s-wk-jnhwv-j5k8h status is now: NodeHasSufficientPID                                                                                                                                                                                                                                                                                                                          26m          4       r8s-wk-jnhwv-j5k8h.1890a49440665cbe
default                    26m         Normal    NodeAllocatableEnforced          node/r8s-wk-jnhwv-j5k8h                                                                                                 kubelet, r8s-wk-jnhwv-j5k8h                                            Updated Node Allocatable limit across pods                                                                                                                                                                                                                                                                                                                                           26m          1       r8s-wk-jnhwv-j5k8h.1890a494431cd7d9
default                    26m         Normal    RegisteredNode                   node/r8s-wk-jnhwv-j5k8h                                                                                                 node-controller                                                        Node r8s-wk-jnhwv-j5k8h event: Registered Node r8s-wk-jnhwv-j5k8h in Controller                                                                                                                                                                                                                                                                                                      26m          1       r8s-wk-jnhwv-j5k8h.1890a49452f52458
default                    26m         Normal    CIDRAssignmentFailed             node/r8s-wk-jnhwv-j5k8h                                                                                                 cidrAllocator                                                          Node r8s-wk-jnhwv-j5k8h status is now: CIDRAssignmentFailed                                                                                                                                                                                                                                                                                                                          26m          1       r8s-wk-jnhwv-j5k8h.1890a49460dca0b0
default                    26m         Normal    Synced                           node/r8s-wk-jnhwv-j5k8h                                                                                                 cloud-node-controller                                                  Node synced successfully                                                                                                                                                                                                                                                                                                                                                             26m          1       r8s-wk-jnhwv-j5k8h.1890a4946dc1cedb
default                    26m         Normal    Starting                         node/r8s-wk-jnhwv-j5k8h                                                                                                 kube-proxy, kube-proxy-r8s-wk-jnhwv-j5k8h                                                                                                                                                                                                                                                                                                                                                                                                                   26m          1       r8s-wk-jnhwv-j5k8h.1890a495807b021b
default                    26m         Normal    NodeReady                        node/r8s-wk-jnhwv-j5k8h                                                                                                 kubelet, r8s-wk-jnhwv-j5k8h                                            Node r8s-wk-jnhwv-j5k8h status is now: NodeReady                                                                                                                                                                                                                                                                                                                                     26m          1       r8s-wk-jnhwv-j5k8h.1890a49c2adbf4ea
default                    27m         Normal    CertificateExpirationOK          node/r8s-wk-jnhwv-vpdq4                                                                                                 rke2-cert-monitor, r8s-wk-jnhwv-vpdq4                                  Node and Certificate Authority certificates managed by rke2 are OK                                                                                                                                                                                                                                                                                                                   27m          1       r8s-wk-jnhwv-vpdq4.1890a493ad80a542
default                    26m         Normal    Starting                         node/r8s-wk-jnhwv-vpdq4                                                                                                 kubelet, r8s-wk-jnhwv-vpdq4                                            Starting kubelet.                                                                                                                                                                                                                                                                                                                                                                    26m          1       r8s-wk-jnhwv-vpdq4.1890a494e751ab33
default                    26m         Warning   InvalidDiskCapacity              node/r8s-wk-jnhwv-vpdq4                                                                                                 kubelet, r8s-wk-jnhwv-vpdq4                                            invalid capacity 0 on image filesystem                                                                                                                                                                                                                                                                                                                                               26m          1       r8s-wk-jnhwv-vpdq4.1890a494e8095652
default                    26m         Normal    NodeHasSufficientMemory          node/r8s-wk-jnhwv-vpdq4                                                                                                 kubelet, r8s-wk-jnhwv-vpdq4                                            Node r8s-wk-jnhwv-vpdq4 status is now: NodeHasSufficientMemory                                                                                                                                                                                                                                                                                                                       26m          4       r8s-wk-jnhwv-vpdq4.1890a494e932fcc5
default                    26m         Normal    NodeHasNoDiskPressure            node/r8s-wk-jnhwv-vpdq4                                                                                                 kubelet, r8s-wk-jnhwv-vpdq4                                            Node r8s-wk-jnhwv-vpdq4 status is now: NodeHasNoDiskPressure                                                                                                                                                                                                                                                                                                                         26m          4       r8s-wk-jnhwv-vpdq4.1890a494e9334aa4
default                    26m         Normal    NodeHasSufficientPID             node/r8s-wk-jnhwv-vpdq4                                                                                                 kubelet, r8s-wk-jnhwv-vpdq4                                            Node r8s-wk-jnhwv-vpdq4 status is now: NodeHasSufficientPID                                                                                                                                                                                                                                                                                                                          26m          4       r8s-wk-jnhwv-vpdq4.1890a494e9336145
default                    26m         Normal    NodeAllocatableEnforced          node/r8s-wk-jnhwv-vpdq4                                                                                                 kubelet, r8s-wk-jnhwv-vpdq4                                            Updated Node Allocatable limit across pods                                                                                                                                                                                                                                                                                                                                           26m          1       r8s-wk-jnhwv-vpdq4.1890a494ec9cc8a7
default                    26m         Normal    Synced                           node/r8s-wk-jnhwv-vpdq4                                                                                                 cloud-node-controller                                                  Node synced successfully                                                                                                                                                                                                                                                                                                                                                             26m          2       r8s-wk-jnhwv-vpdq4.1890a495020b3ffd
default                    26m         Normal    RegisteredNode                   node/r8s-wk-jnhwv-vpdq4                                                                                                 node-controller                                                        Node r8s-wk-jnhwv-vpdq4 event: Registered Node r8s-wk-jnhwv-vpdq4 in Controller                                                                                                                                                                                                                                                                                                      26m          1       r8s-wk-jnhwv-vpdq4.1890a4957d60657c
default                    26m         Normal    Starting                         node/r8s-wk-jnhwv-vpdq4                                                                                                 kube-proxy, kube-proxy-r8s-wk-jnhwv-vpdq4                                                                                                                                                                                                                                                                                                                                                                                                                   26m          1       r8s-wk-jnhwv-vpdq4.1890a4963117d993
default                    26m         Normal    NodeReady                        node/r8s-wk-jnhwv-vpdq4                                                                                                 kubelet, r8s-wk-jnhwv-vpdq4                                            Node r8s-wk-jnhwv-vpdq4 status is now: NodeReady                                                                                                                                                                                                                                                                                                                                     26m          1       r8s-wk-jnhwv-vpdq4.1890a49caab1ce67
kube-system                30m         Normal    ApplyingManifest                 addon/addons                                                                                                            deploy, r8s-cp-wlp7h-lhvgq                                             Applying manifest at "/var/lib/rancher/rke2/server/manifests/rancher/addons.yaml"                                                                                                                                                                                                                                                                                                    30m          1       addons.1890a45e59658f56
kube-system                30m         Normal    AppliedManifest                  addon/addons                                                                                                            deploy, r8s-cp-wlp7h-lhvgq                                             Applied manifest at "/var/lib/rancher/rke2/server/manifests/rancher/addons.yaml"                                                                                                                                                                                                                                                                                                     30m          1       addons.1890a45e596623a6
kube-system                17s         Warning   DNSConfigForming                 pod/cloud-controller-manager-r8s-cp-wlp7h-lhvgq                                                                         kubelet, r8s-cp-wlp7h-lhvgq                                            Nameserver limits were exceeded, some nameservers have been omitted, the applied nameserver line is: 67.207.67.3 67.207.67.2 67.207.67.3                                                                                                                                                                                                                                             30m          53      cloud-controller-manager-r8s-cp-wlp7h-lhvgq.1890a45dcd7794db
kube-system                30m         Normal    Pulled                           pod/cloud-controller-manager-r8s-cp-wlp7h-lhvgq                       spec.containers{cloud-controller-manager}         kubelet, r8s-cp-wlp7h-lhvgq                                            Container image "index.docker.io/rancher/rke2-cloud-provider:v1.33.7-0.20251210094413-291666bcc1a4-build20251210" already present on machine                                                                                                                                                                                                                                         30m          1       cloud-controller-manager-r8s-cp-wlp7h-lhvgq.1890a45ddaae9ef4
kube-system                30m         Normal    Created                          pod/cloud-controller-manager-r8s-cp-wlp7h-lhvgq                       spec.containers{cloud-controller-manager}         kubelet, r8s-cp-wlp7h-lhvgq                                            Created container: cloud-controller-manager                                                                                                                                                                                                                                                                                                                                          30m          1       cloud-controller-manager-r8s-cp-wlp7h-lhvgq.1890a45ddc8e55b7
kube-system                30m         Normal    Started                          pod/cloud-controller-manager-r8s-cp-wlp7h-lhvgq                       spec.containers{cloud-controller-manager}         kubelet, r8s-cp-wlp7h-lhvgq                                            Started container cloud-controller-manager                                                                                                                                                                                                                                                                                                                                           30m          1       cloud-controller-manager-r8s-cp-wlp7h-lhvgq.1890a45de3ffaf3d
kube-system                27m         Normal    ApplyingManifest                 addon/cluster-agent                                                                                                     deploy, r8s-cp-wlp7h-lhvgq                                             Applying manifest at "/var/lib/rancher/rke2/server/manifests/rancher/cluster-agent.yaml"                                                                                                                                                                                                                                                                                             30m          2       cluster-agent.1890a45e5a3e6ffe
kube-system                27m         Normal    AppliedManifest                  addon/cluster-agent                                                                                                     deploy, r8s-cp-wlp7h-lhvgq                                             Applied manifest at "/var/lib/rancher/rke2/server/manifests/rancher/cluster-agent.yaml"                                                                                                                                                                                                                                                                                              30m          2       cluster-agent.1890a45e6144c788
kube-system                45s         Warning   DNSConfigForming                 pod/etcd-r8s-cp-wlp7h-lhvgq                                                                                             kubelet, r8s-cp-wlp7h-lhvgq                                            Nameserver limits were exceeded, some nameservers have been omitted, the applied nameserver line is: 67.207.67.3 67.207.67.2 67.207.67.3                                                                                                                                                                                                                                             31m          52      etcd-r8s-cp-wlp7h-lhvgq.1890a45545e4078c
kube-system                31m         Normal    Pulled                           pod/etcd-r8s-cp-wlp7h-lhvgq                                           spec.containers{etcd}                             kubelet, r8s-cp-wlp7h-lhvgq                                            Container image "index.docker.io/rancher/hardened-etcd:v3.5.25-k3s1-build20251210" already present on machine                                                                                                                                                                                                                                                                        31m          1       etcd-r8s-cp-wlp7h-lhvgq.1890a456648cd381
kube-system                31m         Normal    Created                          pod/etcd-r8s-cp-wlp7h-lhvgq                                           spec.containers{etcd}                             kubelet, r8s-cp-wlp7h-lhvgq                                            Created container: etcd                                                                                                                                                                                                                                                                                                                                                              31m          1       etcd-r8s-cp-wlp7h-lhvgq.1890a45668ffd09c
kube-system                31m         Normal    Started                          pod/etcd-r8s-cp-wlp7h-lhvgq                                           spec.containers{etcd}                             kubelet, r8s-cp-wlp7h-lhvgq                                            Started container etcd                                                                                                                                                                                                                                                                                                                                                               31m          1       etcd-r8s-cp-wlp7h-lhvgq.1890a456723313b1
kube-system                30m         Normal    DeletingManifest                 addon/harvester-cloud-provider                                                                                          deploy, r8s-cp-wlp7h-lhvgq                                             Deleting manifest at "/var/lib/rancher/rke2/server/manifests/harvester-cloud-provider.yaml"                                                                                                                                                                                                                                                                                          30m          1       harvester-cloud-provider.1890a45e46fa2628
kube-system                30m         Normal    DeletingManifest                 addon/harvester-csi-driver                                                                                              deploy, r8s-cp-wlp7h-lhvgq                                             Deleting manifest at "/var/lib/rancher/rke2/server/manifests/harvester-csi-driver.yaml"                                                                                                                                                                                                                                                                                              30m          1       harvester-csi-driver.1890a45e4cef5185
kube-system                30m         Normal    Scheduled                        pod/helm-install-rke2-calico-crd-tf6wn                                                                                  default-scheduler, default-scheduler-r8s-cp-wlp7h-lhvgq                Successfully assigned kube-system/helm-install-rke2-calico-crd-tf6wn to r8s-cp-wlp7h-lhvgq                                                                                                                                                                                                                                                                                           30m          1       helm-install-rke2-calico-crd-tf6wn.1890a45efb9346bf
kube-system                30m         Warning   DNSConfigForming                 pod/helm-install-rke2-calico-crd-tf6wn                                                                                  kubelet, r8s-cp-wlp7h-lhvgq                                            Nameserver limits were exceeded, some nameservers have been omitted, the applied nameserver line is: 67.207.67.3 67.207.67.2 67.207.67.3                                                                                                                                                                                                                                             30m          4       helm-install-rke2-calico-crd-tf6wn.1890a45f0e35e8da
kube-system                30m         Normal    Pulling                          pod/helm-install-rke2-calico-crd-tf6wn                                spec.containers{helm}                             kubelet, r8s-cp-wlp7h-lhvgq                                            Pulling image "rancher/klipper-helm:v0.9.12-build20251215"                                                                                                                                                                                                                                                                                                                           30m          1       helm-install-rke2-calico-crd-tf6wn.1890a45f1d5fe2ed
kube-system                30m         Normal    Pulled                           pod/helm-install-rke2-calico-crd-tf6wn                                spec.containers{helm}                             kubelet, r8s-cp-wlp7h-lhvgq                                            Successfully pulled image "rancher/klipper-helm:v0.9.12-build20251215" in 9.415s (9.415s including waiting). Image size: 65538854 bytes.                                                                                                                                                                                                                                             30m          1       helm-install-rke2-calico-crd-tf6wn.1890a4614e90ea3f
kube-system                30m         Normal    Created                          pod/helm-install-rke2-calico-crd-tf6wn                                spec.containers{helm}                             kubelet, r8s-cp-wlp7h-lhvgq                                            Created container: helm                                                                                                                                                                                                                                                                                                                                                              30m          1       helm-install-rke2-calico-crd-tf6wn.1890a46154115547
kube-system                30m         Normal    Started                          pod/helm-install-rke2-calico-crd-tf6wn                                spec.containers{helm}                             kubelet, r8s-cp-wlp7h-lhvgq                                            Started container helm                                                                                                                                                                                                                                                                                                                                                               30m          1       helm-install-rke2-calico-crd-tf6wn.1890a461626c9a89
kube-system                30m         Normal    SuccessfulCreate                 job/helm-install-rke2-calico-crd                                                                                        job-controller                                                         Created pod: helm-install-rke2-calico-crd-tf6wn                                                                                                                                                                                                                                                                                                                                      30m          1       helm-install-rke2-calico-crd.1890a45ef9f0bd26
kube-system                30m         Normal    Completed                        job/helm-install-rke2-calico-crd                                                                                        job-controller                                                         Job completed                                                                                                                                                                                                                                                                                                                                                                        30m          1       helm-install-rke2-calico-crd.1890a46374f05873
kube-system                30m         Normal    Scheduled                        pod/helm-install-rke2-calico-qmqv9                                                                                      default-scheduler, default-scheduler-r8s-cp-wlp7h-lhvgq                Successfully assigned kube-system/helm-install-rke2-calico-qmqv9 to r8s-cp-wlp7h-lhvgq                                                                                                                                                                                                                                                                                               30m          1       helm-install-rke2-calico-qmqv9.1890a45f03704f3a
kube-system                30m         Warning   FailedMount                      pod/helm-install-rke2-calico-qmqv9                                                                                      kubelet, r8s-cp-wlp7h-lhvgq                                            MountVolume.SetUp failed for volume "values" : failed to sync secret cache: timed out waiting for the condition                                                                                                                                                                                                                                                                      30m          1       helm-install-rke2-calico-qmqv9.1890a45f4eb51bfa
kube-system                30m         Warning   FailedMount                      pod/helm-install-rke2-calico-qmqv9                                                                                      kubelet, r8s-cp-wlp7h-lhvgq                                            MountVolume.SetUp failed for volume "content" : failed to sync configmap cache: timed out waiting for the condition                                                                                                                                                                                                                                                                  30m          1       helm-install-rke2-calico-qmqv9.1890a45f4fa3d7e9
kube-system                30m         Warning   DNSConfigForming                 pod/helm-install-rke2-calico-qmqv9                                                                                      kubelet, r8s-cp-wlp7h-lhvgq                                            Nameserver limits were exceeded, some nameservers have been omitted, the applied nameserver line is: 67.207.67.3 67.207.67.2 67.207.67.3                                                                                                                                                                                                                                             30m          7       helm-install-rke2-calico-qmqv9.1890a45f6e7e5535
kube-system                30m         Normal    Pulling                          pod/helm-install-rke2-calico-qmqv9                                    spec.containers{helm}                             kubelet, r8s-cp-wlp7h-lhvgq                                            Pulling image "rancher/klipper-helm:v0.9.12-build20251215"                                                                                                                                                                                                                                                                                                                           30m          1       helm-install-rke2-calico-qmqv9.1890a45f7893119a
kube-system                30m         Normal    Pulled                           pod/helm-install-rke2-calico-qmqv9                                    spec.containers{helm}                             kubelet, r8s-cp-wlp7h-lhvgq                                            Successfully pulled image "rancher/klipper-helm:v0.9.12-build20251215" in 7.88s (7.88s including waiting). Image size: 65538854 bytes.                                                                                                                                                                                                                                               30m          1       helm-install-rke2-calico-qmqv9.1890a4614e504fb6
kube-system                30m         Normal    Created                          pod/helm-install-rke2-calico-qmqv9                                    spec.containers{helm}                             kubelet, r8s-cp-wlp7h-lhvgq                                            Created container: helm                                                                                                                                                                                                                                                                                                                                                              30m          3       helm-install-rke2-calico-qmqv9.1890a46155039236
kube-system                30m         Normal    Started                          pod/helm-install-rke2-calico-qmqv9                                    spec.containers{helm}                             kubelet, r8s-cp-wlp7h-lhvgq                                            Started container helm                                                                                                                                                                                                                                                                                                                                                               30m          3       helm-install-rke2-calico-qmqv9.1890a461664d1a2d
kube-system                30m         Normal    Pulled                           pod/helm-install-rke2-calico-qmqv9                                    spec.containers{helm}                             kubelet, r8s-cp-wlp7h-lhvgq                                            Container image "rancher/klipper-helm:v0.9.12-build20251215" already present on machine                                                                                                                                                                                                                                                                                              30m          2       helm-install-rke2-calico-qmqv9.1890a461917b0e91
kube-system                30m         Warning   BackOff                          pod/helm-install-rke2-calico-qmqv9                                    spec.containers{helm}                             kubelet, r8s-cp-wlp7h-lhvgq                                            Back-off restarting failed container helm in pod helm-install-rke2-calico-qmqv9_kube-system(574f2766-3a51-415a-8458-48c50b938e8d)                                                                                                                                                                                                                                                    30m          2       helm-install-rke2-calico-qmqv9.1890a461cda6a7fd
kube-system                30m         Normal    SuccessfulCreate                 job/helm-install-rke2-calico                                                                                            job-controller                                                         Created pod: helm-install-rke2-calico-qmqv9                                                                                                                                                                                                                                                                                                                                          30m          1       helm-install-rke2-calico.1890a45efaaa934f
kube-system                30m         Normal    Completed                        job/helm-install-rke2-calico                                                                                            job-controller                                                         Job completed                                                                                                                                                                                                                                                                                                                                                                        30m          1       helm-install-rke2-calico.1890a4660d25d47a
kube-system                30m         Normal    Scheduled                        pod/helm-install-rke2-coredns-l7hdg                                                                                     default-scheduler, default-scheduler-r8s-cp-wlp7h-lhvgq                Successfully assigned kube-system/helm-install-rke2-coredns-l7hdg to r8s-cp-wlp7h-lhvgq                                                                                                                                                                                                                                                                                              30m          1       helm-install-rke2-coredns-l7hdg.1890a45f0439a565
kube-system                30m         Warning   DNSConfigForming                 pod/helm-install-rke2-coredns-l7hdg                                                                                     kubelet, r8s-cp-wlp7h-lhvgq                                            Nameserver limits were exceeded, some nameservers have been omitted, the applied nameserver line is: 67.207.67.3 67.207.67.2 67.207.67.3                                                                                                                                                                                                                                             30m          3       helm-install-rke2-coredns-l7hdg.1890a45f29a9032f
kube-system                30m         Normal    Pulling                          pod/helm-install-rke2-coredns-l7hdg                                   spec.containers{helm}                             kubelet, r8s-cp-wlp7h-lhvgq                                            Pulling image "rancher/klipper-helm:v0.9.12-build20251215"                                                                                                                                                                                                                                                                                                                           30m          1       helm-install-rke2-coredns-l7hdg.1890a45f32e56d14
kube-system                30m         Normal    Pulled                           pod/helm-install-rke2-coredns-l7hdg                                   spec.containers{helm}                             kubelet, r8s-cp-wlp7h-lhvgq                                            Successfully pulled image "rancher/klipper-helm:v0.9.12-build20251215" in 9.051s (9.051s including waiting). Image size: 65538854 bytes.                                                                                                                                                                                                                                             30m          1       helm-install-rke2-coredns-l7hdg.1890a4614e620eb5
kube-system                30m         Normal    Created                          pod/helm-install-rke2-coredns-l7hdg                                   spec.containers{helm}                             kubelet, r8s-cp-wlp7h-lhvgq                                            Created container: helm                                                                                                                                                                                                                                                                                                                                                              30m          1       helm-install-rke2-coredns-l7hdg.1890a461513450a9
kube-system                30m         Normal    Started                          pod/helm-install-rke2-coredns-l7hdg                                   spec.containers{helm}                             kubelet, r8s-cp-wlp7h-lhvgq                                            Started container helm                                                                                                                                                                                                                                                                                                                                                               30m          1       helm-install-rke2-coredns-l7hdg.1890a4615f23c34a
kube-system                30m         Normal    SuccessfulCreate                 job/helm-install-rke2-coredns                                                                                           job-controller                                                         Created pod: helm-install-rke2-coredns-l7hdg                                                                                                                                                                                                                                                                                                                                         30m          1       helm-install-rke2-coredns.1890a45efaba59b7
kube-system                30m         Normal    Completed                        job/helm-install-rke2-coredns                                                                                           job-controller                                                         Job completed                                                                                                                                                                                                                                                                                                                                                                        30m          1       helm-install-rke2-coredns.1890a4624d994832
kube-system                30m         Warning   FailedScheduling                 pod/helm-install-rke2-ingress-nginx-qbl5k                                                                               default-scheduler, default-scheduler-r8s-cp-wlp7h-lhvgq                0/1 nodes are available: 1 node(s) had untolerated taint {node-role.kubernetes.io/control-plane: }. preemption: 0/1 nodes are available: 1 Preemption is not helpful for scheduling.                                                                                                                                                                                                 30m          1       helm-install-rke2-ingress-nginx-qbl5k.1890a45efa22b6dd
kube-system                26m         Normal    Scheduled                        pod/helm-install-rke2-ingress-nginx-qbl5k                                                                               default-scheduler, default-scheduler-r8s-cp-wlp7h-lhvgq                Successfully assigned kube-system/helm-install-rke2-ingress-nginx-qbl5k to r8s-wk-jnhwv-j5k8h                                                                                                                                                                                                                                                                                        26m          1       helm-install-rke2-ingress-nginx-qbl5k.1890a49c2f1fd361
kube-system                26m         Warning   FailedCreatePodSandBox           pod/helm-install-rke2-ingress-nginx-qbl5k                                                                               kubelet, r8s-wk-jnhwv-j5k8h                                            Failed to create pod sandbox: rpc error: code = Unknown desc = failed to setup network for sandbox "13cbdb52f950fea88b2629634e4b8d6a9d6f0cf3fc991c6da445577a244286cd": plugin type="calico" failed (add): stat /var/lib/calico/nodename: no such file or directory: check that the calico/node container is running and has mounted /var/lib/calico/                                 26m          1       helm-install-rke2-ingress-nginx-qbl5k.1890a49c56fbe6da
kube-system                26m         Normal    TaintManagerEviction             pod/helm-install-rke2-ingress-nginx-qbl5k                                                                               taint-eviction-controller                                              Cancelling deletion of Pod kube-system/helm-install-rke2-ingress-nginx-qbl5k                                                                                                                                                                                                                                                                                                         26m          1       helm-install-rke2-ingress-nginx-qbl5k.1890a49c7b41ac21
kube-system                26m         Normal    Pulling                          pod/helm-install-rke2-ingress-nginx-qbl5k                             spec.containers{helm}                             kubelet, r8s-wk-jnhwv-j5k8h                                            Pulling image "rancher/klipper-helm:v0.9.12-build20251215"                                                                                                                                                                                                                                                                                                                           26m          1       helm-install-rke2-ingress-nginx-qbl5k.1890a49fbf7b238f
kube-system                26m         Normal    Pulled                           pod/helm-install-rke2-ingress-nginx-qbl5k                             spec.containers{helm}                             kubelet, r8s-wk-jnhwv-j5k8h                                            Successfully pulled image "rancher/klipper-helm:v0.9.12-build20251215" in 5.021s (5.021s including waiting). Image size: 65538854 bytes.                                                                                                                                                                                                                                             26m          1       helm-install-rke2-ingress-nginx-qbl5k.1890a4a0eaccf10d
kube-system                26m         Normal    Created                          pod/helm-install-rke2-ingress-nginx-qbl5k                             spec.containers{helm}                             kubelet, r8s-wk-jnhwv-j5k8h                                            Created container: helm                                                                                                                                                                                                                                                                                                                                                              26m          1       helm-install-rke2-ingress-nginx-qbl5k.1890a4a0ee95c7ea
kube-system                26m         Normal    Started                          pod/helm-install-rke2-ingress-nginx-qbl5k                             spec.containers{helm}                             kubelet, r8s-wk-jnhwv-j5k8h                                            Started container helm                                                                                                                                                                                                                                                                                                                                                               26m          1       helm-install-rke2-ingress-nginx-qbl5k.1890a4a0fb6fcf0b
kube-system                30m         Normal    SuccessfulCreate                 job/helm-install-rke2-ingress-nginx                                                                                     job-controller                                                         Created pod: helm-install-rke2-ingress-nginx-qbl5k                                                                                                                                                                                                                                                                                                                                   30m          1       helm-install-rke2-ingress-nginx.1890a45efab1a3c0
kube-system                25m         Normal    Completed                        job/helm-install-rke2-ingress-nginx                                                                                     job-controller                                                         Job completed                                                                                                                                                                                                                                                                                                                                                                        25m          1       helm-install-rke2-ingress-nginx.1890a4a5d14136df
kube-system                30m         Warning   FailedScheduling                 pod/helm-install-rke2-metrics-server-wspf2                                                                              default-scheduler, default-scheduler-r8s-cp-wlp7h-lhvgq                0/1 nodes are available: 1 node(s) had untolerated taint {node-role.kubernetes.io/control-plane: }. preemption: 0/1 nodes are available: 1 Preemption is not helpful for scheduling.                                                                                                                                                                                                 30m          1       helm-install-rke2-metrics-server-wspf2.1890a45eff8514a9
kube-system                26m         Normal    Scheduled                        pod/helm-install-rke2-metrics-server-wspf2                                                                              default-scheduler, default-scheduler-r8s-cp-wlp7h-lhvgq                Successfully assigned kube-system/helm-install-rke2-metrics-server-wspf2 to r8s-wk-jnhwv-j5k8h                                                                                                                                                                                                                                                                                       26m          1       helm-install-rke2-metrics-server-wspf2.1890a49c2eff9b5f
kube-system                26m         Warning   FailedCreatePodSandBox           pod/helm-install-rke2-metrics-server-wspf2                                                                              kubelet, r8s-wk-jnhwv-j5k8h                                            Failed to create pod sandbox: rpc error: code = Unknown desc = failed to setup network for sandbox "0b8eb3f2c2cd2b3a4bab73e528fac7dc2d8a8ac39ef04f1e93586c311cf3a05c": plugin type="calico" failed (add): stat /var/lib/calico/nodename: no such file or directory: check that the calico/node container is running and has mounted /var/lib/calico/                                 26m          1       helm-install-rke2-metrics-server-wspf2.1890a49c53f9f2c1
kube-system                26m         Normal    TaintManagerEviction             pod/helm-install-rke2-metrics-server-wspf2                                                                              taint-eviction-controller                                              Cancelling deletion of Pod kube-system/helm-install-rke2-metrics-server-wspf2                                                                                                                                                                                                                                                                                                        26m          1       helm-install-rke2-metrics-server-wspf2.1890a49c7b41c116
kube-system                26m         Normal    Pulling                          pod/helm-install-rke2-metrics-server-wspf2                            spec.containers{helm}                             kubelet, r8s-wk-jnhwv-j5k8h                                            Pulling image "rancher/klipper-helm:v0.9.12-build20251215"                                                                                                                                                                                                                                                                                                                           26m          1       helm-install-rke2-metrics-server-wspf2.1890a49f140e4926
kube-system                26m         Normal    Pulled                           pod/helm-install-rke2-metrics-server-wspf2                            spec.containers{helm}                             kubelet, r8s-wk-jnhwv-j5k8h                                            Successfully pulled image "rancher/klipper-helm:v0.9.12-build20251215" in 7.89s (7.89s including waiting). Image size: 65538854 bytes.                                                                                                                                                                                                                                               26m          1       helm-install-rke2-metrics-server-wspf2.1890a4a0ea5f613e
kube-system                26m         Normal    Created                          pod/helm-install-rke2-metrics-server-wspf2                            spec.containers{helm}                             kubelet, r8s-wk-jnhwv-j5k8h                                            Created container: helm                                                                                                                                                                                                                                                                                                                                                              26m          1       helm-install-rke2-metrics-server-wspf2.1890a4a0ed26ca0f
kube-system                26m         Normal    Started                          pod/helm-install-rke2-metrics-server-wspf2                            spec.containers{helm}                             kubelet, r8s-wk-jnhwv-j5k8h                                            Started container helm                                                                                                                                                                                                                                                                                                                                                               26m          1       helm-install-rke2-metrics-server-wspf2.1890a4a0f7370863
kube-system                30m         Normal    SuccessfulCreate                 job/helm-install-rke2-metrics-server                                                                                    job-controller                                                         Created pod: helm-install-rke2-metrics-server-wspf2                                                                                                                                                                                                                                                                                                                                  30m          1       helm-install-rke2-metrics-server.1890a45efab66bcb
kube-system                26m         Normal    Completed                        job/helm-install-rke2-metrics-server                                                                                    job-controller                                                         Job completed                                                                                                                                                                                                                                                                                                                                                                        26m          1       helm-install-rke2-metrics-server.1890a4a1ead6bff6
kube-system                30m         Warning   FailedScheduling                 pod/helm-install-rke2-runtimeclasses-g6xm8                                                                              default-scheduler, default-scheduler-r8s-cp-wlp7h-lhvgq                0/1 nodes are available: 1 node(s) had untolerated taint {node-role.kubernetes.io/control-plane: }. preemption: 0/1 nodes are available: 1 Preemption is not helpful for scheduling.                                                                                                                                                                                                 30m          1       helm-install-rke2-runtimeclasses-g6xm8.1890a45f0847b5a2
kube-system                26m         Normal    Scheduled                        pod/helm-install-rke2-runtimeclasses-g6xm8                                                                              default-scheduler, default-scheduler-r8s-cp-wlp7h-lhvgq                Successfully assigned kube-system/helm-install-rke2-runtimeclasses-g6xm8 to r8s-wk-jnhwv-j5k8h                                                                                                                                                                                                                                                                                       26m          1       helm-install-rke2-runtimeclasses-g6xm8.1890a49c2f6fb94e
kube-system                26m         Warning   FailedCreatePodSandBox           pod/helm-install-rke2-runtimeclasses-g6xm8                                                                              kubelet, r8s-wk-jnhwv-j5k8h                                            Failed to create pod sandbox: rpc error: code = Unknown desc = failed to setup network for sandbox "1a87507ce220fc003754c8ff513f510d731bf530535e3588c9e03f3932043a4a": plugin type="calico" failed (add): stat /var/lib/calico/nodename: no such file or directory: check that the calico/node container is running and has mounted /var/lib/calico/                                 26m          1       helm-install-rke2-runtimeclasses-g6xm8.1890a49c55d55d29
kube-system                26m         Normal    TaintManagerEviction             pod/helm-install-rke2-runtimeclasses-g6xm8                                                                              taint-eviction-controller                                              Cancelling deletion of Pod kube-system/helm-install-rke2-runtimeclasses-g6xm8                                                                                                                                                                                                                                                                                                        26m          1       helm-install-rke2-runtimeclasses-g6xm8.1890a49c7b417b5a
kube-system                26m         Normal    Pulling                          pod/helm-install-rke2-runtimeclasses-g6xm8                            spec.containers{helm}                             kubelet, r8s-wk-jnhwv-j5k8h                                            Pulling image "rancher/klipper-helm:v0.9.12-build20251215"                                                                                                                                                                                                                                                                                                                           26m          1       helm-install-rke2-runtimeclasses-g6xm8.1890a49f82290cc8
kube-system                26m         Normal    Pulled                           pod/helm-install-rke2-runtimeclasses-g6xm8                            spec.containers{helm}                             kubelet, r8s-wk-jnhwv-j5k8h                                            Successfully pulled image "rancher/klipper-helm:v0.9.12-build20251215" in 6.05s (6.05s including waiting). Image size: 65538854 bytes.                                                                                                                                                                                                                                               26m          1       helm-install-rke2-runtimeclasses-g6xm8.1890a4a0eacddde0
kube-system                26m         Normal    Created                          pod/helm-install-rke2-runtimeclasses-g6xm8                            spec.containers{helm}                             kubelet, r8s-wk-jnhwv-j5k8h                                            Created container: helm                                                                                                                                                                                                                                                                                                                                                              26m          1       helm-install-rke2-runtimeclasses-g6xm8.1890a4a0ee971a7c
kube-system                26m         Normal    Started                          pod/helm-install-rke2-runtimeclasses-g6xm8                            spec.containers{helm}                             kubelet, r8s-wk-jnhwv-j5k8h                                            Started container helm                                                                                                                                                                                                                                                                                                                                                               26m          1       helm-install-rke2-runtimeclasses-g6xm8.1890a4a0faa31084
kube-system                30m         Normal    SuccessfulCreate                 job/helm-install-rke2-runtimeclasses                                                                                    job-controller                                                         Created pod: helm-install-rke2-runtimeclasses-g6xm8                                                                                                                                                                                                                                                                                                                                  30m          1       helm-install-rke2-runtimeclasses.1890a45f013767e4
kube-system                26m         Normal    Completed                        job/helm-install-rke2-runtimeclasses                                                                                    job-controller                                                         Job completed                                                                                                                                                                                                                                                                                                                                                                        26m          1       helm-install-rke2-runtimeclasses.1890a4a1e9778c90
kube-system                30m         Warning   FailedScheduling                 pod/helm-install-rke2-snapshot-controller-crd-4cpwx                                                                     default-scheduler, default-scheduler-r8s-cp-wlp7h-lhvgq                0/1 nodes are available: 1 node(s) had untolerated taint {node-role.kubernetes.io/control-plane: }. preemption: 0/1 nodes are available: 1 Preemption is not helpful for scheduling.                                                                                                                                                                                                 30m          1       helm-install-rke2-snapshot-controller-crd-4cpwx.1890a45f0b2c4cc8
kube-system                26m         Normal    Scheduled                        pod/helm-install-rke2-snapshot-controller-crd-4cpwx                                                                     default-scheduler, default-scheduler-r8s-cp-wlp7h-lhvgq                Successfully assigned kube-system/helm-install-rke2-snapshot-controller-crd-4cpwx to r8s-wk-jnhwv-j5k8h                                                                                                                                                                                                                                                                              26m          1       helm-install-rke2-snapshot-controller-crd-4cpwx.1890a49c2f650245
kube-system                26m         Warning   FailedCreatePodSandBox           pod/helm-install-rke2-snapshot-controller-crd-4cpwx                                                                     kubelet, r8s-wk-jnhwv-j5k8h                                            Failed to create pod sandbox: rpc error: code = Unknown desc = failed to setup network for sandbox "b8e44ace486d0c714c15433988c6a83a1cd69e5d0ec91114cc8bed48c7cf950b": plugin type="calico" failed (add): stat /var/lib/calico/nodename: no such file or directory: check that the calico/node container is running and has mounted /var/lib/calico/                                 26m          1       helm-install-rke2-snapshot-controller-crd-4cpwx.1890a49c5633ccd7
kube-system                26m         Normal    TaintManagerEviction             pod/helm-install-rke2-snapshot-controller-crd-4cpwx                                                                     taint-eviction-controller                                              Cancelling deletion of Pod kube-system/helm-install-rke2-snapshot-controller-crd-4cpwx                                                                                                                                                                                                                                                                                               26m          1       helm-install-rke2-snapshot-controller-crd-4cpwx.1890a49c7b4113ce
kube-system                26m         Normal    Pulling                          pod/helm-install-rke2-snapshot-controller-crd-4cpwx                   spec.containers{helm}                             kubelet, r8s-wk-jnhwv-j5k8h                                            Pulling image "rancher/klipper-helm:v0.9.12-build20251215"                                                                                                                                                                                                                                                                                                                           26m          1       helm-install-rke2-snapshot-controller-crd-4cpwx.1890a49f0df986c7
kube-system                26m         Normal    Pulled                           pod/helm-install-rke2-snapshot-controller-crd-4cpwx                   spec.containers{helm}                             kubelet, r8s-wk-jnhwv-j5k8h                                            Successfully pulled image "rancher/klipper-helm:v0.9.12-build20251215" in 7.991s (7.991s including waiting). Image size: 65538854 bytes.                                                                                                                                                                                                                                             26m          1       helm-install-rke2-snapshot-controller-crd-4cpwx.1890a4a0ea4adb89
kube-system                26m         Normal    Created                          pod/helm-install-rke2-snapshot-controller-crd-4cpwx                   spec.containers{helm}                             kubelet, r8s-wk-jnhwv-j5k8h                                            Created container: helm                                                                                                                                                                                                                                                                                                                                                              26m          1       helm-install-rke2-snapshot-controller-crd-4cpwx.1890a4a0ed385647
kube-system                26m         Normal    Started                          pod/helm-install-rke2-snapshot-controller-crd-4cpwx                   spec.containers{helm}                             kubelet, r8s-wk-jnhwv-j5k8h                                            Started container helm                                                                                                                                                                                                                                                                                                                                                               26m          1       helm-install-rke2-snapshot-controller-crd-4cpwx.1890a4a0f75aabe5
kube-system                30m         Normal    SuccessfulCreate                 job/helm-install-rke2-snapshot-controller-crd                                                                           job-controller                                                         Created pod: helm-install-rke2-snapshot-controller-crd-4cpwx                                                                                                                                                                                                                                                                                                                         30m          1       helm-install-rke2-snapshot-controller-crd.1890a45f01314354
kube-system                26m         Normal    Completed                        job/helm-install-rke2-snapshot-controller-crd                                                                           job-controller                                                         Job completed                                                                                                                                                                                                                                                                                                                                                                        26m          1       helm-install-rke2-snapshot-controller-crd.1890a4a1e3436818
kube-system                30m         Warning   FailedScheduling                 pod/helm-install-rke2-snapshot-controller-jw6js                                                                         default-scheduler, default-scheduler-r8s-cp-wlp7h-lhvgq                0/1 nodes are available: 1 node(s) had untolerated taint {node-role.kubernetes.io/control-plane: }. preemption: 0/1 nodes are available: 1 Preemption is not helpful for scheduling.                                                                                                                                                                                                 30m          1       helm-install-rke2-snapshot-controller-jw6js.1890a45f04417d57
kube-system                26m         Normal    Scheduled                        pod/helm-install-rke2-snapshot-controller-jw6js                                                                         default-scheduler, default-scheduler-r8s-cp-wlp7h-lhvgq                Successfully assigned kube-system/helm-install-rke2-snapshot-controller-jw6js to r8s-wk-jnhwv-j5k8h                                                                                                                                                                                                                                                                                  26m          1       helm-install-rke2-snapshot-controller-jw6js.1890a49c2f20a0a0
kube-system                26m         Warning   FailedCreatePodSandBox           pod/helm-install-rke2-snapshot-controller-jw6js                                                                         kubelet, r8s-wk-jnhwv-j5k8h                                            Failed to create pod sandbox: rpc error: code = Unknown desc = failed to setup network for sandbox "2769bcebff9f594ef383e2826b079a47681db5e4ee29cacc06215c4f924cf8fb": plugin type="calico" failed (add): stat /var/lib/calico/nodename: no such file or directory: check that the calico/node container is running and has mounted /var/lib/calico/                                 26m          1       helm-install-rke2-snapshot-controller-jw6js.1890a49c55797f2f
kube-system                26m         Normal    TaintManagerEviction             pod/helm-install-rke2-snapshot-controller-jw6js                                                                         taint-eviction-controller                                              Cancelling deletion of Pod kube-system/helm-install-rke2-snapshot-controller-jw6js                                                                                                                                                                                                                                                                                                   26m          1       helm-install-rke2-snapshot-controller-jw6js.1890a49c7b41d7e2
kube-system                26m         Normal    Pulling                          pod/helm-install-rke2-snapshot-controller-jw6js                       spec.containers{helm}                             kubelet, r8s-wk-jnhwv-j5k8h                                            Pulling image "rancher/klipper-helm:v0.9.12-build20251215"                                                                                                                                                                                                                                                                                                                           26m          1       helm-install-rke2-snapshot-controller-jw6js.1890a49ff9d6c62d
kube-system                26m         Normal    Pulled                           pod/helm-install-rke2-snapshot-controller-jw6js                       spec.containers{helm}                             kubelet, r8s-wk-jnhwv-j5k8h                                            Successfully pulled image "rancher/klipper-helm:v0.9.12-build20251215" in 4.043s (4.043s including waiting). Image size: 65538854 bytes.                                                                                                                                                                                                                                             26m          1       helm-install-rke2-snapshot-controller-jw6js.1890a4a0eadf7e43
kube-system                26m         Normal    Created                          pod/helm-install-rke2-snapshot-controller-jw6js                       spec.containers{helm}                             kubelet, r8s-wk-jnhwv-j5k8h                                            Created container: helm                                                                                                                                                                                                                                                                                                                                                              26m          2       helm-install-rke2-snapshot-controller-jw6js.1890a4a0ee23bdda
kube-system                26m         Normal    Started                          pod/helm-install-rke2-snapshot-controller-jw6js                       spec.containers{helm}                             kubelet, r8s-wk-jnhwv-j5k8h                                            Started container helm                                                                                                                                                                                                                                                                                                                                                               26m          2       helm-install-rke2-snapshot-controller-jw6js.1890a4a0fca64652
kube-system                26m         Normal    Pulled                           pod/helm-install-rke2-snapshot-controller-jw6js                       spec.containers{helm}                             kubelet, r8s-wk-jnhwv-j5k8h                                            Container image "rancher/klipper-helm:v0.9.12-build20251215" already present on machine                                                                                                                                                                                                                                                                                              26m          1       helm-install-rke2-snapshot-controller-jw6js.1890a4a159ed3c5e
kube-system                30m         Normal    SuccessfulCreate                 job/helm-install-rke2-snapshot-controller                                                                               job-controller                                                         Created pod: helm-install-rke2-snapshot-controller-jw6js                                                                                                                                                                                                                                                                                                                             30m          1       helm-install-rke2-snapshot-controller.1890a45f01b8b404
kube-system                25m         Normal    Completed                        job/helm-install-rke2-snapshot-controller                                                                               job-controller                                                         Job completed                                                                                                                                                                                                                                                                                                                                                                        25m          1       helm-install-rke2-snapshot-controller.1890a4a25bbcec30
kube-system                36s         Warning   DNSConfigForming                 pod/kube-apiserver-r8s-cp-wlp7h-lhvgq                                                                                   kubelet, r8s-cp-wlp7h-lhvgq                                            Nameserver limits were exceeded, some nameservers have been omitted, the applied nameserver line is: 67.207.67.3 67.207.67.2 67.207.67.3                                                                                                                                                                                                                                             30m          55      kube-apiserver-r8s-cp-wlp7h-lhvgq.1890a45c2c293f3b
kube-system                30m         Normal    Pulled                           pod/kube-apiserver-r8s-cp-wlp7h-lhvgq                                 spec.containers{kube-apiserver}                   kubelet, r8s-cp-wlp7h-lhvgq                                            Container image "index.docker.io/rancher/hardened-kubernetes:v1.33.7-rke2r1-build20251210" already present on machine                                                                                                                                                                                                                                                                30m          1       kube-apiserver-r8s-cp-wlp7h-lhvgq.1890a45c39ebecbd
kube-system                30m         Normal    Created                          pod/kube-apiserver-r8s-cp-wlp7h-lhvgq                                 spec.containers{kube-apiserver}                   kubelet, r8s-cp-wlp7h-lhvgq                                            Created container: kube-apiserver                                                                                                                                                                                                                                                                                                                                                    30m          1       kube-apiserver-r8s-cp-wlp7h-lhvgq.1890a45c3b5ce475
kube-system                30m         Normal    Started                          pod/kube-apiserver-r8s-cp-wlp7h-lhvgq                                 spec.containers{kube-apiserver}                   kubelet, r8s-cp-wlp7h-lhvgq                                            Started container kube-apiserver                                                                                                                                                                                                                                                                                                                                                     30m          1       kube-apiserver-r8s-cp-wlp7h-lhvgq.1890a45c42822ea2
kube-system                43s         Warning   DNSConfigForming                 pod/kube-controller-manager-r8s-cp-wlp7h-lhvgq                                                                          kubelet, r8s-cp-wlp7h-lhvgq                                            Nameserver limits were exceeded, some nameservers have been omitted, the applied nameserver line is: 67.207.67.3 67.207.67.2 67.207.67.3                                                                                                                                                                                                                                             30m          52      kube-controller-manager-r8s-cp-wlp7h-lhvgq.1890a45d58da85dc
kube-system                30m         Normal    Pulled                           pod/kube-controller-manager-r8s-cp-wlp7h-lhvgq                        spec.containers{kube-controller-manager}          kubelet, r8s-cp-wlp7h-lhvgq                                            Container image "index.docker.io/rancher/hardened-kubernetes:v1.33.7-rke2r1-build20251210" already present on machine                                                                                                                                                                                                                                                                30m          1       kube-controller-manager-r8s-cp-wlp7h-lhvgq.1890a45d706113c0
kube-system                30m         Normal    Created                          pod/kube-controller-manager-r8s-cp-wlp7h-lhvgq                        spec.containers{kube-controller-manager}          kubelet, r8s-cp-wlp7h-lhvgq                                            Created container: kube-controller-manager                                                                                                                                                                                                                                                                                                                                           30m          1       kube-controller-manager-r8s-cp-wlp7h-lhvgq.1890a45d73bc381e
kube-system                30m         Normal    Started                          pod/kube-controller-manager-r8s-cp-wlp7h-lhvgq                        spec.containers{kube-controller-manager}          kubelet, r8s-cp-wlp7h-lhvgq                                            Started container kube-controller-manager                                                                                                                                                                                                                                                                                                                                            30m          1       kube-controller-manager-r8s-cp-wlp7h-lhvgq.1890a45d7ffb569b
kube-system                30m         Normal    LeaderElection                   lease/kube-controller-manager                                                                                           kube-controller-manager                                                r8s-cp-wlp7h-lhvgq_9692bf53-5b23-448b-a4a0-33aa028f56ab became leader                                                                                                                                                                                                                                                                                                                30m          1       kube-controller-manager.1890a45db0eec1ef
kube-system                51s         Warning   DNSConfigForming                 pod/kube-proxy-r8s-cp-wlp7h-lhvgq                                                                                       kubelet, r8s-cp-wlp7h-lhvgq                                            Nameserver limits were exceeded, some nameservers have been omitted, the applied nameserver line is: 67.207.67.3 67.207.67.2 67.207.67.3                                                                                                                                                                                                                                             31m          51      kube-proxy-r8s-cp-wlp7h-lhvgq.1890a455462b24da
kube-system                31m         Normal    Pulled                           pod/kube-proxy-r8s-cp-wlp7h-lhvgq                                     spec.containers{kube-proxy}                       kubelet, r8s-cp-wlp7h-lhvgq                                            Container image "index.docker.io/rancher/hardened-kubernetes:v1.33.7-rke2r1-build20251210" already present on machine                                                                                                                                                                                                                                                                31m          1       kube-proxy-r8s-cp-wlp7h-lhvgq.1890a456649306c4
kube-system                31m         Normal    Created                          pod/kube-proxy-r8s-cp-wlp7h-lhvgq                                     spec.containers{kube-proxy}                       kubelet, r8s-cp-wlp7h-lhvgq                                            Created container: kube-proxy                                                                                                                                                                                                                                                                                                                                                        31m          1       kube-proxy-r8s-cp-wlp7h-lhvgq.1890a4566784161d
kube-system                31m         Normal    Started                          pod/kube-proxy-r8s-cp-wlp7h-lhvgq                                     spec.containers{kube-proxy}                       kubelet, r8s-cp-wlp7h-lhvgq                                            Started container kube-proxy                                                                                                                                                                                                                                                                                                                                                         31m          1       kube-proxy-r8s-cp-wlp7h-lhvgq.1890a456718d62fa
kube-system                30m         Warning   Unhealthy                        pod/kube-proxy-r8s-cp-wlp7h-lhvgq                                     spec.containers{kube-proxy}                       kubelet, r8s-cp-wlp7h-lhvgq                                            Liveness probe failed: Get "http://localhost:10256/livez": dial tcp [::1]:10256: connect: connection refused                                                                                                                                                                                                                                                                         31m          2       kube-proxy-r8s-cp-wlp7h-lhvgq.1890a45a405f6f72
kube-system                113s        Warning   DNSConfigForming                 pod/kube-proxy-r8s-wk-jnhwv-4xqzn                                                                                       kubelet, r8s-wk-jnhwv-4xqzn                                            Nameserver limits were exceeded, some nameservers have been omitted, the applied nameserver line is: 67.207.67.2 67.207.67.3 67.207.67.2                                                                                                                                                                                                                                             26m          43      kube-proxy-r8s-wk-jnhwv-4xqzn.1890a4949a68b837
kube-system                26m         Normal    Pulled                           pod/kube-proxy-r8s-wk-jnhwv-4xqzn                                     spec.containers{kube-proxy}                       kubelet, r8s-wk-jnhwv-4xqzn                                            Container image "index.docker.io/rancher/hardened-kubernetes:v1.33.7-rke2r1-build20251210" already present on machine                                                                                                                                                                                                                                                                26m          1       kube-proxy-r8s-wk-jnhwv-4xqzn.1890a495a9d0d799
kube-system                26m         Normal    Created                          pod/kube-proxy-r8s-wk-jnhwv-4xqzn                                     spec.containers{kube-proxy}                       kubelet, r8s-wk-jnhwv-4xqzn                                            Created container: kube-proxy                                                                                                                                                                                                                                                                                                                                                        26m          1       kube-proxy-r8s-wk-jnhwv-4xqzn.1890a495ac267d13
kube-system                26m         Normal    Started                          pod/kube-proxy-r8s-wk-jnhwv-4xqzn                                     spec.containers{kube-proxy}                       kubelet, r8s-wk-jnhwv-4xqzn                                            Started container kube-proxy                                                                                                                                                                                                                                                                                                                                                         26m          1       kube-proxy-r8s-wk-jnhwv-4xqzn.1890a495b38532a5
kube-system                101s        Warning   DNSConfigForming                 pod/kube-proxy-r8s-wk-jnhwv-j5k8h                                                                                       kubelet, r8s-wk-jnhwv-j5k8h                                            Nameserver limits were exceeded, some nameservers have been omitted, the applied nameserver line is: 67.207.67.2 67.207.67.3 67.207.67.2                                                                                                                                                                                                                                             26m          44      kube-proxy-r8s-wk-jnhwv-j5k8h.1890a49462fb2852
kube-system                26m         Normal    Pulled                           pod/kube-proxy-r8s-wk-jnhwv-j5k8h                                     spec.containers{kube-proxy}                       kubelet, r8s-wk-jnhwv-j5k8h                                            Container image "index.docker.io/rancher/hardened-kubernetes:v1.33.7-rke2r1-build20251210" already present on machine                                                                                                                                                                                                                                                                26m          1       kube-proxy-r8s-wk-jnhwv-j5k8h.1890a4956a614894
kube-system                26m         Normal    Created                          pod/kube-proxy-r8s-wk-jnhwv-j5k8h                                     spec.containers{kube-proxy}                       kubelet, r8s-wk-jnhwv-j5k8h                                            Created container: kube-proxy                                                                                                                                                                                                                                                                                                                                                        26m          1       kube-proxy-r8s-wk-jnhwv-j5k8h.1890a4956c12c015
kube-system                26m         Normal    Started                          pod/kube-proxy-r8s-wk-jnhwv-j5k8h                                     spec.containers{kube-proxy}                       kubelet, r8s-wk-jnhwv-j5k8h                                            Started container kube-proxy                                                                                                                                                                                                                                                                                                                                                         26m          1       kube-proxy-r8s-wk-jnhwv-j5k8h.1890a4957377dffc
kube-system                74s         Warning   DNSConfigForming                 pod/kube-proxy-r8s-wk-jnhwv-vpdq4                                                                                       kubelet, r8s-wk-jnhwv-vpdq4                                            Nameserver limits were exceeded, some nameservers have been omitted, the applied nameserver line is: 67.207.67.2 67.207.67.3 67.207.67.2                                                                                                                                                                                                                                             26m          44      kube-proxy-r8s-wk-jnhwv-vpdq4.1890a4950473aadd
kube-system                26m         Normal    Pulled                           pod/kube-proxy-r8s-wk-jnhwv-vpdq4                                     spec.containers{kube-proxy}                       kubelet, r8s-wk-jnhwv-vpdq4                                            Container image "index.docker.io/rancher/hardened-kubernetes:v1.33.7-rke2r1-build20251210" already present on machine                                                                                                                                                                                                                                                                26m          1       kube-proxy-r8s-wk-jnhwv-vpdq4.1890a4961698dc16
kube-system                26m         Normal    Created                          pod/kube-proxy-r8s-wk-jnhwv-vpdq4                                     spec.containers{kube-proxy}                       kubelet, r8s-wk-jnhwv-vpdq4                                            Created container: kube-proxy                                                                                                                                                                                                                                                                                                                                                        26m          1       kube-proxy-r8s-wk-jnhwv-vpdq4.1890a49619b2ed57
kube-system                26m         Normal    Started                          pod/kube-proxy-r8s-wk-jnhwv-vpdq4                                     spec.containers{kube-proxy}                       kubelet, r8s-wk-jnhwv-vpdq4                                            Started container kube-proxy                                                                                                                                                                                                                                                                                                                                                         26m          1       kube-proxy-r8s-wk-jnhwv-vpdq4.1890a496234fef70
kube-system                19s         Warning   DNSConfigForming                 pod/kube-scheduler-r8s-cp-wlp7h-lhvgq                                                                                   kubelet, r8s-cp-wlp7h-lhvgq                                            Nameserver limits were exceeded, some nameservers have been omitted, the applied nameserver line is: 67.207.67.3 67.207.67.2 67.207.67.3                                                                                                                                                                                                                                             30m          57      kube-scheduler-r8s-cp-wlp7h-lhvgq.1890a45d58f012ce
kube-system                30m         Normal    Pulled                           pod/kube-scheduler-r8s-cp-wlp7h-lhvgq                                 spec.containers{kube-scheduler}                   kubelet, r8s-cp-wlp7h-lhvgq                                            Container image "index.docker.io/rancher/hardened-kubernetes:v1.33.7-rke2r1-build20251210" already present on machine                                                                                                                                                                                                                                                                30m          1       kube-scheduler-r8s-cp-wlp7h-lhvgq.1890a45d70329aab
kube-system                30m         Normal    Created                          pod/kube-scheduler-r8s-cp-wlp7h-lhvgq                                 spec.containers{kube-scheduler}                   kubelet, r8s-cp-wlp7h-lhvgq                                            Created container: kube-scheduler                                                                                                                                                                                                                                                                                                                                                    30m          1       kube-scheduler-r8s-cp-wlp7h-lhvgq.1890a45d728f5f9c
kube-system                30m         Normal    Started                          pod/kube-scheduler-r8s-cp-wlp7h-lhvgq                                 spec.containers{kube-scheduler}                   kubelet, r8s-cp-wlp7h-lhvgq                                            Started container kube-scheduler                                                                                                                                                                                                                                                                                                                                                     30m          1       kube-scheduler-r8s-cp-wlp7h-lhvgq.1890a45d7ce812fe
kube-system                30m         Normal    LeaderElection                   lease/kube-scheduler                                                                                                    default-scheduler                                                      r8s-cp-wlp7h-lhvgq_67c10c3d-e205-4034-ad98-9e36213acccc became leader                                                                                                                                                                                                                                                                                                                30m          1       kube-scheduler.1890a45daff60600
kube-system                30m         Normal    ApplyingManifest                 addon/managed-chart-config                                                                                              deploy, r8s-cp-wlp7h-lhvgq                                             Applying manifest at "/var/lib/rancher/rke2/server/manifests/rancher/managed-chart-config.yaml"                                                                                                                                                                                                                                                                                      30m          1       managed-chart-config.1890a45e621a6718
kube-system                30m         Normal    AppliedManifest                  addon/managed-chart-config                                                                                              deploy, r8s-cp-wlp7h-lhvgq                                             Applied manifest at "/var/lib/rancher/rke2/server/manifests/rancher/managed-chart-config.yaml"                                                                                                                                                                                                                                                                                       30m          1       managed-chart-config.1890a45e6316dd67
kube-system                30m         Normal    DeletingManifest                 addon/rancher-vsphere-cpi                                                                                               deploy, r8s-cp-wlp7h-lhvgq                                             Deleting manifest at "/var/lib/rancher/rke2/server/manifests/rancher-vsphere-cpi.yaml"                                                                                                                                                                                                                                                                                               30m          1       rancher-vsphere-cpi.1890a45e52ebae83
kube-system                30m         Normal    DeletingManifest                 addon/rancher-vsphere-csi                                                                                               deploy, r8s-cp-wlp7h-lhvgq                                             Deleting manifest at "/var/lib/rancher/rke2/server/manifests/rancher-vsphere-csi.yaml"                                                                                                                                                                                                                                                                                               30m          1       rancher-vsphere-csi.1890a45e58f3509e
kube-system                30m         Normal    ApplyingManifest                 addon/rke2-calico-crd                                                                                                   deploy, r8s-cp-wlp7h-lhvgq                                             Applying manifest at "/var/lib/rancher/rke2/server/manifests/rke2-calico-crd.yaml"                                                                                                                                                                                                                                                                                                   30m          1       rke2-calico-crd.1890a45e66608a2f
kube-system                30m         Normal    AppliedManifest                  addon/rke2-calico-crd                                                                                                   deploy, r8s-cp-wlp7h-lhvgq                                             Applied manifest at "/var/lib/rancher/rke2/server/manifests/rke2-calico-crd.yaml"                                                                                                                                                                                                                                                                                                    30m          1       rke2-calico-crd.1890a45e699b556e
kube-system                30m         Normal    ApplyJob                         helmchart/rke2-calico-crd                                                                                               helm-controller, r8s-cp-wlp7h-lhvgq                                    Applying HelmChart using Job kube-system/helm-install-rke2-calico-crd                                                                                                                                                                                                                                                                                                                30m          7       rke2-calico-crd.1890a45e72e0063a
kube-system                30m         Normal    ApplyingManifest                 addon/rke2-calico                                                                                                       deploy, r8s-cp-wlp7h-lhvgq                                             Applying manifest at "/var/lib/rancher/rke2/server/manifests/rke2-calico.yaml"                                                                                                                                                                                                                                                                                                       30m          1       rke2-calico.1890a45e6b26b660
kube-system                30m         Normal    AppliedManifest                  addon/rke2-calico                                                                                                       deploy, r8s-cp-wlp7h-lhvgq                                             Applied manifest at "/var/lib/rancher/rke2/server/manifests/rke2-calico.yaml"                                                                                                                                                                                                                                                                                                        30m          1       rke2-calico.1890a45e6e447e0a
kube-system                30m         Normal    ApplyJob                         helmchart/rke2-calico                                                                                                   helm-controller, r8s-cp-wlp7h-lhvgq                                    Applying HelmChart using Job kube-system/helm-install-rke2-calico                                                                                                                                                                                                                                                                                                                    30m          7       rke2-calico.1890a45e707ed7c1
kube-system                30m         Normal    DeletingManifest                 addon/rke2-canal                                                                                                        deploy, r8s-cp-wlp7h-lhvgq                                             Deleting manifest at "/var/lib/rancher/rke2/server/manifests/rke2-canal.yaml"                                                                                                                                                                                                                                                                                                        30m          1       rke2-canal.1890a45e7098ad29
kube-system                30m         Normal    DeletingManifest                 addon/rke2-cilium                                                                                                       deploy, r8s-cp-wlp7h-lhvgq                                             Deleting manifest at "/var/lib/rancher/rke2/server/manifests/rke2-cilium.yaml"                                                                                                                                                                                                                                                                                                       30m          1       rke2-cilium.1890a45e73bf2d52
kube-system                30m         Normal    LeaderElection                   lease/rke2-cloud-controller-manager                                                                                     cloud-controller-manager                                               r8s-cp-wlp7h-lhvgq_d4287af8-ce1b-4522-a2be-d6e08068cc25 became leader                                                                                                                                                                                                                                                                                                                30m          1       rke2-cloud-controller-manager.1890a45e24ee1d28
kube-system                30m         Warning   FailedScheduling                 pod/rke2-coredns-rke2-coredns-76994ddb78-2pj99                                                                          default-scheduler, default-scheduler-r8s-cp-wlp7h-lhvgq                0/1 nodes are available: 1 node(s) had untolerated taint {node.kubernetes.io/not-ready: }. preemption: 0/1 nodes are available: 1 Preemption is not helpful for scheduling.                                                                                                                                                                                                          30m          1       rke2-coredns-rke2-coredns-76994ddb78-2pj99.1890a461ae5149db
kube-system                29m         Normal    Scheduled                        pod/rke2-coredns-rke2-coredns-76994ddb78-2pj99                                                                          default-scheduler, default-scheduler-r8s-cp-wlp7h-lhvgq                Successfully assigned kube-system/rke2-coredns-rke2-coredns-76994ddb78-2pj99 to r8s-cp-wlp7h-lhvgq                                                                                                                                                                                                                                                                                   29m          1       rke2-coredns-rke2-coredns-76994ddb78-2pj99.1890a46ea625486b
kube-system                4m29s       Warning   DNSConfigForming                 pod/rke2-coredns-rke2-coredns-76994ddb78-2pj99                                                                          kubelet, r8s-cp-wlp7h-lhvgq                                            Nameserver limits were exceeded, some nameservers have been omitted, the applied nameserver line is: 67.207.67.3 67.207.67.2 67.207.67.3                                                                                                                                                                                                                                             29m          46      rke2-coredns-rke2-coredns-76994ddb78-2pj99.1890a46eba0e8a49
kube-system                29m         Warning   FailedCreatePodSandBox           pod/rke2-coredns-rke2-coredns-76994ddb78-2pj99                                                                          kubelet, r8s-cp-wlp7h-lhvgq                                            Failed to create pod sandbox: rpc error: code = Unknown desc = failed to setup network for sandbox "fdc76de8dcf396a82828bb88c23eaa19e797bb7b904e0980b6ad2282501e088c": plugin type="calico" failed (add): stat /var/lib/calico/nodename: no such file or directory: check that the calico/node container is running and has mounted /var/lib/calico/                                 29m          1       rke2-coredns-rke2-coredns-76994ddb78-2pj99.1890a46ed00cb9e4
kube-system                29m         Normal    Pulling                          pod/rke2-coredns-rke2-coredns-76994ddb78-2pj99                        spec.containers{coredns}                          kubelet, r8s-cp-wlp7h-lhvgq                                            Pulling image "rancher/hardened-coredns:v1.13.1-build20251204"                                                                                                                                                                                                                                                                                                                       29m          1       rke2-coredns-rke2-coredns-76994ddb78-2pj99.1890a47270c8cb88
kube-system                29m         Normal    Pulled                           pod/rke2-coredns-rke2-coredns-76994ddb78-2pj99                        spec.containers{coredns}                          kubelet, r8s-cp-wlp7h-lhvgq                                            Successfully pulled image "rancher/hardened-coredns:v1.13.1-build20251204" in 11.884s (11.884s including waiting). Image size: 30261822 bytes.                                                                                                                                                                                                                                       29m          1       rke2-coredns-rke2-coredns-76994ddb78-2pj99.1890a475352a78a5
kube-system                29m         Normal    Created                          pod/rke2-coredns-rke2-coredns-76994ddb78-2pj99                        spec.containers{coredns}                          kubelet, r8s-cp-wlp7h-lhvgq                                            Created container: coredns                                                                                                                                                                                                                                                                                                                                                           29m          1       rke2-coredns-rke2-coredns-76994ddb78-2pj99.1890a4753796a6a0
kube-system                29m         Normal    Started                          pod/rke2-coredns-rke2-coredns-76994ddb78-2pj99                        spec.containers{coredns}                          kubelet, r8s-cp-wlp7h-lhvgq                                            Started container coredns                                                                                                                                                                                                                                                                                                                                                            29m          1       rke2-coredns-rke2-coredns-76994ddb78-2pj99.1890a4754709c588
kube-system                26m         Normal    Scheduled                        pod/rke2-coredns-rke2-coredns-76994ddb78-mwq52                                                                          default-scheduler, default-scheduler-r8s-cp-wlp7h-lhvgq                Successfully assigned kube-system/rke2-coredns-rke2-coredns-76994ddb78-mwq52 to r8s-wk-jnhwv-4xqzn                                                                                                                                                                                                                                                                                   26m          1       rke2-coredns-rke2-coredns-76994ddb78-mwq52.1890a49c9b4b5323
kube-system                68s         Warning   DNSConfigForming                 pod/rke2-coredns-rke2-coredns-76994ddb78-mwq52                                                                          kubelet, r8s-wk-jnhwv-4xqzn                                            Nameserver limits were exceeded, some nameservers have been omitted, the applied nameserver line is: 67.207.67.2 67.207.67.3 67.207.67.2                                                                                                                                                                                                                                             26m          44      rke2-coredns-rke2-coredns-76994ddb78-mwq52.1890a49cad83b439
kube-system                26m         Warning   FailedCreatePodSandBox           pod/rke2-coredns-rke2-coredns-76994ddb78-mwq52                                                                          kubelet, r8s-wk-jnhwv-4xqzn                                            Failed to create pod sandbox: rpc error: code = Unknown desc = failed to setup network for sandbox "0aedaa3f92005288d7173af89681afe562a7697d19ef7ccb8bc4c23b38777b26": plugin type="calico" failed (add): stat /var/lib/calico/nodename: no such file or directory: check that the calico/node container is running and has mounted /var/lib/calico/                                 26m          1       rke2-coredns-rke2-coredns-76994ddb78-mwq52.1890a49cb4dd0667
kube-system                26m         Normal    Pulling                          pod/rke2-coredns-rke2-coredns-76994ddb78-mwq52                        spec.containers{coredns}                          kubelet, r8s-wk-jnhwv-4xqzn                                            Pulling image "rancher/hardened-coredns:v1.13.1-build20251204"                                                                                                                                                                                                                                                                                                                       26m          1       rke2-coredns-rke2-coredns-76994ddb78-mwq52.1890a4a019db6a6f
kube-system                26m         Normal    Pulled                           pod/rke2-coredns-rke2-coredns-76994ddb78-mwq52                        spec.containers{coredns}                          kubelet, r8s-wk-jnhwv-4xqzn                                            Successfully pulled image "rancher/hardened-coredns:v1.13.1-build20251204" in 6.734s (6.734s including waiting). Image size: 30261822 bytes.                                                                                                                                                                                                                                         26m          1       rke2-coredns-rke2-coredns-76994ddb78-mwq52.1890a4a1ab43c7e9
kube-system                26m         Normal    Created                          pod/rke2-coredns-rke2-coredns-76994ddb78-mwq52                        spec.containers{coredns}                          kubelet, r8s-wk-jnhwv-4xqzn                                            Created container: coredns                                                                                                                                                                                                                                                                                                                                                           26m          1       rke2-coredns-rke2-coredns-76994ddb78-mwq52.1890a4a1af43dfb6
kube-system                26m         Normal    Started                          pod/rke2-coredns-rke2-coredns-76994ddb78-mwq52                        spec.containers{coredns}                          kubelet, r8s-wk-jnhwv-4xqzn                                            Started container coredns                                                                                                                                                                                                                                                                                                                                                            26m          1       rke2-coredns-rke2-coredns-76994ddb78-mwq52.1890a4a1bb8db89d
kube-system                30m         Normal    SuccessfulCreate                 replicaset/rke2-coredns-rke2-coredns-76994ddb78                                                                         replicaset-controller                                                  Created pod: rke2-coredns-rke2-coredns-76994ddb78-2pj99                                                                                                                                                                                                                                                                                                                              30m          1       rke2-coredns-rke2-coredns-76994ddb78.1890a461ad435044
kube-system                26m         Normal    SuccessfulCreate                 replicaset/rke2-coredns-rke2-coredns-76994ddb78                                                                         replicaset-controller                                                  Created pod: rke2-coredns-rke2-coredns-76994ddb78-mwq52                                                                                                                                                                                                                                                                                                                              26m          1       rke2-coredns-rke2-coredns-76994ddb78.1890a49c99a745e5
kube-system                30m         Warning   FailedScheduling                 pod/rke2-coredns-rke2-coredns-autoscaler-67944c44cc-78bfp                                                               default-scheduler, default-scheduler-r8s-cp-wlp7h-lhvgq                0/1 nodes are available: 1 node(s) had untolerated taint {node.kubernetes.io/not-ready: }. preemption: 0/1 nodes are available: 1 Preemption is not helpful for scheduling.                                                                                                                                                                                                          30m          1       rke2-coredns-rke2-coredns-autoscaler-67944c44cc-78bfp.1890a461acd1ea4d
kube-system                29m         Normal    Scheduled                        pod/rke2-coredns-rke2-coredns-autoscaler-67944c44cc-78bfp                                                               default-scheduler, default-scheduler-r8s-cp-wlp7h-lhvgq                Successfully assigned kube-system/rke2-coredns-rke2-coredns-autoscaler-67944c44cc-78bfp to r8s-cp-wlp7h-lhvgq                                                                                                                                                                                                                                                                        29m          1       rke2-coredns-rke2-coredns-autoscaler-67944c44cc-78bfp.1890a46ea69c253e
kube-system                29m         Warning   FailedCreatePodSandBox           pod/rke2-coredns-rke2-coredns-autoscaler-67944c44cc-78bfp                                                               kubelet, r8s-cp-wlp7h-lhvgq                                            Failed to create pod sandbox: rpc error: code = Unknown desc = failed to setup network for sandbox "ea3790e655130374108ff459b41c9e949dd58208d42ff6948b1a580da1211625": plugin type="calico" failed (add): stat /var/lib/calico/nodename: no such file or directory: check that the calico/node container is running and has mounted /var/lib/calico/                                 29m          1       rke2-coredns-rke2-coredns-autoscaler-67944c44cc-78bfp.1890a46ecd5554f3
kube-system                29m         Normal    Pulling                          pod/rke2-coredns-rke2-coredns-autoscaler-67944c44cc-78bfp             spec.containers{autoscaler}                       kubelet, r8s-cp-wlp7h-lhvgq                                            Pulling image "rancher/hardened-cluster-autoscaler:v1.10.2-build20251204"                                                                                                                                                                                                                                                                                                            29m          1       rke2-coredns-rke2-coredns-autoscaler-67944c44cc-78bfp.1890a471ffd8e2c7
kube-system                29m         Normal    Pulled                           pod/rke2-coredns-rke2-coredns-autoscaler-67944c44cc-78bfp             spec.containers{autoscaler}                       kubelet, r8s-cp-wlp7h-lhvgq                                            Successfully pulled image "rancher/hardened-cluster-autoscaler:v1.10.2-build20251204" in 11.853s (11.853s including waiting). Image size: 14088355 bytes.                                                                                                                                                                                                                            29m          1       rke2-coredns-rke2-coredns-autoscaler-67944c44cc-78bfp.1890a474c25f3227
kube-system                29m         Normal    Created                          pod/rke2-coredns-rke2-coredns-autoscaler-67944c44cc-78bfp             spec.containers{autoscaler}                       kubelet, r8s-cp-wlp7h-lhvgq                                            Created container: autoscaler                                                                                                                                                                                                                                                                                                                                                        29m          1       rke2-coredns-rke2-coredns-autoscaler-67944c44cc-78bfp.1890a474c6de2a8a
kube-system                29m         Normal    Started                          pod/rke2-coredns-rke2-coredns-autoscaler-67944c44cc-78bfp             spec.containers{autoscaler}                       kubelet, r8s-cp-wlp7h-lhvgq                                            Started container autoscaler                                                                                                                                                                                                                                                                                                                                                         29m          1       rke2-coredns-rke2-coredns-autoscaler-67944c44cc-78bfp.1890a474d93410ac
kube-system                30m         Normal    SuccessfulCreate                 replicaset/rke2-coredns-rke2-coredns-autoscaler-67944c44cc                                                              replicaset-controller                                                  Created pod: rke2-coredns-rke2-coredns-autoscaler-67944c44cc-78bfp                                                                                                                                                                                                                                                                                                                   30m          1       rke2-coredns-rke2-coredns-autoscaler-67944c44cc.1890a461ad1cc91b
kube-system                30m         Normal    ScalingReplicaSet                deployment/rke2-coredns-rke2-coredns-autoscaler                                                                         deployment-controller                                                  Scaled up replica set rke2-coredns-rke2-coredns-autoscaler-67944c44cc from 0 to 1                                                                                                                                                                                                                                                                                                    30m          1       rke2-coredns-rke2-coredns-autoscaler.1890a461ab68d9e2
kube-system                30m         Normal    ScalingReplicaSet                deployment/rke2-coredns-rke2-coredns                                                                                    deployment-controller                                                  Scaled up replica set rke2-coredns-rke2-coredns-76994ddb78 from 0 to 1                                                                                                                                                                                                                                                                                                               30m          1       rke2-coredns-rke2-coredns.1890a461ac32f75c
kube-system                26m         Normal    ScalingReplicaSet                deployment/rke2-coredns-rke2-coredns                                                                                    deployment-controller                                                  Scaled up replica set rke2-coredns-rke2-coredns-76994ddb78 from 1 to 2                                                                                                                                                                                                                                                                                                               26m          1       rke2-coredns-rke2-coredns.1890a49c95475794
kube-system                30m         Normal    ApplyingManifest                 addon/rke2-coredns                                                                                                      deploy, r8s-cp-wlp7h-lhvgq                                             Applying manifest at "/var/lib/rancher/rke2/server/manifests/rke2-coredns.yaml"                                                                                                                                                                                                                                                                                                      30m          1       rke2-coredns.1890a45e74e8cdb1
kube-system                30m         Normal    AppliedManifest                  addon/rke2-coredns                                                                                                      deploy, r8s-cp-wlp7h-lhvgq                                             Applied manifest at "/var/lib/rancher/rke2/server/manifests/rke2-coredns.yaml"                                                                                                                                                                                                                                                                                                       30m          1       rke2-coredns.1890a45e7894bc95
kube-system                30m         Normal    ApplyJob                         helmchart/rke2-coredns                                                                                                  helm-controller, r8s-cp-wlp7h-lhvgq                                    Applying HelmChart using Job kube-system/helm-install-rke2-coredns                                                                                                                                                                                                                                                                                                                   30m          7       rke2-coredns.1890a45e7c1f4925
kube-system                30m         Normal    ApplyingManifest                 addon/rke2-etcd-snapshot-extra-metadata                                                                                 deploy, r8s-cp-wlp7h-lhvgq                                             Applying manifest at "/var/lib/rancher/rke2/server/manifests/rancher/rke2-etcd-snapshot-extra-metadata.yaml"                                                                                                                                                                                                                                                                         30m          1       rke2-etcd-snapshot-extra-metadata.1890a45e63dacec6
kube-system                30m         Normal    AppliedManifest                  addon/rke2-etcd-snapshot-extra-metadata                                                                                 deploy, r8s-cp-wlp7h-lhvgq                                             Applied manifest at "/var/lib/rancher/rke2/server/manifests/rancher/rke2-etcd-snapshot-extra-metadata.yaml"                                                                                                                                                                                                                                                                          30m          1       rke2-etcd-snapshot-extra-metadata.1890a45e64e02d38
kube-system                30m         Normal    DeletingManifest                 addon/rke2-flannel                                                                                                      deploy, r8s-cp-wlp7h-lhvgq                                             Deleting manifest at "/var/lib/rancher/rke2/server/manifests/rke2-flannel.yaml"                                                                                                                                                                                                                                                                                                      30m          1       rke2-flannel.1890a45e7b24677d
kube-system                26m         Normal    Scheduled                        pod/rke2-ingress-nginx-admission-create-dd8lv                                                                           default-scheduler, default-scheduler-r8s-cp-wlp7h-lhvgq                Successfully assigned kube-system/rke2-ingress-nginx-admission-create-dd8lv to r8s-wk-jnhwv-4xqzn                                                                                                                                                                                                                                                                                    26m          1       rke2-ingress-nginx-admission-create-dd8lv.1890a4a1830fa8bd
kube-system                26m         Normal    Pulling                          pod/rke2-ingress-nginx-admission-create-dd8lv                         spec.containers{create}                           kubelet, r8s-wk-jnhwv-4xqzn                                            Pulling image "rancher/mirrored-ingress-nginx-kube-webhook-certgen:v1.6.5"                                                                                                                                                                                                                                                                                                           26m          1       rke2-ingress-nginx-admission-create-dd8lv.1890a4a1c48f5968
kube-system                25m         Normal    Pulled                           pod/rke2-ingress-nginx-admission-create-dd8lv                         spec.containers{create}                           kubelet, r8s-wk-jnhwv-4xqzn                                            Successfully pulled image "rancher/mirrored-ingress-nginx-kube-webhook-certgen:v1.6.5" in 6.024s (6.024s including waiting). Image size: 18878642 bytes.                                                                                                                                                                                                                             25m          1       rke2-ingress-nginx-admission-create-dd8lv.1890a4a32baca07c
kube-system                25m         Normal    Created                          pod/rke2-ingress-nginx-admission-create-dd8lv                         spec.containers{create}                           kubelet, r8s-wk-jnhwv-4xqzn                                            Created container: create                                                                                                                                                                                                                                                                                                                                                            25m          1       rke2-ingress-nginx-admission-create-dd8lv.1890a4a32d2cf907
kube-system                25m         Normal    Started                          pod/rke2-ingress-nginx-admission-create-dd8lv                         spec.containers{create}                           kubelet, r8s-wk-jnhwv-4xqzn                                            Started container create                                                                                                                                                                                                                                                                                                                                                             25m          1       rke2-ingress-nginx-admission-create-dd8lv.1890a4a334fbcfa4
kube-system                26m         Normal    SuccessfulCreate                 job/rke2-ingress-nginx-admission-create                                                                                 job-controller                                                         Created pod: rke2-ingress-nginx-admission-create-dd8lv                                                                                                                                                                                                                                                                                                                               26m          1       rke2-ingress-nginx-admission-create.1890a4a1825c2ecc
kube-system                25m         Normal    Completed                        job/rke2-ingress-nginx-admission-create                                                                                 job-controller                                                         Job completed                                                                                                                                                                                                                                                                                                                                                                        25m          1       rke2-ingress-nginx-admission-create.1890a4a3f7111837
kube-system                25m         Normal    Scheduled                        pod/rke2-ingress-nginx-admission-patch-mwl5j                                                                            default-scheduler, default-scheduler-r8s-cp-wlp7h-lhvgq                Successfully assigned kube-system/rke2-ingress-nginx-admission-patch-mwl5j to r8s-wk-jnhwv-4xqzn                                                                                                                                                                                                                                                                                     25m          1       rke2-ingress-nginx-admission-patch-mwl5j.1890a4a43a0b7c11
kube-system                25m         Normal    Pulled                           pod/rke2-ingress-nginx-admission-patch-mwl5j                          spec.containers{patch}                            kubelet, r8s-wk-jnhwv-4xqzn                                            Container image "rancher/mirrored-ingress-nginx-kube-webhook-certgen:v1.6.5" already present on machine                                                                                                                                                                                                                                                                              25m          1       rke2-ingress-nginx-admission-patch-mwl5j.1890a4a4613584e9
kube-system                25m         Normal    Created                          pod/rke2-ingress-nginx-admission-patch-mwl5j                          spec.containers{patch}                            kubelet, r8s-wk-jnhwv-4xqzn                                            Created container: patch                                                                                                                                                                                                                                                                                                                                                             25m          1       rke2-ingress-nginx-admission-patch-mwl5j.1890a4a463116c59
kube-system                25m         Normal    Started                          pod/rke2-ingress-nginx-admission-patch-mwl5j                          spec.containers{patch}                            kubelet, r8s-wk-jnhwv-4xqzn                                            Started container patch                                                                                                                                                                                                                                                                                                                                                              25m          1       rke2-ingress-nginx-admission-patch-mwl5j.1890a4a46caedac2
kube-system                25m         Normal    SuccessfulCreate                 job/rke2-ingress-nginx-admission-patch                                                                                  job-controller                                                         Created pod: rke2-ingress-nginx-admission-patch-mwl5j                                                                                                                                                                                                                                                                                                                                25m          1       rke2-ingress-nginx-admission-patch.1890a4a4396e0990
kube-system                25m         Normal    Completed                        job/rke2-ingress-nginx-admission-patch                                                                                  job-controller                                                         Job completed                                                                                                                                                                                                                                                                                                                                                                        25m          1       rke2-ingress-nginx-admission-patch.1890a4a52bd6de31
kube-system                25m         Normal    Scheduled                        pod/rke2-ingress-nginx-controller-7wlmd                                                                                 default-scheduler, default-scheduler-r8s-cp-wlp7h-lhvgq                Successfully assigned kube-system/rke2-ingress-nginx-controller-7wlmd to r8s-wk-jnhwv-j5k8h                                                                                                                                                                                                                                                                                          25m          1       rke2-ingress-nginx-controller-7wlmd.1890a4a4059f2ee5
kube-system                25m         Normal    Pulling                          pod/rke2-ingress-nginx-controller-7wlmd                               spec.containers{rke2-ingress-nginx-controller}    kubelet, r8s-wk-jnhwv-j5k8h                                            Pulling image "rancher/nginx-ingress-controller:v1.13.5-hardened2"                                                                                                                                                                                                                                                                                                                   25m          1       rke2-ingress-nginx-controller-7wlmd.1890a4a4324f3066
kube-system                25m         Normal    Pulled                           pod/rke2-ingress-nginx-controller-7wlmd                               spec.containers{rke2-ingress-nginx-controller}    kubelet, r8s-wk-jnhwv-j5k8h                                            Successfully pulled image "rancher/nginx-ingress-controller:v1.13.5-hardened2" in 15.765s (15.765s including waiting). Image size: 285122879 bytes.                                                                                                                                                                                                                                  25m          1       rke2-ingress-nginx-controller-7wlmd.1890a4a7de0818ae
kube-system                25m         Normal    Created                          pod/rke2-ingress-nginx-controller-7wlmd                               spec.containers{rke2-ingress-nginx-controller}    kubelet, r8s-wk-jnhwv-j5k8h                                            Created container: rke2-ingress-nginx-controller                                                                                                                                                                                                                                                                                                                                     25m          1       rke2-ingress-nginx-controller-7wlmd.1890a4a7df3ca7a0
kube-system                25m         Normal    Started                          pod/rke2-ingress-nginx-controller-7wlmd                               spec.containers{rke2-ingress-nginx-controller}    kubelet, r8s-wk-jnhwv-j5k8h                                            Started container rke2-ingress-nginx-controller                                                                                                                                                                                                                                                                                                                                      25m          1       rke2-ingress-nginx-controller-7wlmd.1890a4a7e65a1a5f
kube-system                25m         Normal    RELOAD                           pod/rke2-ingress-nginx-controller-7wlmd                                                                                 nginx-ingress-controller                                               NGINX reload triggered due to a change in configuration                                                                                                                                                                                                                                                                                                                              25m          1       rke2-ingress-nginx-controller-7wlmd.1890a4a83a53112c
kube-system                25m         Normal    Scheduled                        pod/rke2-ingress-nginx-controller-n9x4d                                                                                 default-scheduler, default-scheduler-r8s-cp-wlp7h-lhvgq                Successfully assigned kube-system/rke2-ingress-nginx-controller-n9x4d to r8s-wk-jnhwv-4xqzn                                                                                                                                                                                                                                                                                          25m          1       rke2-ingress-nginx-controller-n9x4d.1890a4a408137af5
kube-system                25m         Normal    Pulling                          pod/rke2-ingress-nginx-controller-n9x4d                               spec.containers{rke2-ingress-nginx-controller}    kubelet, r8s-wk-jnhwv-4xqzn                                            Pulling image "rancher/nginx-ingress-controller:v1.13.5-hardened2"                                                                                                                                                                                                                                                                                                                   25m          1       rke2-ingress-nginx-controller-n9x4d.1890a4a43d5048d9
kube-system                25m         Normal    Pulled                           pod/rke2-ingress-nginx-controller-n9x4d                               spec.containers{rke2-ingress-nginx-controller}    kubelet, r8s-wk-jnhwv-4xqzn                                            Successfully pulled image "rancher/nginx-ingress-controller:v1.13.5-hardened2" in 15.743s (15.743s including waiting). Image size: 285122879 bytes.                                                                                                                                                                                                                                  25m          1       rke2-ingress-nginx-controller-n9x4d.1890a4a7e7b9b6d0
kube-system                25m         Normal    Created                          pod/rke2-ingress-nginx-controller-n9x4d                               spec.containers{rke2-ingress-nginx-controller}    kubelet, r8s-wk-jnhwv-4xqzn                                            Created container: rke2-ingress-nginx-controller                                                                                                                                                                                                                                                                                                                                     25m          1       rke2-ingress-nginx-controller-n9x4d.1890a4a7e91cfb7d
kube-system                25m         Normal    Started                          pod/rke2-ingress-nginx-controller-n9x4d                               spec.containers{rke2-ingress-nginx-controller}    kubelet, r8s-wk-jnhwv-4xqzn                                            Started container rke2-ingress-nginx-controller                                                                                                                                                                                                                                                                                                                                      25m          1       rke2-ingress-nginx-controller-n9x4d.1890a4a7f0eb96b8
kube-system                25m         Normal    RELOAD                           pod/rke2-ingress-nginx-controller-n9x4d                                                                                 nginx-ingress-controller                                               NGINX reload triggered due to a change in configuration                                                                                                                                                                                                                                                                                                                              25m          1       rke2-ingress-nginx-controller-n9x4d.1890a4a8465389c3
kube-system                25m         Normal    Scheduled                        pod/rke2-ingress-nginx-controller-w2ll7                                                                                 default-scheduler, default-scheduler-r8s-cp-wlp7h-lhvgq                Successfully assigned kube-system/rke2-ingress-nginx-controller-w2ll7 to r8s-wk-jnhwv-vpdq4                                                                                                                                                                                                                                                                                          25m          1       rke2-ingress-nginx-controller-w2ll7.1890a4a4081288b5
kube-system                25m         Normal    Pulling                          pod/rke2-ingress-nginx-controller-w2ll7                               spec.containers{rke2-ingress-nginx-controller}    kubelet, r8s-wk-jnhwv-vpdq4                                            Pulling image "rancher/nginx-ingress-controller:v1.13.5-hardened2"                                                                                                                                                                                                                                                                                                                   25m          1       rke2-ingress-nginx-controller-w2ll7.1890a4a446e35bff
kube-system                25m         Normal    Pulled                           pod/rke2-ingress-nginx-controller-w2ll7                               spec.containers{rke2-ingress-nginx-controller}    kubelet, r8s-wk-jnhwv-vpdq4                                            Successfully pulled image "rancher/nginx-ingress-controller:v1.13.5-hardened2" in 17.205s (17.205s including waiting). Image size: 285122879 bytes.                                                                                                                                                                                                                                  25m          1       rke2-ingress-nginx-controller-w2ll7.1890a4a848699193
kube-system                25m         Normal    Created                          pod/rke2-ingress-nginx-controller-w2ll7                               spec.containers{rke2-ingress-nginx-controller}    kubelet, r8s-wk-jnhwv-vpdq4                                            Created container: rke2-ingress-nginx-controller                                                                                                                                                                                                                                                                                                                                     25m          1       rke2-ingress-nginx-controller-w2ll7.1890a4a849e64cf8
kube-system                25m         Normal    Started                          pod/rke2-ingress-nginx-controller-w2ll7                               spec.containers{rke2-ingress-nginx-controller}    kubelet, r8s-wk-jnhwv-vpdq4                                            Started container rke2-ingress-nginx-controller                                                                                                                                                                                                                                                                                                                                      25m          1       rke2-ingress-nginx-controller-w2ll7.1890a4a853323387
kube-system                25m         Normal    RELOAD                           pod/rke2-ingress-nginx-controller-w2ll7                                                                                 nginx-ingress-controller                                               NGINX reload triggered due to a change in configuration                                                                                                                                                                                                                                                                                                                              25m          1       rke2-ingress-nginx-controller-w2ll7.1890a4a8b2352e91
kube-system                25m         Normal    SuccessfulCreate                 daemonset/rke2-ingress-nginx-controller                                                                                 daemonset-controller                                                   Created pod: rke2-ingress-nginx-controller-7wlmd                                                                                                                                                                                                                                                                                                                                     25m          1       rke2-ingress-nginx-controller.1890a4a4056ce23f
kube-system                25m         Normal    SuccessfulCreate                 daemonset/rke2-ingress-nginx-controller                                                                                 daemonset-controller                                                   Created pod: rke2-ingress-nginx-controller-n9x4d                                                                                                                                                                                                                                                                                                                                     25m          1       rke2-ingress-nginx-controller.1890a4a4077929a1
kube-system                25m         Normal    SuccessfulCreate                 daemonset/rke2-ingress-nginx-controller                                                                                 daemonset-controller                                                   Created pod: rke2-ingress-nginx-controller-w2ll7                                                                                                                                                                                                                                                                                                                                     25m          1       rke2-ingress-nginx-controller.1890a4a4077affc0
kube-system                25m         Normal    CREATE                           configmap/rke2-ingress-nginx-controller                                                                                 nginx-ingress-controller                                               ConfigMap kube-system/rke2-ingress-nginx-controller                                                                                                                                                                                                                                                                                                                                  25m          1       rke2-ingress-nginx-controller.1890a4a7f2ae0e26
kube-system                25m         Normal    CREATE                           configmap/rke2-ingress-nginx-controller                                                                                 nginx-ingress-controller                                               ConfigMap kube-system/rke2-ingress-nginx-controller                                                                                                                                                                                                                                                                                                                                  25m          1       rke2-ingress-nginx-controller.1890a4a7fe152452
kube-system                25m         Normal    CREATE                           configmap/rke2-ingress-nginx-controller                                                                                 nginx-ingress-controller                                               ConfigMap kube-system/rke2-ingress-nginx-controller                                                                                                                                                                                                                                                                                                                                  25m          1       rke2-ingress-nginx-controller.1890a4a86a6daf65
kube-system                30m         Normal    ApplyingManifest                 addon/rke2-ingress-nginx                                                                                                deploy, r8s-cp-wlp7h-lhvgq                                             Applying manifest at "/var/lib/rancher/rke2/server/manifests/rke2-ingress-nginx.yaml"                                                                                                                                                                                                                                                                                                30m          1       rke2-ingress-nginx.1890a45e7d3bfa69
kube-system                30m         Normal    AppliedManifest                  addon/rke2-ingress-nginx                                                                                                deploy, r8s-cp-wlp7h-lhvgq                                             Applied manifest at "/var/lib/rancher/rke2/server/manifests/rke2-ingress-nginx.yaml"                                                                                                                                                                                                                                                                                                 30m          1       rke2-ingress-nginx.1890a45e87c0a51b
kube-system                25m         Normal    ApplyJob                         helmchart/rke2-ingress-nginx                                                                                            helm-controller, r8s-cp-wlp7h-lhvgq                                    Applying HelmChart using Job kube-system/helm-install-rke2-ingress-nginx                                                                                                                                                                                                                                                                                                             30m          9       rke2-ingress-nginx.1890a45e8e4168f4
kube-system                26m         Normal    Scheduled                        pod/rke2-metrics-server-5699475d99-vwshf                                                                                default-scheduler, default-scheduler-r8s-cp-wlp7h-lhvgq                Successfully assigned kube-system/rke2-metrics-server-5699475d99-vwshf to r8s-wk-jnhwv-4xqzn                                                                                                                                                                                                                                                                                         26m          1       rke2-metrics-server-5699475d99-vwshf.1890a4a147963f65
kube-system                26m         Normal    Pulling                          pod/rke2-metrics-server-5699475d99-vwshf                              spec.containers{metrics-server}                   kubelet, r8s-wk-jnhwv-4xqzn                                            Pulling image "rancher/hardened-k8s-metrics-server:v0.8.0-build20251204"                                                                                                                                                                                                                                                                                                             26m          1       rke2-metrics-server-5699475d99-vwshf.1890a4a17834b0eb
kube-system                25m         Normal    Pulled                           pod/rke2-metrics-server-5699475d99-vwshf                              spec.containers{metrics-server}                   kubelet, r8s-wk-jnhwv-4xqzn                                            Successfully pulled image "rancher/hardened-k8s-metrics-server:v0.8.0-build20251204" in 5.719s (5.719s including waiting). Image size: 21360135 bytes.                                                                                                                                                                                                                               25m          1       rke2-metrics-server-5699475d99-vwshf.1890a4a2cd1af56a
kube-system                25m         Normal    Created                          pod/rke2-metrics-server-5699475d99-vwshf                              spec.containers{metrics-server}                   kubelet, r8s-wk-jnhwv-4xqzn                                            Created container: metrics-server                                                                                                                                                                                                                                                                                                                                                    25m          1       rke2-metrics-server-5699475d99-vwshf.1890a4a2d089792d
kube-system                25m         Normal    Started                          pod/rke2-metrics-server-5699475d99-vwshf                              spec.containers{metrics-server}                   kubelet, r8s-wk-jnhwv-4xqzn                                            Started container metrics-server                                                                                                                                                                                                                                                                                                                                                     25m          1       rke2-metrics-server-5699475d99-vwshf.1890a4a2d886406c
kube-system                26m         Normal    SuccessfulCreate                 replicaset/rke2-metrics-server-5699475d99                                                                               replicaset-controller                                                  Created pod: rke2-metrics-server-5699475d99-vwshf                                                                                                                                                                                                                                                                                                                                    26m          1       rke2-metrics-server-5699475d99.1890a4a145f18498
kube-system                30m         Normal    ApplyingManifest                 addon/rke2-metrics-server                                                                                               deploy, r8s-cp-wlp7h-lhvgq                                             Applying manifest at "/var/lib/rancher/rke2/server/manifests/rke2-metrics-server.yaml"                                                                                                                                                                                                                                                                                               30m          1       rke2-metrics-server.1890a45e8e14ec18
kube-system                30m         Normal    AppliedManifest                  addon/rke2-metrics-server                                                                                               deploy, r8s-cp-wlp7h-lhvgq                                             Applied manifest at "/var/lib/rancher/rke2/server/manifests/rke2-metrics-server.yaml"                                                                                                                                                                                                                                                                                                30m          1       rke2-metrics-server.1890a45e9191b31c
kube-system                26m         Normal    ApplyJob                         helmchart/rke2-metrics-server                                                                                           helm-controller, r8s-cp-wlp7h-lhvgq                                    Applying HelmChart using Job kube-system/helm-install-rke2-metrics-server                                                                                                                                                                                                                                                                                                            30m          5       rke2-metrics-server.1890a45e94229169
kube-system                26m         Normal    ScalingReplicaSet                deployment/rke2-metrics-server                                                                                          deployment-controller                                                  Scaled up replica set rke2-metrics-server-5699475d99 from 0 to 1                                                                                                                                                                                                                                                                                                                     26m          1       rke2-metrics-server.1890a4a1443036b7
kube-system                30m         Normal    DeletingManifest                 addon/rke2-multus                                                                                                       deploy, r8s-cp-wlp7h-lhvgq                                             Deleting manifest at "/var/lib/rancher/rke2/server/manifests/rke2-multus.yaml"                                                                                                                                                                                                                                                                                                       30m          1       rke2-multus.1890a45e951e2e6e
kube-system                30m         Normal    ApplyingManifest                 addon/rke2-runtimeclasses                                                                                               deploy, r8s-cp-wlp7h-lhvgq                                             Applying manifest at "/var/lib/rancher/rke2/server/manifests/rke2-runtimeclasses.yaml"                                                                                                                                                                                                                                                                                               30m          1       rke2-runtimeclasses.1890a45e969d31e7
kube-system                30m         Normal    AppliedManifest                  addon/rke2-runtimeclasses                                                                                               deploy, r8s-cp-wlp7h-lhvgq                                             Applied manifest at "/var/lib/rancher/rke2/server/manifests/rke2-runtimeclasses.yaml"                                                                                                                                                                                                                                                                                                30m          1       rke2-runtimeclasses.1890a45e9afef9c4
kube-system                26m         Normal    ApplyJob                         helmchart/rke2-runtimeclasses                                                                                           helm-controller, r8s-cp-wlp7h-lhvgq                                    Applying HelmChart using Job kube-system/helm-install-rke2-runtimeclasses                                                                                                                                                                                                                                                                                                            30m          7       rke2-runtimeclasses.1890a45e9e0e38c7
kube-system                26m         Normal    Scheduled                        pod/rke2-snapshot-controller-696989ffdd-ml54w                                                                           default-scheduler, default-scheduler-r8s-cp-wlp7h-lhvgq                Successfully assigned kube-system/rke2-snapshot-controller-696989ffdd-ml54w to r8s-wk-jnhwv-vpdq4                                                                                                                                                                                                                                                                                    26m          1       rke2-snapshot-controller-696989ffdd-ml54w.1890a4a19c1ff6c3
kube-system                26m         Normal    Pulling                          pod/rke2-snapshot-controller-696989ffdd-ml54w                         spec.containers{rke2-snapshot-controller}         kubelet, r8s-wk-jnhwv-vpdq4                                            Pulling image "rancher/mirrored-sig-storage-snapshot-controller:v8.2.0"                                                                                                                                                                                                                                                                                                              26m          1       rke2-snapshot-controller-696989ffdd-ml54w.1890a4a1cb3c6ce9
kube-system                25m         Normal    Pulled                           pod/rke2-snapshot-controller-696989ffdd-ml54w                         spec.containers{rke2-snapshot-controller}         kubelet, r8s-wk-jnhwv-vpdq4                                            Successfully pulled image "rancher/mirrored-sig-storage-snapshot-controller:v8.2.0" in 6.697s (6.697s including waiting). Image size: 29129582 bytes.                                                                                                                                                                                                                                25m          1       rke2-snapshot-controller-696989ffdd-ml54w.1890a4a35a753477
kube-system                25m         Normal    Created                          pod/rke2-snapshot-controller-696989ffdd-ml54w                         spec.containers{rke2-snapshot-controller}         kubelet, r8s-wk-jnhwv-vpdq4                                            Created container: rke2-snapshot-controller                                                                                                                                                                                                                                                                                                                                          25m          1       rke2-snapshot-controller-696989ffdd-ml54w.1890a4a35c408243
kube-system                25m         Normal    Started                          pod/rke2-snapshot-controller-696989ffdd-ml54w                         spec.containers{rke2-snapshot-controller}         kubelet, r8s-wk-jnhwv-vpdq4                                            Started container rke2-snapshot-controller                                                                                                                                                                                                                                                                                                                                           25m          1       rke2-snapshot-controller-696989ffdd-ml54w.1890a4a363002a2a
kube-system                26m         Normal    SuccessfulCreate                 replicaset/rke2-snapshot-controller-696989ffdd                                                                          replicaset-controller                                                  Created pod: rke2-snapshot-controller-696989ffdd-ml54w                                                                                                                                                                                                                                                                                                                               26m          1       rke2-snapshot-controller-696989ffdd.1890a4a198a3afe9
kube-system                30m         Normal    ApplyingManifest                 addon/rke2-snapshot-controller-crd                                                                                      deploy, r8s-cp-wlp7h-lhvgq                                             Applying manifest at "/var/lib/rancher/rke2/server/manifests/rke2-snapshot-controller-crd.yaml"                                                                                                                                                                                                                                                                                      30m          1       rke2-snapshot-controller-crd.1890a45e9e8e5396
kube-system                30m         Normal    AppliedManifest                  addon/rke2-snapshot-controller-crd                                                                                      deploy, r8s-cp-wlp7h-lhvgq                                             Applied manifest at "/var/lib/rancher/rke2/server/manifests/rke2-snapshot-controller-crd.yaml"                                                                                                                                                                                                                                                                                       30m          1       rke2-snapshot-controller-crd.1890a45ea33fbc5a
kube-system                26m         Normal    ApplyJob                         helmchart/rke2-snapshot-controller-crd                                                                                  helm-controller, r8s-cp-wlp7h-lhvgq                                    Applying HelmChart using Job kube-system/helm-install-rke2-snapshot-controller-crd                                                                                                                                                                                                                                                                                                   30m          9       rke2-snapshot-controller-crd.1890a45ea4f39ef7
kube-system                30m         Normal    ApplyingManifest                 addon/rke2-snapshot-controller                                                                                          deploy, r8s-cp-wlp7h-lhvgq                                             Applying manifest at "/var/lib/rancher/rke2/server/manifests/rke2-snapshot-controller.yaml"                                                                                                                                                                                                                                                                                          30m          1       rke2-snapshot-controller.1890a45ea57825ee
kube-system                30m         Normal    AppliedManifest                  addon/rke2-snapshot-controller                                                                                          deploy, r8s-cp-wlp7h-lhvgq                                             Applied manifest at "/var/lib/rancher/rke2/server/manifests/rke2-snapshot-controller.yaml"                                                                                                                                                                                                                                                                                           30m          1       rke2-snapshot-controller.1890a45ea86f0232
kube-system                25m         Normal    ApplyJob                         helmchart/rke2-snapshot-controller                                                                                      helm-controller, r8s-cp-wlp7h-lhvgq                                    Applying HelmChart using Job kube-system/helm-install-rke2-snapshot-controller                                                                                                                                                                                                                                                                                                       30m          10      rke2-snapshot-controller.1890a45eaaeedd88
kube-system                26m         Normal    ScalingReplicaSet                deployment/rke2-snapshot-controller                                                                                     deployment-controller                                                  Scaled up replica set rke2-snapshot-controller-696989ffdd from 0 to 1                                                                                                                                                                                                                                                                                                                26m          1       rke2-snapshot-controller.1890a4a193959c26
kube-system                30m         Normal    ApplyingManifest                 addon/rke2-snapshot-validation-webhook                                                                                  deploy, r8s-cp-wlp7h-lhvgq                                             Applying manifest at "/var/lib/rancher/rke2/server/manifests/rke2-snapshot-validation-webhook.yaml"                                                                                                                                                                                                                                                                                  30m          1       rke2-snapshot-validation-webhook.1890a45eaaa27d3c
